Workbook

Sheet Export_ControlTot
A1: ;YEAR | B1: BYU | C1: ENSIGN | D1: SLCC_MAIN | E1: SLCC_JD | F1: SLCC_ML | G1: SLCC_SC | H1: UOFU_Main | I1: UVU_Main | J1: UVU_Lehi | K1: UVU_Payson | L1: UVU_Vineyard | M1: WSU_Main | N1: WSU_Davis | O1: WESTMIN
A2: 1990 | B2: =INDEX('Campus Enrol Disaggregation'!$P$5:$AC$65,MATCH(Export_ControlTot!$A2,'Campus Enrol Disaggregation'!$O$5:$O$65,0),MATCH(B$1,'Campus Enrol Disaggregation'!$P$4:$AC$4,0)) -> 30450 | C2: =INDEX('Campus Enrol Disaggregation'!$P$5:$AC$65,MATCH(Export_ControlTot!$A2,'Campus Enrol Disaggregation'!$O$5:$O$65,0),MATCH(C$1,'Campus Enrol Disaggregation'!$P$4:$AC$4,0)) -> 0 | D2: =INDEX('Campus Enrol Disaggregation'!$P$5:$AC$65,MATCH(Export_ControlTot!$A2,'Campus Enrol Disaggregation'!$O$5:$O$65,0),MATCH(D$1,'Campus Enrol Disaggregation'!$P$4:$AC$4,0)) -> 7050 | E2: =INDEX('Campus Enrol Disaggregation'!$P$5:$AC$65,MATCH(Export_ControlTot!$A2,'Campus Enrol Disaggregation'!$O$5:$O$65,0),MATCH(E$1,'Campus Enrol Disaggregation'!$P$4:$AC$4,0)) -> 2450 | F2: =INDEX('Campus Enrol Disaggregation'!$P$5:$AC$65,MATCH(Export_ControlTot!$A2,'Campus Enrol Disaggregation'!$O$5:$O$65,0),MATCH(F$1,'Campus Enrol Disaggregation'!$P$4:$AC$4,0)) -> 600 | G2: =INDEX('Campus Enrol Disaggregation'!$P$5:$AC$65,MATCH(Export_ControlTot!$A2,'Campus Enrol Disaggregation'!$O$5:$O$65,0),MATCH(G$1,'Campus Enrol Disaggregation'!$P$4:$AC$4,0)) -> 2200 | H2: =INDEX('Campus Enrol Disaggregation'!$P$5:$AC$65,MATCH(Export_ControlTot!$A2,'Campus Enrol Disaggregation'!$O$5:$O$65,0),MATCH(H$1,'Campus Enrol Disaggregation'!$P$4:$AC$4,0)) -> 23650 | I2: =INDEX('Campus Enrol Disaggregation'!$P$5:$AC$65,MATCH(Export_ControlTot!$A2,'Campus Enrol Disaggregation'!$O$5:$O$65,0),MATCH(I$1,'Campus Enrol Disaggregation'!$P$4:$AC$4,0)) -> 7900 | ... O2: =INDEX('Campus Enrol Disaggregation'!$P$5:$AC$65,MATCH(Export_ControlTot!$A2,'Campus Enrol Disaggregation'!$O$5:$O$65,0),MATCH(O$1,'Campus Enrol Disaggregation'!$P$4:$AC$4,0)) -> 0
A3: 1991 | B3: =INDEX('Campus Enrol Disaggregation'!$P$5:$AC$65,MATCH(Export_ControlTot!$A3,'Campus Enrol Disaggregation'!$O$5:$O$65,0),MATCH(B$1,'Campus Enrol Disaggregation'!$P$4:$AC$4,0)) -> 31100 | C3: =INDEX('Campus Enrol Disaggregation'!$P$5:$AC$65,MATCH(Export_ControlTot!$A3,'Campus Enrol Disaggregation'!$O$5:$O$65,0),MATCH(C$1,'Campus Enrol Disaggregation'!$P$4:$AC$4,0)) -> 0 | D3: =INDEX('Campus Enrol Disaggregation'!$P$5:$AC$65,MATCH(Export_ControlTot!$A3,'Campus Enrol Disaggregation'!$O$5:$O$65,0),MATCH(D$1,'Campus Enrol Disaggregation'!$P$4:$AC$4,0)) -> 8450 | E3: =INDEX('Campus Enrol Disaggregation'!$P$5:$AC$65,MATCH(Export_ControlTot!$A3,'Campus Enrol Disaggregation'!$O$5:$O$65,0),MATCH(E$1,'Campus Enrol Disaggregation'!$P$4:$AC$4,0)) -> 2950 | F3: =INDEX('Campus Enrol Disaggregation'!$P$5:$AC$65,MATCH(Export_ControlTot!$A3,'Campus Enrol Disaggregation'!$O$5:$O$65,0),MATCH(F$1,'Campus Enrol Disaggregation'!$P$4:$AC$4,0)) -> 750 | G3: =INDEX('Campus Enrol Disaggregation'!$P$5:$AC$65,MATCH(Export_ControlTot!$A3,'Campus Enrol Disaggregation'!$O$5:$O$65,0),MATCH(G$1,'Campus Enrol Disaggregation'!$P$4:$AC$4,0)) -> 2600 | H3: =INDEX('Campus Enrol Disaggregation'!$P$5:$AC$65,MATCH(Export_ControlTot!$A3,'Campus Enrol Disaggregation'!$O$5:$O$65,0),MATCH(H$1,'Campus Enrol Disaggregation'!$P$4:$AC$4,0)) -> 24900 | I3: =INDEX('Campus Enrol Disaggregation'!$P$5:$AC$65,MATCH(Export_ControlTot!$A3,'Campus Enrol Disaggregation'!$O$5:$O$65,0),MATCH(I$1,'Campus Enrol Disaggregation'!$P$4:$AC$4,0)) -> 8800 | ... O3: =INDEX('Campus Enrol Disaggregation'!$P$5:$AC$65,MATCH(Export_ControlTot!$A3,'Campus Enrol Disaggregation'!$O$5:$O$65,0),MATCH(O$1,'Campus Enrol Disaggregation'!$P$4:$AC$4,0)) -> 0
A4: 1992 | B4: =INDEX('Campus Enrol Disaggregation'!$P$5:$AC$65,MATCH(Export_ControlTot!$A4,'Campus Enrol Disaggregation'!$O$5:$O$65,0),MATCH(B$1,'Campus Enrol Disaggregation'!$P$4:$AC$4,0)) -> 31100 | C4: =INDEX('Campus Enrol Disaggregation'!$P$5:$AC$65,MATCH(Export_ControlTot!$A4,'Campus Enrol Disaggregation'!$O$5:$O$65,0),MATCH(C$1,'Campus Enrol Disaggregation'!$P$4:$AC$4,0)) -> 0 | D4: =INDEX('Campus Enrol Disaggregation'!$P$5:$AC$65,MATCH(Export_ControlTot!$A4,'Campus Enrol Disaggregation'!$O$5:$O$65,0),MATCH(D$1,'Campus Enrol Disaggregation'!$P$4:$AC$4,0)) -> 9400 | E4: =INDEX('Campus Enrol Disaggregation'!$P$5:$AC$65,MATCH(Export_ControlTot!$A4,'Campus Enrol Disaggregation'!$O$5:$O$65,0),MATCH(E$1,'Campus Enrol Disaggregation'!$P$4:$AC$4,0)) -> 3300 | F4: =INDEX('Campus Enrol Disaggregation'!$P$5:$AC$65,MATCH(Export_ControlTot!$A4,'Campus Enrol Disaggregation'!$O$5:$O$65,0),MATCH(F$1,'Campus Enrol Disaggregation'!$P$4:$AC$4,0)) -> 800 | G4: =INDEX('Campus Enrol Disaggregation'!$P$5:$AC$65,MATCH(Export_ControlTot!$A4,'Campus Enrol Disaggregation'!$O$5:$O$65,0),MATCH(G$1,'Campus Enrol Disaggregation'!$P$4:$AC$4,0)) -> 2900 | H4: =INDEX('Campus Enrol Disaggregation'!$P$5:$AC$65,MATCH(Export_ControlTot!$A4,'Campus Enrol Disaggregation'!$O$5:$O$65,0),MATCH(H$1,'Campus Enrol Disaggregation'!$P$4:$AC$4,0)) -> 25200 | I4: =INDEX('Campus Enrol Disaggregation'!$P$5:$AC$65,MATCH(Export_ControlTot!$A4,'Campus Enrol Disaggregation'!$O$5:$O$65,0),MATCH(I$1,'Campus Enrol Disaggregation'!$P$4:$AC$4,0)) -> 9600 | ... O4: =INDEX('Campus Enrol Disaggregation'!$P$5:$AC$65,MATCH(Export_ControlTot!$A4,'Campus Enrol Disaggregation'!$O$5:$O$65,0),MATCH(O$1,'Campus Enrol Disaggregation'!$P$4:$AC$4,0)) -> 0
A5: 1993 | B5: =INDEX('Campus Enrol Disaggregation'!$P$5:$AC$65,MATCH(Export_ControlTot!$A5,'Campus Enrol Disaggregation'!$O$5:$O$65,0),MATCH(B$1,'Campus Enrol Disaggregation'!$P$4:$AC$4,0)) -> 30550 | C5: =INDEX('Campus Enrol Disaggregation'!$P$5:$AC$65,MATCH(Export_ControlTot!$A5,'Campus Enrol Disaggregation'!$O$5:$O$65,0),MATCH(C$1,'Campus Enrol Disaggregation'!$P$4:$AC$4,0)) -> 0 | D5: =INDEX('Campus Enrol Disaggregation'!$P$5:$AC$65,MATCH(Export_ControlTot!$A5,'Campus Enrol Disaggregation'!$O$5:$O$65,0),MATCH(D$1,'Campus Enrol Disaggregation'!$P$4:$AC$4,0)) -> 9650 | E5: =INDEX('Campus Enrol Disaggregation'!$P$5:$AC$65,MATCH(Export_ControlTot!$A5,'Campus Enrol Disaggregation'!$O$5:$O$65,0),MATCH(E$1,'Campus Enrol Disaggregation'!$P$4:$AC$4,0)) -> 3400 | F5: =INDEX('Campus Enrol Disaggregation'!$P$5:$AC$65,MATCH(Export_ControlTot!$A5,'Campus Enrol Disaggregation'!$O$5:$O$65,0),MATCH(F$1,'Campus Enrol Disaggregation'!$P$4:$AC$4,0)) -> 850 | G5: =INDEX('Campus Enrol Disaggregation'!$P$5:$AC$65,MATCH(Export_ControlTot!$A5,'Campus Enrol Disaggregation'!$O$5:$O$65,0),MATCH(G$1,'Campus Enrol Disaggregation'!$P$4:$AC$4,0)) -> 3000 | H5: =INDEX('Campus Enrol Disaggregation'!$P$5:$AC$65,MATCH(Export_ControlTot!$A5,'Campus Enrol Disaggregation'!$O$5:$O$65,0),MATCH(H$1,'Campus Enrol Disaggregation'!$P$4:$AC$4,0)) -> 25300 | I5: =INDEX('Campus Enrol Disaggregation'!$P$5:$AC$65,MATCH(Export_ControlTot!$A5,'Campus Enrol Disaggregation'!$O$5:$O$65,0),MATCH(I$1,'Campus Enrol Disaggregation'!$P$4:$AC$4,0)) -> 10500 | ... O5: =INDEX('Campus Enrol Disaggregation'!$P$5:$AC$65,MATCH(Export_ControlTot!$A5,'Campus Enrol Disaggregation'!$O$5:$O$65,0),MATCH(O$1,'Campus Enrol Disaggregation'!$P$4:$AC$4,0)) -> 0
A6: 1994 | B6: =INDEX('Campus Enrol Disaggregation'!$P$5:$AC$65,MATCH(Export_ControlTot!$A6,'Campus Enrol Disaggregation'!$O$5:$O$65,0),MATCH(B$1,'Campus Enrol Disaggregation'!$P$4:$AC$4,0)) -> 30400 | C6: =INDEX('Campus Enrol Disaggregation'!$P$5:$AC$65,MATCH(Export_ControlTot!$A6,'Campus Enrol Disaggregation'!$O$5:$O$65,0),MATCH(C$1,'Campus Enrol Disaggregation'!$P$4:$AC$4,0)) -> 0 | D6: =INDEX('Campus Enrol Disaggregation'!$P$5:$AC$65,MATCH(Export_ControlTot!$A6,'Campus Enrol Disaggregation'!$O$5:$O$65,0),MATCH(D$1,'Campus Enrol Disaggregation'!$P$4:$AC$4,0)) -> 10250 | E6: =INDEX('Campus Enrol Disaggregation'!$P$5:$AC$65,MATCH(Export_ControlTot!$A6,'Campus Enrol Disaggregation'!$O$5:$O$65,0),MATCH(E$1,'Campus Enrol Disaggregation'!$P$4:$AC$4,0)) -> 3600 | F6: =INDEX('Campus Enrol Disaggregation'!$P$5:$AC$65,MATCH(Export_ControlTot!$A6,'Campus Enrol Disaggregation'!$O$5:$O$65,0),MATCH(F$1,'Campus Enrol Disaggregation'!$P$4:$AC$4,0)) -> 900 | G6: =INDEX('Campus Enrol Disaggregation'!$P$5:$AC$65,MATCH(Export_ControlTot!$A6,'Campus Enrol Disaggregation'!$O$5:$O$65,0),MATCH(G$1,'Campus Enrol Disaggregation'!$P$4:$AC$4,0)) -> 3200 | H6: =INDEX('Campus Enrol Disaggregation'!$P$5:$AC$65,MATCH(Export_ControlTot!$A6,'Campus Enrol Disaggregation'!$O$5:$O$65,0),MATCH(H$1,'Campus Enrol Disaggregation'!$P$4:$AC$4,0)) -> 24950 | I6: =INDEX('Campus Enrol Disaggregation'!$P$5:$AC$65,MATCH(Export_ControlTot!$A6,'Campus Enrol Disaggregation'!$O$5:$O$65,0),MATCH(I$1,'Campus Enrol Disaggregation'!$P$4:$AC$4,0)) -> 13300 | ... O6: =INDEX('Campus Enrol Disaggregation'!$P$5:$AC$65,MATCH(Export_ControlTot!$A6,'Campus Enrol Disaggregation'!$O$5:$O$65,0),MATCH(O$1,'Campus Enrol Disaggregation'!$P$4:$AC$4,0)) -> 0
A7: 1995 | B7: =INDEX('Campus Enrol Disaggregation'!$P$5:$AC$65,MATCH(Export_ControlTot!$A7,'Campus Enrol Disaggregation'!$O$5:$O$65,0),MATCH(B$1,'Campus Enrol Disaggregation'!$P$4:$AC$4,0)) -> 30450 | C7: =INDEX('Campus Enrol Disaggregation'!$P$5:$AC$65,MATCH(Export_ControlTot!$A7,'Campus Enrol Disaggregation'!$O$5:$O$65,0),MATCH(C$1,'Campus Enrol Disaggregation'!$P$4:$AC$4,0)) -> 0 | D7: =INDEX('Campus Enrol Disaggregation'!$P$5:$AC$65,MATCH(Export_ControlTot!$A7,'Campus Enrol Disaggregation'!$O$5:$O$65,0),MATCH(D$1,'Campus Enrol Disaggregation'!$P$4:$AC$4,0)) -> 11000 | E7: =INDEX('Campus Enrol Disaggregation'!$P$5:$AC$65,MATCH(Export_ControlTot!$A7,'Campus Enrol Disaggregation'!$O$5:$O$65,0),MATCH(E$1,'Campus Enrol Disaggregation'!$P$4:$AC$4,0)) -> 3850 | F7: =INDEX('Campus Enrol Disaggregation'!$P$5:$AC$65,MATCH(Export_ControlTot!$A7,'Campus Enrol Disaggregation'!$O$5:$O$65,0),MATCH(F$1,'Campus Enrol Disaggregation'!$P$4:$AC$4,0)) -> 950 | G7: =INDEX('Campus Enrol Disaggregation'!$P$5:$AC$65,MATCH(Export_ControlTot!$A7,'Campus Enrol Disaggregation'!$O$5:$O$65,0),MATCH(G$1,'Campus Enrol Disaggregation'!$P$4:$AC$4,0)) -> 3400 | H7: =INDEX('Campus Enrol Disaggregation'!$P$5:$AC$65,MATCH(Export_ControlTot!$A7,'Campus Enrol Disaggregation'!$O$5:$O$65,0),MATCH(H$1,'Campus Enrol Disaggregation'!$P$4:$AC$4,0)) -> 26100 | I7: =INDEX('Campus Enrol Disaggregation'!$P$5:$AC$65,MATCH(Export_ControlTot!$A7,'Campus Enrol Disaggregation'!$O$5:$O$65,0),MATCH(I$1,'Campus Enrol Disaggregation'!$P$4:$AC$4,0)) -> 14050 | ... O7: =INDEX('Campus Enrol Disaggregation'!$P$5:$AC$65,MATCH(Export_ControlTot!$A7,'Campus Enrol Disaggregation'!$O$5:$O$65,0),MATCH(O$1,'Campus Enrol Disaggregation'!$P$4:$AC$4,0)) -> 0
A8: 1996 | B8: =INDEX('Campus Enrol Disaggregation'!$P$5:$AC$65,MATCH(Export_ControlTot!$A8,'Campus Enrol Disaggregation'!$O$5:$O$65,0),MATCH(B$1,'Campus Enrol Disaggregation'!$P$4:$AC$4,0)) -> 30550 | C8: =INDEX('Campus Enrol Disaggregation'!$P$5:$AC$65,MATCH(Export_ControlTot!$A8,'Campus Enrol Disaggregation'!$O$5:$O$65,0),MATCH(C$1,'Campus Enrol Disaggregation'!$P$4:$AC$4,0)) -> 0 | D8: =INDEX('Campus Enrol Disaggregation'!$P$5:$AC$65,MATCH(Export_ControlTot!$A8,'Campus Enrol Disaggregation'!$O$5:$O$65,0),MATCH(D$1,'Campus Enrol Disaggregation'!$P$4:$AC$4,0)) -> 11800 | E8: =INDEX('Campus Enrol Disaggregation'!$P$5:$AC$65,MATCH(Export_ControlTot!$A8,'Campus Enrol Disaggregation'!$O$5:$O$65,0),MATCH(E$1,'Campus Enrol Disaggregation'!$P$4:$AC$4,0)) -> 4150 | F8: =INDEX('Campus Enrol Disaggregation'!$P$5:$AC$65,MATCH(Export_ControlTot!$A8,'Campus Enrol Disaggregation'!$O$5:$O$65,0),MATCH(F$1,'Campus Enrol Disaggregation'!$P$4:$AC$4,0)) -> 1050 | G8: =INDEX('Campus Enrol Disaggregation'!$P$5:$AC$65,MATCH(Export_ControlTot!$A8,'Campus Enrol Disaggregation'!$O$5:$O$65,0),MATCH(G$1,'Campus Enrol Disaggregation'!$P$4:$AC$4,0)) -> 3650 | H8: =INDEX('Campus Enrol Disaggregation'!$P$5:$AC$65,MATCH(Export_ControlTot!$A8,'Campus Enrol Disaggregation'!$O$5:$O$65,0),MATCH(H$1,'Campus Enrol Disaggregation'!$P$4:$AC$4,0)) -> 25400 | I8: =INDEX('Campus Enrol Disaggregation'!$P$5:$AC$65,MATCH(Export_ControlTot!$A8,'Campus Enrol Disaggregation'!$O$5:$O$65,0),MATCH(I$1,'Campus Enrol Disaggregation'!$P$4:$AC$4,0)) -> 14750 | ... O8: =INDEX('Campus Enrol Disaggregation'!$P$5:$AC$65,MATCH(Export_ControlTot!$A8,'Campus Enrol Disaggregation'!$O$5:$O$65,0),MATCH(O$1,'Campus Enrol Disaggregation'!$P$4:$AC$4,0)) -> 0
A9: 1997 | B9: =INDEX('Campus Enrol Disaggregation'!$P$5:$AC$65,MATCH(Export_ControlTot!$A9,'Campus Enrol Disaggregation'!$O$5:$O$65,0),MATCH(B$1,'Campus Enrol Disaggregation'!$P$4:$AC$4,0)) -> 31250 | C9: =INDEX('Campus Enrol Disaggregation'!$P$5:$AC$65,MATCH(Export_ControlTot!$A9,'Campus Enrol Disaggregation'!$O$5:$O$65,0),MATCH(C$1,'Campus Enrol Disaggregation'!$P$4:$AC$4,0)) -> 0 | D9: =INDEX('Campus Enrol Disaggregation'!$P$5:$AC$65,MATCH(Export_ControlTot!$A9,'Campus Enrol Disaggregation'!$O$5:$O$65,0),MATCH(D$1,'Campus Enrol Disaggregation'!$P$4:$AC$4,0)) -> 12850 | E9: =INDEX('Campus Enrol Disaggregation'!$P$5:$AC$65,MATCH(Export_ControlTot!$A9,'Campus Enrol Disaggregation'!$O$5:$O$65,0),MATCH(E$1,'Campus Enrol Disaggregation'!$P$4:$AC$4,0)) -> 4500 | F9: =INDEX('Campus Enrol Disaggregation'!$P$5:$AC$65,MATCH(Export_ControlTot!$A9,'Campus Enrol Disaggregation'!$O$5:$O$65,0),MATCH(F$1,'Campus Enrol Disaggregation'!$P$4:$AC$4,0)) -> 1100 | G9: =INDEX('Campus Enrol Disaggregation'!$P$5:$AC$65,MATCH(Export_ControlTot!$A9,'Campus Enrol Disaggregation'!$O$5:$O$65,0),MATCH(G$1,'Campus Enrol Disaggregation'!$P$4:$AC$4,0)) -> 4000 | H9: =INDEX('Campus Enrol Disaggregation'!$P$5:$AC$65,MATCH(Export_ControlTot!$A9,'Campus Enrol Disaggregation'!$O$5:$O$65,0),MATCH(H$1,'Campus Enrol Disaggregation'!$P$4:$AC$4,0)) -> 25200 | I9: =INDEX('Campus Enrol Disaggregation'!$P$5:$AC$65,MATCH(Export_ControlTot!$A9,'Campus Enrol Disaggregation'!$O$5:$O$65,0),MATCH(I$1,'Campus Enrol Disaggregation'!$P$4:$AC$4,0)) -> 16000 | ... O9: =INDEX('Campus Enrol Disaggregation'!$P$5:$AC$65,MATCH(Export_ControlTot!$A9,'Campus Enrol Disaggregation'!$O$5:$O$65,0),MATCH(O$1,'Campus Enrol Disaggregation'!$P$4:$AC$4,0)) -> 0
A10: 1998 | B10: =INDEX('Campus Enrol Disaggregation'!$P$5:$AC$65,MATCH(Export_ControlTot!$A10,'Campus Enrol Disaggregation'!$O$5:$O$65,0),MATCH(B$1,'Campus Enrol Disaggregation'!$P$4:$AC$4,0)) -> 32200 | C10: =INDEX('Campus Enrol Disaggregation'!$P$5:$AC$65,MATCH(Export_ControlTot!$A10,'Campus Enrol Disaggregation'!$O$5:$O$65,0),MATCH(C$1,'Campus Enrol Disaggregation'!$P$4:$AC$4,0)) -> 0 | D10: =INDEX('Campus Enrol Disaggregation'!$P$5:$AC$65,MATCH(Export_ControlTot!$A10,'Campus Enrol Disaggregation'!$O$5:$O$65,0),MATCH(D$1,'Campus Enrol Disaggregation'!$P$4:$AC$4,0)) -> 10450 | E10: =INDEX('Campus Enrol Disaggregation'!$P$5:$AC$65,MATCH(Export_ControlTot!$A10,'Campus Enrol Disaggregation'!$O$5:$O$65,0),MATCH(E$1,'Campus Enrol Disaggregation'!$P$4:$AC$4,0)) -> 3650 | F10: =INDEX('Campus Enrol Disaggregation'!$P$5:$AC$65,MATCH(Export_ControlTot!$A10,'Campus Enrol Disaggregation'!$O$5:$O$65,0),MATCH(F$1,'Campus Enrol Disaggregation'!$P$4:$AC$4,0)) -> 900 | G10: =INDEX('Campus Enrol Disaggregation'!$P$5:$AC$65,MATCH(Export_ControlTot!$A10,'Campus Enrol Disaggregation'!$O$5:$O$65,0),MATCH(G$1,'Campus Enrol Disaggregation'!$P$4:$AC$4,0)) -> 3250 | H10: =INDEX('Campus Enrol Disaggregation'!$P$5:$AC$65,MATCH(Export_ControlTot!$A10,'Campus Enrol Disaggregation'!$O$5:$O$65,0),MATCH(H$1,'Campus Enrol Disaggregation'!$P$4:$AC$4,0)) -> 24350 | I10: =INDEX('Campus Enrol Disaggregation'!$P$5:$AC$65,MATCH(Export_ControlTot!$A10,'Campus Enrol Disaggregation'!$O$5:$O$65,0),MATCH(I$1,'Campus Enrol Disaggregation'!$P$4:$AC$4,0)) -> 18150 | ... O10: =INDEX('Campus Enrol Disaggregation'!$P$5:$AC$65,MATCH(Export_ControlTot!$A10,'Campus Enrol Disaggregation'!$O$5:$O$65,0),MATCH(O$1,'Campus Enrol Disaggregation'!$P$4:$AC$4,0)) -> 0
A11: 1999 | B11: =INDEX('Campus Enrol Disaggregation'!$P$5:$AC$65,MATCH(Export_ControlTot!$A11,'Campus Enrol Disaggregation'!$O$5:$O$65,0),MATCH(B$1,'Campus Enrol Disaggregation'!$P$4:$AC$4,0)) -> 32750 | C11: =INDEX('Campus Enrol Disaggregation'!$P$5:$AC$65,MATCH(Export_ControlTot!$A11,'Campus Enrol Disaggregation'!$O$5:$O$65,0),MATCH(C$1,'Campus Enrol Disaggregation'!$P$4:$AC$4,0)) -> 0 | D11: =INDEX('Campus Enrol Disaggregation'!$P$5:$AC$65,MATCH(Export_ControlTot!$A11,'Campus Enrol Disaggregation'!$O$5:$O$65,0),MATCH(D$1,'Campus Enrol Disaggregation'!$P$4:$AC$4,0)) -> 11250 | E11: =INDEX('Campus Enrol Disaggregation'!$P$5:$AC$65,MATCH(Export_ControlTot!$A11,'Campus Enrol Disaggregation'!$O$5:$O$65,0),MATCH(E$1,'Campus Enrol Disaggregation'!$P$4:$AC$4,0)) -> 3950 | F11: =INDEX('Campus Enrol Disaggregation'!$P$5:$AC$65,MATCH(Export_ControlTot!$A11,'Campus Enrol Disaggregation'!$O$5:$O$65,0),MATCH(F$1,'Campus Enrol Disaggregation'!$P$4:$AC$4,0)) -> 1000 | G11: =INDEX('Campus Enrol Disaggregation'!$P$5:$AC$65,MATCH(Export_ControlTot!$A11,'Campus Enrol Disaggregation'!$O$5:$O$65,0),MATCH(G$1,'Campus Enrol Disaggregation'!$P$4:$AC$4,0)) -> 3500 | H11: =INDEX('Campus Enrol Disaggregation'!$P$5:$AC$65,MATCH(Export_ControlTot!$A11,'Campus Enrol Disaggregation'!$O$5:$O$65,0),MATCH(H$1,'Campus Enrol Disaggregation'!$P$4:$AC$4,0)) -> 25100 | I11: =INDEX('Campus Enrol Disaggregation'!$P$5:$AC$65,MATCH(Export_ControlTot!$A11,'Campus Enrol Disaggregation'!$O$5:$O$65,0),MATCH(I$1,'Campus Enrol Disaggregation'!$P$4:$AC$4,0)) -> 20050 | ... O11: =INDEX('Campus Enrol Disaggregation'!$P$5:$AC$65,MATCH(Export_ControlTot!$A11,'Campus Enrol Disaggregation'!$O$5:$O$65,0),MATCH(O$1,'Campus Enrol Disaggregation'!$P$4:$AC$4,0)) -> 0
A12: 2000 | B12: =INDEX('Campus Enrol Disaggregation'!$P$5:$AC$65,MATCH(Export_ControlTot!$A12,'Campus Enrol Disaggregation'!$O$5:$O$65,0),MATCH(B$1,'Campus Enrol Disaggregation'!$P$4:$AC$4,0)) -> 32550 | C12: =INDEX('Campus Enrol Disaggregation'!$P$5:$AC$65,MATCH(Export_ControlTot!$A12,'Campus Enrol Disaggregation'!$O$5:$O$65,0),MATCH(C$1,'Campus Enrol Disaggregation'!$P$4:$AC$4,0)) -> 0 | D12: =INDEX('Campus Enrol Disaggregation'!$P$5:$AC$65,MATCH(Export_ControlTot!$A12,'Campus Enrol Disaggregation'!$O$5:$O$65,0),MATCH(D$1,'Campus Enrol Disaggregation'!$P$4:$AC$4,0)) -> 11650 | E12: =INDEX('Campus Enrol Disaggregation'!$P$5:$AC$65,MATCH(Export_ControlTot!$A12,'Campus Enrol Disaggregation'!$O$5:$O$65,0),MATCH(E$1,'Campus Enrol Disaggregation'!$P$4:$AC$4,0)) -> 4100 | F12: =INDEX('Campus Enrol Disaggregation'!$P$5:$AC$65,MATCH(Export_ControlTot!$A12,'Campus Enrol Disaggregation'!$O$5:$O$65,0),MATCH(F$1,'Campus Enrol Disaggregation'!$P$4:$AC$4,0)) -> 1000 | G12: =INDEX('Campus Enrol Disaggregation'!$P$5:$AC$65,MATCH(Export_ControlTot!$A12,'Campus Enrol Disaggregation'!$O$5:$O$65,0),MATCH(G$1,'Campus Enrol Disaggregation'!$P$4:$AC$4,0)) -> 3600 | H12: =INDEX('Campus Enrol Disaggregation'!$P$5:$AC$65,MATCH(Export_ControlTot!$A12,'Campus Enrol Disaggregation'!$O$5:$O$65,0),MATCH(H$1,'Campus Enrol Disaggregation'!$P$4:$AC$4,0)) -> 25450 | I12: =INDEX('Campus Enrol Disaggregation'!$P$5:$AC$65,MATCH(Export_ControlTot!$A12,'Campus Enrol Disaggregation'!$O$5:$O$65,0),MATCH(I$1,'Campus Enrol Disaggregation'!$P$4:$AC$4,0)) -> 20950 | ... O12: =INDEX('Campus Enrol Disaggregation'!$P$5:$AC$65,MATCH(Export_ControlTot!$A12,'Campus Enrol Disaggregation'!$O$5:$O$65,0),MATCH(O$1,'Campus Enrol Disaggregation'!$P$4:$AC$4,0)) -> 0
A13: 2001 | B13: =INDEX('Campus Enrol Disaggregation'!$P$5:$AC$65,MATCH(Export_ControlTot!$A13,'Campus Enrol Disaggregation'!$O$5:$O$65,0),MATCH(B$1,'Campus Enrol Disaggregation'!$P$4:$AC$4,0)) -> 32750 | C13: =INDEX('Campus Enrol Disaggregation'!$P$5:$AC$65,MATCH(Export_ControlTot!$A13,'Campus Enrol Disaggregation'!$O$5:$O$65,0),MATCH(C$1,'Campus Enrol Disaggregation'!$P$4:$AC$4,0)) -> 0 | D13: =INDEX('Campus Enrol Disaggregation'!$P$5:$AC$65,MATCH(Export_ControlTot!$A13,'Campus Enrol Disaggregation'!$O$5:$O$65,0),MATCH(D$1,'Campus Enrol Disaggregation'!$P$4:$AC$4,0)) -> 12800 | E13: =INDEX('Campus Enrol Disaggregation'!$P$5:$AC$65,MATCH(Export_ControlTot!$A13,'Campus Enrol Disaggregation'!$O$5:$O$65,0),MATCH(E$1,'Campus Enrol Disaggregation'!$P$4:$AC$4,0)) -> 4450 | F13: =INDEX('Campus Enrol Disaggregation'!$P$5:$AC$65,MATCH(Export_ControlTot!$A13,'Campus Enrol Disaggregation'!$O$5:$O$65,0),MATCH(F$1,'Campus Enrol Disaggregation'!$P$4:$AC$4,0)) -> 1100 | G13: =INDEX('Campus Enrol Disaggregation'!$P$5:$AC$65,MATCH(Export_ControlTot!$A13,'Campus Enrol Disaggregation'!$O$5:$O$65,0),MATCH(G$1,'Campus Enrol Disaggregation'!$P$4:$AC$4,0)) -> 3950 | H13: =INDEX('Campus Enrol Disaggregation'!$P$5:$AC$65,MATCH(Export_ControlTot!$A13,'Campus Enrol Disaggregation'!$O$5:$O$65,0),MATCH(H$1,'Campus Enrol Disaggregation'!$P$4:$AC$4,0)) -> 26950 | I13: =INDEX('Campus Enrol Disaggregation'!$P$5:$AC$65,MATCH(Export_ControlTot!$A13,'Campus Enrol Disaggregation'!$O$5:$O$65,0),MATCH(I$1,'Campus Enrol Disaggregation'!$P$4:$AC$4,0)) -> 22600 | ... O13: =INDEX('Campus Enrol Disaggregation'!$P$5:$AC$65,MATCH(Export_ControlTot!$A13,'Campus Enrol Disaggregation'!$O$5:$O$65,0),MATCH(O$1,'Campus Enrol Disaggregation'!$P$4:$AC$4,0)) -> 0
... A62: 2050 | B62: =INDEX('Campus Enrol Disaggregation'!$P$5:$AC$65,MATCH(Export_ControlTot!$A62,'Campus Enrol Disaggregation'!$O$5:$O$65,0),MATCH(B$1,'Campus Enrol Disaggregation'!$P$4:$AC$4,0)) -> 39300 | C62: =INDEX('Campus Enrol Disaggregation'!$P$5:$AC$65,MATCH(Export_ControlTot!$A62,'Campus Enrol Disaggregation'!$O$5:$O$65,0),MATCH(C$1,'Campus Enrol Disaggregation'!$P$4:$AC$4,0)) -> 2000 | D62: =INDEX('Campus Enrol Disaggregation'!$P$5:$AC$65,MATCH(Export_ControlTot!$A62,'Campus Enrol Disaggregation'!$O$5:$O$65,0),MATCH(D$1,'Campus Enrol Disaggregation'!$P$4:$AC$4,0)) -> 21100 | E62: =INDEX('Campus Enrol Disaggregation'!$P$5:$AC$65,MATCH(Export_ControlTot!$A62,'Campus Enrol Disaggregation'!$O$5:$O$65,0),MATCH(E$1,'Campus Enrol Disaggregation'!$P$4:$AC$4,0)) -> 7400 | F62: =INDEX('Campus Enrol Disaggregation'!$P$5:$AC$65,MATCH(Export_ControlTot!$A62,'Campus Enrol Disaggregation'!$O$5:$O$65,0),MATCH(F$1,'Campus Enrol Disaggregation'!$P$4:$AC$4,0)) -> 1850 | G62: =INDEX('Campus Enrol Disaggregation'!$P$5:$AC$65,MATCH(Export_ControlTot!$A62,'Campus Enrol Disaggregation'!$O$5:$O$65,0),MATCH(G$1,'Campus Enrol Disaggregation'!$P$4:$AC$4,0)) -> 6550 | H62: =INDEX('Campus Enrol Disaggregation'!$P$5:$AC$65,MATCH(Export_ControlTot!$A62,'Campus Enrol Disaggregation'!$O$5:$O$65,0),MATCH(H$1,'Campus Enrol Disaggregation'!$P$4:$AC$4,0)) -> 41850 | I62: =INDEX('Campus Enrol Disaggregation'!$P$5:$AC$65,MATCH(Export_ControlTot!$A62,'Campus Enrol Disaggregation'!$O$5:$O$65,0),MATCH(I$1,'Campus Enrol Disaggregation'!$P$4:$AC$4,0)) -> 68000 | ... O62: =INDEX('Campus Enrol Disaggregation'!$P$5:$AC$65,MATCH(Export_ControlTot!$A62,'Campus Enrol Disaggregation'!$O$5:$O$65,0),MATCH(O$1,'Campus Enrol Disaggregation'!$P$4:$AC$4,0)) -> 3000

Sheet Export_Factors
A1: ;INDEX | B1: ENSIGN | C1: WESTMIN | D1: UOFU_Main | E1: UofU_Med | F1: WSU_Main | G1: WSU_Davis | H1: WSU_West | I1: SLCC_MAIN | J1: SLCC_SC | K1: SLCC_JD | L1: SLCC_Mead | M1: SLCC_ML | N1: SLCC_LB | O1: SLCC_HL | P1: SLCC_Airp | Q1: SLCC_West | R1: SLCC_HM | S1: BYU | T1: UVU_Main | U1: UVU_Geneva | V1: UVU_Lehi | W1: UVU_Vineyard | X1: UVU_Payson | Y1: Var_Name
A2: 1 | B2: =VLOOKUP(B1,'calc%concurrent'!$A$2:$B$15,2,FALSE) -> 0.1005 | C2: =VLOOKUP(C1,'calc%concurrent'!$A$2:$B$15,2,FALSE) -> 0.0115625 | D2: =VLOOKUP(D1,'calc%concurrent'!$A$2:$B$15,2,FALSE) -> 0.026040514 | E2: =D2 -> 0.026040514 | F2: =VLOOKUP(F1,'calc%concurrent'!$A$2:$B$15,2,FALSE) -> 0.21501654 | G2: =VLOOKUP(G1,'calc%concurrent'!$A$2:$B$15,2,FALSE) -> 0.30851477 | H2: =G2 -> 0.30851477 | I2: =VLOOKUP(I1,'calc%concurrent'!$A$2:$B$15,2,FALSE) -> 0.34092451 | J2: =VLOOKUP(J1,'calc%concurrent'!$A$2:$B$15,2,FALSE) -> 0.34092451 | K2: =VLOOKUP(K1,'calc%concurrent'!$A$2:$B$15,2,FALSE) -> 0.34092451 | L2: =K2 -> 0.34092451 | M2: =VLOOKUP(M1,'calc%concurrent'!$A$2:$B$15,2,FALSE) -> 0.34092451 | N2: =M2 -> 0.34092451 | O2: =N2 -> 0.34092451 | P2: =O2 -> 0.34092451 | Q2: =P2 -> 0.34092451 | R2: =Q2 -> 0.34092451 | S2: =VLOOKUP(S$1,'calc%concurrent'!$A$2:$B$15,2,FALSE) -> 0.026040514 | T2: =VLOOKUP(T1,'calc%concurrent'!$A$2:$B$15,2,FALSE) -> 0.26992029 | U2: =T2 -> 0.26992029 | V2: =VLOOKUP(V1,'calc%concurrent'!$A$2:$B$15,2,FALSE) -> 0.26992029 | W2: =VLOOKUP(W1,'calc%concurrent'!$A$2:$B$15,2,FALSE) -> 0.26992029 | X2: =VLOOKUP(X1,'calc%concurrent'!$A$2:$B$15,2,FALSE) -> 0.26992029 | Y2: Pct_Remove
A3: 2 | B3: =VLOOKUP(B$1,'FTE Rate Calcs'!$A$2:$B$15,2,FALSE) -> 1.1790281 | C3: =VLOOKUP(C$1,'FTE Rate Calcs'!$A$2:$B$15,2,FALSE) -> 1.0984237 | D3: =VLOOKUP(D$1,'FTE Rate Calcs'!$A$2:$B$15,2,FALSE) -> 1.0252202 | E3: =D3 -> 1.0252202 | F3: =VLOOKUP(F$1,'FTE Rate Calcs'!$A$2:$B$15,2,FALSE) -> 1.0375684 | G3: =VLOOKUP(G$1,'FTE Rate Calcs'!$A$2:$B$15,2,FALSE) -> 1.0375684 | H3: =G3 -> 1.0375684 | I3: =VLOOKUP(I$1,'FTE Rate Calcs'!$A$2:$B$15,2,FALSE) -> 1.2081372 | J3: =VLOOKUP(J$1,'FTE Rate Calcs'!$A$2:$B$15,2,FALSE) -> 1.2081372 | K3: =VLOOKUP(K$1,'FTE Rate Calcs'!$A$2:$B$15,2,FALSE) -> 1.2081372 | L3: =K3 -> 1.2081372 | M3: =VLOOKUP(M$1,'FTE Rate Calcs'!$A$2:$B$15,2,FALSE) -> 1.2081372 | N3: =M3 -> 1.2081372 | O3: =N3 -> 1.2081372 | P3: =O3 -> 1.2081372 | Q3: =P3 -> 1.2081372 | R3: =Q3 -> 1.2081372 | S3: =VLOOKUP(S$1,'FTE Rate Calcs'!$A$2:$B$15,2,FALSE) -> 1.0252202 | T3: =VLOOKUP(T$1,'FTE Rate Calcs'!$A$2:$B$15,2,FALSE) -> 1.0967772 | U3: =T3 -> 1.0967772 | V3: =VLOOKUP(V$1,'FTE Rate Calcs'!$A$2:$B$15,2,FALSE) -> 1.0967772 | W3: =VLOOKUP(W$1,'FTE Rate Calcs'!$A$2:$B$15,2,FALSE) -> 1.0967772 | X3: =VLOOKUP(X$1,'FTE Rate Calcs'!$A$2:$B$15,2,FALSE) -> 1.0967772 | Y3: FTERate
A4: 3 | B4: =VLOOKUP(B$1,'HBC Rates'!$A$2:$B$15,2,FALSE) -> 0.9301 | C4: =VLOOKUP(C$1,'HBC Rates'!$A$2:$B$15,2,FALSE) -> 0.9301 | D4: =VLOOKUP(D$1,'HBC Rates'!$A$2:$B$15,2,FALSE) -> 0.9301 | E4: =D4 -> 0.9301 | F4: =VLOOKUP(F$1,'HBC Rates'!$A$2:$B$15,2,FALSE) -> 0.83 | G4: =VLOOKUP(G$1,'HBC Rates'!$A$2:$B$15,2,FALSE) -> 0.677 | H4: =G4 -> 0.677 | I4: =VLOOKUP(I$1,'HBC Rates'!$A$2:$B$15,2,FALSE) -> 0.6219 | J4: =VLOOKUP(J$1,'HBC Rates'!$A$2:$B$15,2,FALSE) -> 0.6422 | K4: =VLOOKUP(K$1,'HBC Rates'!$A$2:$B$15,2,FALSE) -> 0.5687 | L4: =K4 -> 0.5687 | M4: =VLOOKUP(M$1,'HBC Rates'!$A$2:$B$15,2,FALSE) -> 0.6158 | N4: =M4 -> 0.6158 | O4: =N4 -> 0.6158 | P4: =O4 -> 0.6158 | Q4: =P4 -> 0.6158 | R4: =Q4 -> 0.6158 | S4: =VLOOKUP(S$1,'HBC Rates'!$A$2:$B$15,2,FALSE) -> 0.9301 | T4: =VLOOKUP(T$1,'HBC Rates'!$A$2:$B$15,2,FALSE) -> 0.9452 | U4: =T4 -> 0.9452 | V4: =VLOOKUP(V$1,'HBC Rates'!$A$2:$B$15,2,FALSE) -> 0.9452 | W4: =VLOOKUP(W$1,'HBC Rates'!$A$2:$B$15,2,FALSE) -> 0.9452 | X4: =VLOOKUP(X$1,'HBC Rates'!$A$2:$B$15,2,FALSE) -> 0.9452 | Y4: HBCRates
A6: Note:
A7: Removal means concurrent, online degree etc.
A8: FTERate = FTE / Total Headcount, Total Headcount includes online and concurrent enrollment

Sheet Campus Enrol Disaggregation
O1: Enrollment Projections by Campus
O2: School: | P2: =IFERROR((FIND("_",P4)),P4) -> BYU | Q2: =IFERROR((FIND("_",Q4)),Q4) -> ENSIGN | R2: =IF(FIND("_",R4),LEFT(R4,FIND("_",R4)-1),R4) -> SLCC | S2: =IF(FIND("_",S4),LEFT(S4,FIND("_",S4)-1),S4) -> SLCC | T2: =IF(FIND("_",T4),LEFT(T4,FIND("_",T4)-1),T4) -> SLCC | U2: =IF(FIND("_",U4),LEFT(U4,FIND("_",U4)-1),U4) -> SLCC | V2: =IF(FIND("_",V4),LEFT(V4,FIND("_",V4)-1),V4) -> UOFU | AA2: =IF(FIND("_",AA4),LEFT(AA4,FIND("_",AA4)-1),AA4) -> WSU | AB2: =IF(FIND("_",AB4),LEFT(AB4,FIND("_",AB4)-1),AB4) -> WSU | AC2: =IFERROR((FIND("_",AC4)),AC4) -> WESTMIN
O3: % of School: | P3: 1 | Q3: 1 | R3: ='USHE 2020 Campus Totals'!D3 -> 0.52792553 | S3: ='USHE 2020 Campus Totals'!D6 -> 0.18466312 | T3: ='USHE 2020 Campus Totals'!D7 -> 0.046010638 | U3: ='USHE 2020 Campus Totals'!D10 -> 0.16374113 | V3: ='USHE 2020 Campus Totals'!D19 -> 0.97352413 | AA3: ='USHE 2020 Campus Totals'!D23 -> 0.75195472 | AB3: ='USHE 2020 Campus Totals'!D26 -> 0.19768935 | AC3: 1
O4: Year | P4: BYU | Q4: ENSIGN | R4: SLCC_MAIN | S4: SLCC_JD | T4: SLCC_ML | U4: SLCC_SC | V4: UOFU_Main | W4: UVU_Main | X4: UVU_Lehi | Y4: UVU_Payson | Z4: UVU_Vineyard | AA4: WSU_Main | AB4: WSU_Davis | AC4: WESTMIN | AD4: Total
O5: 1990 | P5: =MROUND(P$3*INDEX('College Enrollment Projections'!$AJ$2:$AP$62,MATCH('Campus Enrol Disaggregation'!$O5,'College Enrollment Projections'!$AI$2:$AI$62,0),MATCH('Campus Enrol Disaggregation'!P$2,'College Enrollment Projections'!$AJ$1:$AP$1,0)),50) -> 30450 | Q5: =MROUND(Q$3*INDEX('College Enrollment Projections'!$AJ$2:$AP$62,MATCH('Campus Enrol Disaggregation'!$O5,'College Enrollment Projections'!$AI$2:$AI$62,0),MATCH('Campus Enrol Disaggregation'!Q$2,'College Enrollment Projections'!$AJ$1:$AP$1,0)),50) -> 0 | R5: =MROUND(R$3*INDEX('College Enrollment Projections'!$AJ$2:$AP$62,MATCH('Campus Enrol Disaggregation'!$O5,'College Enrollment Projections'!$AI$2:$AI$62,0),MATCH('Campus Enrol Disaggregation'!R$2,'College Enrollment Projections'!$AJ$1:$AP$1,0)),50) -> 7050 | S5: =MROUND(S$3*INDEX('College Enrollment Projections'!$AJ$2:$AP$62,MATCH('Campus Enrol Disaggregation'!$O5,'College Enrollment Projections'!$AI$2:$AI$62,0),MATCH('Campus Enrol Disaggregation'!S$2,'College Enrollment Projections'!$AJ$1:$AP$1,0)),50) -> 2450 | T5: =MROUND(T$3*INDEX('College Enrollment Projections'!$AJ$2:$AP$62,MATCH('Campus Enrol Disaggregation'!$O5,'College Enrollment Projections'!$AI$2:$AI$62,0),MATCH('Campus Enrol Disaggregation'!T$2,'College Enrollment Projections'!$AJ$1:$AP$1,0)),50) -> 600 | U5: =MROUND(U$3*INDEX('College Enrollment Projections'!$AJ$2:$AP$62,MATCH('Campus Enrol Disaggregation'!$O5,'College Enrollment Projections'!$AI$2:$AI$62,0),MATCH('Campus Enrol Disaggregation'!U$2,'College Enrollment Projections'!$AJ$1:$AP$1,0)),50) -> 2200 | V5: =MROUND(V$3*INDEX('College Enrollment Projections'!$AJ$2:$AP$62,MATCH('Campus Enrol Disaggregation'!$O5,'College Enrollment Projections'!$AI$2:$AI$62,0),MATCH('Campus Enrol Disaggregation'!V$2,'College Enrollment Projections'!$AJ$1:$AP$1,0)),50) -> 23650 | W5: =MROUND(INDEX('MAG College Enrollment Forecast'!$B$4:$H$64,MATCH($O5,'MAG College Enrollment Forecast'!$A$4:$A$64,0),MATCH(W$4,'MAG College Enrollment Forecast'!$B$1:$H$1,0)),50) -> 7900 | X5: =MROUND(INDEX('MAG College Enrollment Forecast'!$B$4:$H$64,MATCH($O5,'MAG College Enrollment Forecast'!$A$4:$A$64,0),MATCH(X$4,'MAG College Enrollment Forecast'!$B$1:$H$1,0)),50) -> 0 | Y5: =MROUND(INDEX('MAG College Enrollment Forecast'!$B$4:$H$64,MATCH($O5,'MAG College Enrollment Forecast'!$A$4:$A$64,0),MATCH(Y$4,'MAG College Enrollment Forecast'!$B$1:$H$1,0)),50) -> 0 | Z5: =MROUND(INDEX('MAG College Enrollment Forecast'!$B$4:$H$64,MATCH($O5,'MAG College Enrollment Forecast'!$A$4:$A$64,0),MATCH(Z$4,'MAG College Enrollment Forecast'!$B$1:$H$1,0)),50) -> 0 | AA5: =MROUND(AA$3*INDEX('College Enrollment Projections'!$AJ$2:$AP$62,MATCH('Campus Enrol Disaggregation'!$O5,'College Enrollment Projections'!$AI$2:$AI$62,0),MATCH('Campus Enrol Disaggregation'!AA$2,'College Enrollment Projections'!$AJ$1:$AP$1,0)),50) -> 10100 | AB5: =MROUND(AB$3*INDEX('College Enrollment Projections'!$AJ$2:$AP$62,MATCH('Campus Enrol Disaggregation'!$O5,'College Enrollment Projections'!$AI$2:$AI$62,0),MATCH('Campus Enrol Disaggregation'!AB$2,'College Enrollment Projections'!$AJ$1:$AP$1,0)),50) -> 2650 | AC5: =MROUND(AC$3*INDEX('College Enrollment Projections'!$AJ$2:$AP$62,MATCH('Campus Enrol Disaggregation'!$O5,'College Enrollment Projections'!$AI$2:$AI$62,0),MATCH('Campus Enrol Disaggregation'!AC$2,'College Enrollment Projections'!$AJ$1:$AP$1,0)),50) -> 0 | AD5: =SUM(P5:AC5) -> 87050
O6: 1991 | P6: =MROUND(P$3*INDEX('College Enrollment Projections'!$AJ$2:$AP$62,MATCH('Campus Enrol Disaggregation'!$O6,'College Enrollment Projections'!$AI$2:$AI$62,0),MATCH('Campus Enrol Disaggregation'!P$2,'College Enrollment Projections'!$AJ$1:$AP$1,0)),50) -> 31100 | Q6: =MROUND(Q$3*INDEX('College Enrollment Projections'!$AJ$2:$AP$62,MATCH('Campus Enrol Disaggregation'!$O6,'College Enrollment Projections'!$AI$2:$AI$62,0),MATCH('Campus Enrol Disaggregation'!Q$2,'College Enrollment Projections'!$AJ$1:$AP$1,0)),50) -> 0 | R6: =MROUND(R$3*INDEX('College Enrollment Projections'!$AJ$2:$AP$62,MATCH('Campus Enrol Disaggregation'!$O6,'College Enrollment Projections'!$AI$2:$AI$62,0),MATCH('Campus Enrol Disaggregation'!R$2,'College Enrollment Projections'!$AJ$1:$AP$1,0)),50) -> 8450 | S6: =MROUND(S$3*INDEX('College Enrollment Projections'!$AJ$2:$AP$62,MATCH('Campus Enrol Disaggregation'!$O6,'College Enrollment Projections'!$AI$2:$AI$62,0),MATCH('Campus Enrol Disaggregation'!S$2,'College Enrollment Projections'!$AJ$1:$AP$1,0)),50) -> 2950 | T6: =MROUND(T$3*INDEX('College Enrollment Projections'!$AJ$2:$AP$62,MATCH('Campus Enrol Disaggregation'!$O6,'College Enrollment Projections'!$AI$2:$AI$62,0),MATCH('Campus Enrol Disaggregation'!T$2,'College Enrollment Projections'!$AJ$1:$AP$1,0)),50) -> 750 | U6: =MROUND(U$3*INDEX('College Enrollment Projections'!$AJ$2:$AP$62,MATCH('Campus Enrol Disaggregation'!$O6,'College Enrollment Projections'!$AI$2:$AI$62,0),MATCH('Campus Enrol Disaggregation'!U$2,'College Enrollment Projections'!$AJ$1:$AP$1,0)),50) -> 2600 | V6: =MROUND(V$3*INDEX('College Enrollment Projections'!$AJ$2:$AP$62,MATCH('Campus Enrol Disaggregation'!$O6,'College Enrollment Projections'!$AI$2:$AI$62,0),MATCH('Campus Enrol Disaggregation'!V$2,'College Enrollment Projections'!$AJ$1:$AP$1,0)),50) -> 24900 | W6: =MROUND(INDEX('MAG College Enrollment Forecast'!$B$4:$H$64,MATCH($O6,'MAG College Enrollment Forecast'!$A$4:$A$64,0),MATCH(W$4,'MAG College Enrollment Forecast'!$B$1:$H$1,0)),50) -> 8800 | X6: =MROUND(INDEX('MAG College Enrollment Forecast'!$B$4:$H$64,MATCH($O6,'MAG College Enrollment Forecast'!$A$4:$A$64,0),MATCH(X$4,'MAG College Enrollment Forecast'!$B$1:$H$1,0)),50) -> 0 | Y6: =MROUND(INDEX('MAG College Enrollment Forecast'!$B$4:$H$64,MATCH($O6,'MAG College Enrollment Forecast'!$A$4:$A$64,0),MATCH(Y$4,'MAG College Enrollment Forecast'!$B$1:$H$1,0)),50) -> 0 | Z6: =MROUND(INDEX('MAG College Enrollment Forecast'!$B$4:$H$64,MATCH($O6,'MAG College Enrollment Forecast'!$A$4:$A$64,0),MATCH(Z$4,'MAG College Enrollment Forecast'!$B$1:$H$1,0)),50) -> 0 | AA6: =MROUND(AA$3*INDEX('College Enrollment Projections'!$AJ$2:$AP$62,MATCH('Campus Enrol Disaggregation'!$O6,'College Enrollment Projections'!$AI$2:$AI$62,0),MATCH('Campus Enrol Disaggregation'!AA$2,'College Enrollment Projections'!$AJ$1:$AP$1,0)),50) -> 10900 | AB6: =MROUND(AB$3*INDEX('College Enrollment Projections'!$AJ$2:$AP$62,MATCH('Campus Enrol Disaggregation'!$O6,'College Enrollment Projections'!$AI$2:$AI$62,0),MATCH('Campus Enrol Disaggregation'!AB$2,'College Enrollment Projections'!$AJ$1:$AP$1,0)),50) -> 2850 | AC6: =MROUND(AC$3*INDEX('College Enrollment Projections'!$AJ$2:$AP$62,MATCH('Campus Enrol Disaggregation'!$O6,'College Enrollment Projections'!$AI$2:$AI$62,0),MATCH('Campus Enrol Disaggregation'!AC$2,'College Enrollment Projections'!$AJ$1:$AP$1,0)),50) -> 0 | AD6: =SUM(P6:AC6) -> 93300
O7: 1992 | P7: =MROUND(P$3*INDEX('College Enrollment Projections'!$AJ$2:$AP$62,MATCH('Campus Enrol Disaggregation'!$O7,'College Enrollment Projections'!$AI$2:$AI$62,0),MATCH('Campus Enrol Disaggregation'!P$2,'College Enrollment Projections'!$AJ$1:$AP$1,0)),50) -> 31100 | Q7: =MROUND(Q$3*INDEX('College Enrollment Projections'!$AJ$2:$AP$62,MATCH('Campus Enrol Disaggregation'!$O7,'College Enrollment Projections'!$AI$2:$AI$62,0),MATCH('Campus Enrol Disaggregation'!Q$2,'College Enrollment Projections'!$AJ$1:$AP$1,0)),50) -> 0 | R7: =MROUND(R$3*INDEX('College Enrollment Projections'!$AJ$2:$AP$62,MATCH('Campus Enrol Disaggregation'!$O7,'College Enrollment Projections'!$AI$2:$AI$62,0),MATCH('Campus Enrol Disaggregation'!R$2,'College Enrollment Projections'!$AJ$1:$AP$1,0)),50) -> 9400 | S7: =MROUND(S$3*INDEX('College Enrollment Projections'!$AJ$2:$AP$62,MATCH('Campus Enrol Disaggregation'!$O7,'College Enrollment Projections'!$AI$2:$AI$62,0),MATCH('Campus Enrol Disaggregation'!S$2,'College Enrollment Projections'!$AJ$1:$AP$1,0)),50) -> 3300 | T7: =MROUND(T$3*INDEX('College Enrollment Projections'!$AJ$2:$AP$62,MATCH('Campus Enrol Disaggregation'!$O7,'College Enrollment Projections'!$AI$2:$AI$62,0),MATCH('Campus Enrol Disaggregation'!T$2,'College Enrollment Projections'!$AJ$1:$AP$1,0)),50) -> 800 | U7: =MROUND(U$3*INDEX('College Enrollment Projections'!$AJ$2:$AP$62,MATCH('Campus Enrol Disaggregation'!$O7,'College Enrollment Projections'!$AI$2:$AI$62,0),MATCH('Campus Enrol Disaggregation'!U$2,'College Enrollment Projections'!$AJ$1:$AP$1,0)),50) -> 2900 | V7: =MROUND(V$3*INDEX('College Enrollment Projections'!$AJ$2:$AP$62,MATCH('Campus Enrol Disaggregation'!$O7,'College Enrollment Projections'!$AI$2:$AI$62,0),MATCH('Campus Enrol Disaggregation'!V$2,'College Enrollment Projections'!$AJ$1:$AP$1,0)),50) -> 25200 | W7: =MROUND(INDEX('MAG College Enrollment Forecast'!$B$4:$H$64,MATCH($O7,'MAG College Enrollment Forecast'!$A$4:$A$64,0),MATCH(W$4,'MAG College Enrollment Forecast'!$B$1:$H$1,0)),50) -> 9600 | X7: =MROUND(INDEX('MAG College Enrollment Forecast'!$B$4:$H$64,MATCH($O7,'MAG College Enrollment Forecast'!$A$4:$A$64,0),MATCH(X$4,'MAG College Enrollment Forecast'!$B$1:$H$1,0)),50) -> 0 | Y7: =MROUND(INDEX('MAG College Enrollment Forecast'!$B$4:$H$64,MATCH($O7,'MAG College Enrollment Forecast'!$A$4:$A$64,0),MATCH(Y$4,'MAG College Enrollment Forecast'!$B$1:$H$1,0)),50) -> 0 | Z7: =MROUND(INDEX('MAG College Enrollment Forecast'!$B$4:$H$64,MATCH($O7,'MAG College Enrollment Forecast'!$A$4:$A$64,0),MATCH(Z$4,'MAG College Enrollment Forecast'!$B$1:$H$1,0)),50) -> 0 | AA7: =MROUND(AA$3*INDEX('College Enrollment Projections'!$AJ$2:$AP$62,MATCH('Campus Enrol Disaggregation'!$O7,'College Enrollment Projections'!$AI$2:$AI$62,0),MATCH('Campus Enrol Disaggregation'!AA$2,'College Enrollment Projections'!$AJ$1:$AP$1,0)),50) -> 11250 | AB7: =MROUND(AB$3*INDEX('College Enrollment Projections'!$AJ$2:$AP$62,MATCH('Campus Enrol Disaggregation'!$O7,'College Enrollment Projections'!$AI$2:$AI$62,0),MATCH('Campus Enrol Disaggregation'!AB$2,'College Enrollment Projections'!$AJ$1:$AP$1,0)),50) -> 2950 | AC7: =MROUND(AC$3*INDEX('College Enrollment Projections'!$AJ$2:$AP$62,MATCH('Campus Enrol Disaggregation'!$O7,'College Enrollment Projections'!$AI$2:$AI$62,0),MATCH('Campus Enrol Disaggregation'!AC$2,'College Enrollment Projections'!$AJ$1:$AP$1,0)),50) -> 0 | AD7: =SUM(P7:AC7) -> 96500
O8: 1993 | P8: =MROUND(P$3*INDEX('College Enrollment Projections'!$AJ$2:$AP$62,MATCH('Campus Enrol Disaggregation'!$O8,'College Enrollment Projections'!$AI$2:$AI$62,0),MATCH('Campus Enrol Disaggregation'!P$2,'College Enrollment Projections'!$AJ$1:$AP$1,0)),50) -> 30550 | Q8: =MROUND(Q$3*INDEX('College Enrollment Projections'!$AJ$2:$AP$62,MATCH('Campus Enrol Disaggregation'!$O8,'College Enrollment Projections'!$AI$2:$AI$62,0),MATCH('Campus Enrol Disaggregation'!Q$2,'College Enrollment Projections'!$AJ$1:$AP$1,0)),50) -> 0 | R8: =MROUND(R$3*INDEX('College Enrollment Projections'!$AJ$2:$AP$62,MATCH('Campus Enrol Disaggregation'!$O8,'College Enrollment Projections'!$AI$2:$AI$62,0),MATCH('Campus Enrol Disaggregation'!R$2,'College Enrollment Projections'!$AJ$1:$AP$1,0)),50) -> 9650 | S8: =MROUND(S$3*INDEX('College Enrollment Projections'!$AJ$2:$AP$62,MATCH('Campus Enrol Disaggregation'!$O8,'College Enrollment Projections'!$AI$2:$AI$62,0),MATCH('Campus Enrol Disaggregation'!S$2,'College Enrollment Projections'!$AJ$1:$AP$1,0)),50) -> 3400 | T8: =MROUND(T$3*INDEX('College Enrollment Projections'!$AJ$2:$AP$62,MATCH('Campus Enrol Disaggregation'!$O8,'College Enrollment Projections'!$AI$2:$AI$62,0),MATCH('Campus Enrol Disaggregation'!T$2,'College Enrollment Projections'!$AJ$1:$AP$1,0)),50) -> 850 | U8: =MROUND(U$3*INDEX('College Enrollment Projections'!$AJ$2:$AP$62,MATCH('Campus Enrol Disaggregation'!$O8,'College Enrollment Projections'!$AI$2:$AI$62,0),MATCH('Campus Enrol Disaggregation'!U$2,'College Enrollment Projections'!$AJ$1:$AP$1,0)),50) -> 3000 | V8: =MROUND(V$3*INDEX('College Enrollment Projections'!$AJ$2:$AP$62,MATCH('Campus Enrol Disaggregation'!$O8,'College Enrollment Projections'!$AI$2:$AI$62,0),MATCH('Campus Enrol Disaggregation'!V$2,'College Enrollment Projections'!$AJ$1:$AP$1,0)),50) -> 25300 | W8: =MROUND(INDEX('MAG College Enrollment Forecast'!$B$4:$H$64,MATCH($O8,'MAG College Enrollment Forecast'!$A$4:$A$64,0),MATCH(W$4,'MAG College Enrollment Forecast'!$B$1:$H$1,0)),50) -> 10500 | X8: =MROUND(INDEX('MAG College Enrollment Forecast'!$B$4:$H$64,MATCH($O8,'MAG College Enrollment Forecast'!$A$4:$A$64,0),MATCH(X$4,'MAG College Enrollment Forecast'!$B$1:$H$1,0)),50) -> 0 | Y8: =MROUND(INDEX('MAG College Enrollment Forecast'!$B$4:$H$64,MATCH($O8,'MAG College Enrollment Forecast'!$A$4:$A$64,0),MATCH(Y$4,'MAG College Enrollment Forecast'!$B$1:$H$1,0)),50) -> 0 | Z8: =MROUND(INDEX('MAG College Enrollment Forecast'!$B$4:$H$64,MATCH($O8,'MAG College Enrollment Forecast'!$A$4:$A$64,0),MATCH(Z$4,'MAG College Enrollment Forecast'!$B$1:$H$1,0)),50) -> 0 | AA8: =MROUND(AA$3*INDEX('College Enrollment Projections'!$AJ$2:$AP$62,MATCH('Campus Enrol Disaggregation'!$O8,'College Enrollment Projections'!$AI$2:$AI$62,0),MATCH('Campus Enrol Disaggregation'!AA$2,'College Enrollment Projections'!$AJ$1:$AP$1,0)),50) -> 10850 | AB8: =MROUND(AB$3*INDEX('College Enrollment Projections'!$AJ$2:$AP$62,MATCH('Campus Enrol Disaggregation'!$O8,'College Enrollment Projections'!$AI$2:$AI$62,0),MATCH('Campus Enrol Disaggregation'!AB$2,'College Enrollment Projections'!$AJ$1:$AP$1,0)),50) -> 2850 | AC8: =MROUND(AC$3*INDEX('College Enrollment Projections'!$AJ$2:$AP$62,MATCH('Campus Enrol Disaggregation'!$O8,'College Enrollment Projections'!$AI$2:$AI$62,0),MATCH('Campus Enrol Disaggregation'!AC$2,'College Enrollment Projections'!$AJ$1:$AP$1,0)),50) -> 0 | AD8: =SUM(P8:AC8) -> 96950
O9: 1994 | P9: =MROUND(P$3*INDEX('College Enrollment Projections'!$AJ$2:$AP$62,MATCH('Campus Enrol Disaggregation'!$O9,'College Enrollment Projections'!$AI$2:$AI$62,0),MATCH('Campus Enrol Disaggregation'!P$2,'College Enrollment Projections'!$AJ$1:$AP$1,0)),50) -> 30400 | Q9: =MROUND(Q$3*INDEX('College Enrollment Projections'!$AJ$2:$AP$62,MATCH('Campus Enrol Disaggregation'!$O9,'College Enrollment Projections'!$AI$2:$AI$62,0),MATCH('Campus Enrol Disaggregation'!Q$2,'College Enrollment Projections'!$AJ$1:$AP$1,0)),50) -> 0 | R9: =MROUND(R$3*INDEX('College Enrollment Projections'!$AJ$2:$AP$62,MATCH('Campus Enrol Disaggregation'!$O9,'College Enrollment Projections'!$AI$2:$AI$62,0),MATCH('Campus Enrol Disaggregation'!R$2,'College Enrollment Projections'!$AJ$1:$AP$1,0)),50) -> 10250 | S9: =MROUND(S$3*INDEX('College Enrollment Projections'!$AJ$2:$AP$62,MATCH('Campus Enrol Disaggregation'!$O9,'College Enrollment Projections'!$AI$2:$AI$62,0),MATCH('Campus Enrol Disaggregation'!S$2,'College Enrollment Projections'!$AJ$1:$AP$1,0)),50) -> 3600 | T9: =MROUND(T$3*INDEX('College Enrollment Projections'!$AJ$2:$AP$62,MATCH('Campus Enrol Disaggregation'!$O9,'College Enrollment Projections'!$AI$2:$AI$62,0),MATCH('Campus Enrol Disaggregation'!T$2,'College Enrollment Projections'!$AJ$1:$AP$1,0)),50) -> 900 | U9: =MROUND(U$3*INDEX('College Enrollment Projections'!$AJ$2:$AP$62,MATCH('Campus Enrol Disaggregation'!$O9,'College Enrollment Projections'!$AI$2:$AI$62,0),MATCH('Campus Enrol Disaggregation'!U$2,'College Enrollment Projections'!$AJ$1:$AP$1,0)),50) -> 3200 | V9: =MROUND(V$3*INDEX('College Enrollment Projections'!$AJ$2:$AP$62,MATCH('Campus Enrol Disaggregation'!$O9,'College Enrollment Projections'!$AI$2:$AI$62,0),MATCH('Campus Enrol Disaggregation'!V$2,'College Enrollment Projections'!$AJ$1:$AP$1,0)),50) -> 24950 | W9: =MROUND(INDEX('MAG College Enrollment Forecast'!$B$4:$H$64,MATCH($O9,'MAG College Enrollment Forecast'!$A$4:$A$64,0),MATCH(W$4,'MAG College Enrollment Forecast'!$B$1:$H$1,0)),50) -> 13300 | X9: =MROUND(INDEX('MAG College Enrollment Forecast'!$B$4:$H$64,MATCH($O9,'MAG College Enrollment Forecast'!$A$4:$A$64,0),MATCH(X$4,'MAG College Enrollment Forecast'!$B$1:$H$1,0)),50) -> 0 | Y9: =MROUND(INDEX('MAG College Enrollment Forecast'!$B$4:$H$64,MATCH($O9,'MAG College Enrollment Forecast'!$A$4:$A$64,0),MATCH(Y$4,'MAG College Enrollment Forecast'!$B$1:$H$1,0)),50) -> 0 | Z9: =MROUND(INDEX('MAG College Enrollment Forecast'!$B$4:$H$64,MATCH($O9,'MAG College Enrollment Forecast'!$A$4:$A$64,0),MATCH(Z$4,'MAG College Enrollment Forecast'!$B$1:$H$1,0)),50) -> 0 | AA9: =MROUND(AA$3*INDEX('College Enrollment Projections'!$AJ$2:$AP$62,MATCH('Campus Enrol Disaggregation'!$O9,'College Enrollment Projections'!$AI$2:$AI$62,0),MATCH('Campus Enrol Disaggregation'!AA$2,'College Enrollment Projections'!$AJ$1:$AP$1,0)),50) -> 10700 | AB9: =MROUND(AB$3*INDEX('College Enrollment Projections'!$AJ$2:$AP$62,MATCH('Campus Enrol Disaggregation'!$O9,'College Enrollment Projections'!$AI$2:$AI$62,0),MATCH('Campus Enrol Disaggregation'!AB$2,'College Enrollment Projections'!$AJ$1:$AP$1,0)),50) -> 2800 | AC9: =MROUND(AC$3*INDEX('College Enrollment Projections'!$AJ$2:$AP$62,MATCH('Campus Enrol Disaggregation'!$O9,'College Enrollment Projections'!$AI$2:$AI$62,0),MATCH('Campus Enrol Disaggregation'!AC$2,'College Enrollment Projections'!$AJ$1:$AP$1,0)),50) -> 0 | AD9: =SUM(P9:AC9) -> 100100
O10: 1995 | P10: =MROUND(P$3*INDEX('College Enrollment Projections'!$AJ$2:$AP$62,MATCH('Campus Enrol Disaggregation'!$O10,'College Enrollment Projections'!$AI$2:$AI$62,0),MATCH('Campus Enrol Disaggregation'!P$2,'College Enrollment Projections'!$AJ$1:$AP$1,0)),50) -> 30450 | Q10: =MROUND(Q$3*INDEX('College Enrollment Projections'!$AJ$2:$AP$62,MATCH('Campus Enrol Disaggregation'!$O10,'College Enrollment Projections'!$AI$2:$AI$62,0),MATCH('Campus Enrol Disaggregation'!Q$2,'College Enrollment Projections'!$AJ$1:$AP$1,0)),50) -> 0 | R10: =MROUND(R$3*INDEX('College Enrollment Projections'!$AJ$2:$AP$62,MATCH('Campus Enrol Disaggregation'!$O10,'College Enrollment Projections'!$AI$2:$AI$62,0),MATCH('Campus Enrol Disaggregation'!R$2,'College Enrollment Projections'!$AJ$1:$AP$1,0)),50) -> 11000 | S10: =MROUND(S$3*INDEX('College Enrollment Projections'!$AJ$2:$AP$62,MATCH('Campus Enrol Disaggregation'!$O10,'College Enrollment Projections'!$AI$2:$AI$62,0),MATCH('Campus Enrol Disaggregation'!S$2,'College Enrollment Projections'!$AJ$1:$AP$1,0)),50) -> 3850 | T10: =MROUND(T$3*INDEX('College Enrollment Projections'!$AJ$2:$AP$62,MATCH('Campus Enrol Disaggregation'!$O10,'College Enrollment Projections'!$AI$2:$AI$62,0),MATCH('Campus Enrol Disaggregation'!T$2,'College Enrollment Projections'!$AJ$1:$AP$1,0)),50) -> 950 | U10: =MROUND(U$3*INDEX('College Enrollment Projections'!$AJ$2:$AP$62,MATCH('Campus Enrol Disaggregation'!$O10,'College Enrollment Projections'!$AI$2:$AI$62,0),MATCH('Campus Enrol Disaggregation'!U$2,'College Enrollment Projections'!$AJ$1:$AP$1,0)),50) -> 3400 | V10: =MROUND(V$3*INDEX('College Enrollment Projections'!$AJ$2:$AP$62,MATCH('Campus Enrol Disaggregation'!$O10,'College Enrollment Projections'!$AI$2:$AI$62,0),MATCH('Campus Enrol Disaggregation'!V$2,'College Enrollment Projections'!$AJ$1:$AP$1,0)),50) -> 26100 | W10: =MROUND(INDEX('MAG College Enrollment Forecast'!$B$4:$H$64,MATCH($O10,'MAG College Enrollment Forecast'!$A$4:$A$64,0),MATCH(W$4,'MAG College Enrollment Forecast'!$B$1:$H$1,0)),50) -> 14050 | X10: =MROUND(INDEX('MAG College Enrollment Forecast'!$B$4:$H$64,MATCH($O10,'MAG College Enrollment Forecast'!$A$4:$A$64,0),MATCH(X$4,'MAG College Enrollment Forecast'!$B$1:$H$1,0)),50) -> 0 | Y10: =MROUND(INDEX('MAG College Enrollment Forecast'!$B$4:$H$64,MATCH($O10,'MAG College Enrollment Forecast'!$A$4:$A$64,0),MATCH(Y$4,'MAG College Enrollment Forecast'!$B$1:$H$1,0)),50) -> 0 | Z10: =MROUND(INDEX('MAG College Enrollment Forecast'!$B$4:$H$64,MATCH($O10,'MAG College Enrollment Forecast'!$A$4:$A$64,0),MATCH(Z$4,'MAG College Enrollment Forecast'!$B$1:$H$1,0)),50) -> 0 | AA10: =MROUND(AA$3*INDEX('College Enrollment Projections'!$AJ$2:$AP$62,MATCH('Campus Enrol Disaggregation'!$O10,'College Enrollment Projections'!$AI$2:$AI$62,0),MATCH('Campus Enrol Disaggregation'!AA$2,'College Enrollment Projections'!$AJ$1:$AP$1,0)),50) -> 10500 | AB10: =MROUND(AB$3*INDEX('College Enrollment Projections'!$AJ$2:$AP$62,MATCH('Campus Enrol Disaggregation'!$O10,'College Enrollment Projections'!$AI$2:$AI$62,0),MATCH('Campus Enrol Disaggregation'!AB$2,'College Enrollment Projections'!$AJ$1:$AP$1,0)),50) -> 2750 | AC10: =MROUND(AC$3*INDEX('College Enrollment Projections'!$AJ$2:$AP$62,MATCH('Campus Enrol Disaggregation'!$O10,'College Enrollment Projections'!$AI$2:$AI$62,0),MATCH('Campus Enrol Disaggregation'!AC$2,'College Enrollment Projections'!$AJ$1:$AP$1,0)),50) -> 0 | AD10: =SUM(P10:AC10) -> 103050
O11: 1996 | P11: =MROUND(P$3*INDEX('College Enrollment Projections'!$AJ$2:$AP$62,MATCH('Campus Enrol Disaggregation'!$O11,'College Enrollment Projections'!$AI$2:$AI$62,0),MATCH('Campus Enrol Disaggregation'!P$2,'College Enrollment Projections'!$AJ$1:$AP$1,0)),50) -> 30550 | Q11: =MROUND(Q$3*INDEX('College Enrollment Projections'!$AJ$2:$AP$62,MATCH('Campus Enrol Disaggregation'!$O11,'College Enrollment Projections'!$AI$2:$AI$62,0),MATCH('Campus Enrol Disaggregation'!Q$2,'College Enrollment Projections'!$AJ$1:$AP$1,0)),50) -> 0 | R11: =MROUND(R$3*INDEX('College Enrollment Projections'!$AJ$2:$AP$62,MATCH('Campus Enrol Disaggregation'!$O11,'College Enrollment Projections'!$AI$2:$AI$62,0),MATCH('Campus Enrol Disaggregation'!R$2,'College Enrollment Projections'!$AJ$1:$AP$1,0)),50) -> 11800 | S11: =MROUND(S$3*INDEX('College Enrollment Projections'!$AJ$2:$AP$62,MATCH('Campus Enrol Disaggregation'!$O11,'College Enrollment Projections'!$AI$2:$AI$62,0),MATCH('Campus Enrol Disaggregation'!S$2,'College Enrollment Projections'!$AJ$1:$AP$1,0)),50) -> 4150 | T11: =MROUND(T$3*INDEX('College Enrollment Projections'!$AJ$2:$AP$62,MATCH('Campus Enrol Disaggregation'!$O11,'College Enrollment Projections'!$AI$2:$AI$62,0),MATCH('Campus Enrol Disaggregation'!T$2,'College Enrollment Projections'!$AJ$1:$AP$1,0)),50) -> 1050 | U11: =MROUND(U$3*INDEX('College Enrollment Projections'!$AJ$2:$AP$62,MATCH('Campus Enrol Disaggregation'!$O11,'College Enrollment Projections'!$AI$2:$AI$62,0),MATCH('Campus Enrol Disaggregation'!U$2,'College Enrollment Projections'!$AJ$1:$AP$1,0)),50) -> 3650 | V11: =MROUND(V$3*INDEX('College Enrollment Projections'!$AJ$2:$AP$62,MATCH('Campus Enrol Disaggregation'!$O11,'College Enrollment Projections'!$AI$2:$AI$62,0),MATCH('Campus Enrol Disaggregation'!V$2,'College Enrollment Projections'!$AJ$1:$AP$1,0)),50) -> 25400 | W11: =MROUND(INDEX('MAG College Enrollment Forecast'!$B$4:$H$64,MATCH($O11,'MAG College Enrollment Forecast'!$A$4:$A$64,0),MATCH(W$4,'MAG College Enrollment Forecast'!$B$1:$H$1,0)),50) -> 14750 | X11: =MROUND(INDEX('MAG College Enrollment Forecast'!$B$4:$H$64,MATCH($O11,'MAG College Enrollment Forecast'!$A$4:$A$64,0),MATCH(X$4,'MAG College Enrollment Forecast'!$B$1:$H$1,0)),50) -> 0 | Y11: =MROUND(INDEX('MAG College Enrollment Forecast'!$B$4:$H$64,MATCH($O11,'MAG College Enrollment Forecast'!$A$4:$A$64,0),MATCH(Y$4,'MAG College Enrollment Forecast'!$B$1:$H$1,0)),50) -> 0 | Z11: =MROUND(INDEX('MAG College Enrollment Forecast'!$B$4:$H$64,MATCH($O11,'MAG College Enrollment Forecast'!$A$4:$A$64,0),MATCH(Z$4,'MAG College Enrollment Forecast'!$B$1:$H$1,0)),50) -> 0 | AA11: =MROUND(AA$3*INDEX('College Enrollment Projections'!$AJ$2:$AP$62,MATCH('Campus Enrol Disaggregation'!$O11,'College Enrollment Projections'!$AI$2:$AI$62,0),MATCH('Campus Enrol Disaggregation'!AA$2,'College Enrollment Projections'!$AJ$1:$AP$1,0)),50) -> 10450 | AB11: =MROUND(AB$3*INDEX('College Enrollment Projections'!$AJ$2:$AP$62,MATCH('Campus Enrol Disaggregation'!$O11,'College Enrollment Projections'!$AI$2:$AI$62,0),MATCH('Campus Enrol Disaggregation'!AB$2,'College Enrollment Projections'!$AJ$1:$AP$1,0)),50) -> 2750 | AC11: =MROUND(AC$3*INDEX('College Enrollment Projections'!$AJ$2:$AP$62,MATCH('Campus Enrol Disaggregation'!$O11,'College Enrollment Projections'!$AI$2:$AI$62,0),MATCH('Campus Enrol Disaggregation'!AC$2,'College Enrollment Projections'!$AJ$1:$AP$1,0)),50) -> 0 | AD11: =SUM(P11:AC11) -> 104550
O12: 1997 | P12: =MROUND(P$3*INDEX('College Enrollment Projections'!$AJ$2:$AP$62,MATCH('Campus Enrol Disaggregation'!$O12,'College Enrollment Projections'!$AI$2:$AI$62,0),MATCH('Campus Enrol Disaggregation'!P$2,'College Enrollment Projections'!$AJ$1:$AP$1,0)),50) -> 31250 | Q12: =MROUND(Q$3*INDEX('College Enrollment Projections'!$AJ$2:$AP$62,MATCH('Campus Enrol Disaggregation'!$O12,'College Enrollment Projections'!$AI$2:$AI$62,0),MATCH('Campus Enrol Disaggregation'!Q$2,'College Enrollment Projections'!$AJ$1:$AP$1,0)),50) -> 0 | R12: =MROUND(R$3*INDEX('College Enrollment Projections'!$AJ$2:$AP$62,MATCH('Campus Enrol Disaggregation'!$O12,'College Enrollment Projections'!$AI$2:$AI$62,0),MATCH('Campus Enrol Disaggregation'!R$2,'College Enrollment Projections'!$AJ$1:$AP$1,0)),50) -> 12850 | S12: =MROUND(S$3*INDEX('College Enrollment Projections'!$AJ$2:$AP$62,MATCH('Campus Enrol Disaggregation'!$O12,'College Enrollment Projections'!$AI$2:$AI$62,0),MATCH('Campus Enrol Disaggregation'!S$2,'College Enrollment Projections'!$AJ$1:$AP$1,0)),50) -> 4500 | T12: =MROUND(T$3*INDEX('College Enrollment Projections'!$AJ$2:$AP$62,MATCH('Campus Enrol Disaggregation'!$O12,'College Enrollment Projections'!$AI$2:$AI$62,0),MATCH('Campus Enrol Disaggregation'!T$2,'College Enrollment Projections'!$AJ$1:$AP$1,0)),50) -> 1100 | U12: =MROUND(U$3*INDEX('College Enrollment Projections'!$AJ$2:$AP$62,MATCH('Campus Enrol Disaggregation'!$O12,'College Enrollment Projections'!$AI$2:$AI$62,0),MATCH('Campus Enrol Disaggregation'!U$2,'College Enrollment Projections'!$AJ$1:$AP$1,0)),50) -> 4000 | V12: =MROUND(V$3*INDEX('College Enrollment Projections'!$AJ$2:$AP$62,MATCH('Campus Enrol Disaggregation'!$O12,'College Enrollment Projections'!$AI$2:$AI$62,0),MATCH('Campus Enrol Disaggregation'!V$2,'College Enrollment Projections'!$AJ$1:$AP$1,0)),50) -> 25200 | W12: =MROUND(INDEX('MAG College Enrollment Forecast'!$B$4:$H$64,MATCH($O12,'MAG College Enrollment Forecast'!$A$4:$A$64,0),MATCH(W$4,'MAG College Enrollment Forecast'!$B$1:$H$1,0)),50) -> 16000 | X12: =MROUND(INDEX('MAG College Enrollment Forecast'!$B$4:$H$64,MATCH($O12,'MAG College Enrollment Forecast'!$A$4:$A$64,0),MATCH(X$4,'MAG College Enrollment Forecast'!$B$1:$H$1,0)),50) -> 0 | Y12: =MROUND(INDEX('MAG College Enrollment Forecast'!$B$4:$H$64,MATCH($O12,'MAG College Enrollment Forecast'!$A$4:$A$64,0),MATCH(Y$4,'MAG College Enrollment Forecast'!$B$1:$H$1,0)),50) -> 0 | Z12: =MROUND(INDEX('MAG College Enrollment Forecast'!$B$4:$H$64,MATCH($O12,'MAG College Enrollment Forecast'!$A$4:$A$64,0),MATCH(Z$4,'MAG College Enrollment Forecast'!$B$1:$H$1,0)),50) -> 0 | AA12: =MROUND(AA$3*INDEX('College Enrollment Projections'!$AJ$2:$AP$62,MATCH('Campus Enrol Disaggregation'!$O12,'College Enrollment Projections'!$AI$2:$AI$62,0),MATCH('Campus Enrol Disaggregation'!AA$2,'College Enrollment Projections'!$AJ$1:$AP$1,0)),50) -> 11000 | AB12: =MROUND(AB$3*INDEX('College Enrollment Projections'!$AJ$2:$AP$62,MATCH('Campus Enrol Disaggregation'!$O12,'College Enrollment Projections'!$AI$2:$AI$62,0),MATCH('Campus Enrol Disaggregation'!AB$2,'College Enrollment Projections'!$AJ$1:$AP$1,0)),50) -> 2900 | AC12: =MROUND(AC$3*INDEX('College Enrollment Projections'!$AJ$2:$AP$62,MATCH('Campus Enrol Disaggregation'!$O12,'College Enrollment Projections'!$AI$2:$AI$62,0),MATCH('Campus Enrol Disaggregation'!AC$2,'College Enrollment Projections'!$AJ$1:$AP$1,0)),50) -> 0 | AD12: =SUM(P12:AC12) -> 108800
O13: 1998 | P13: =MROUND(P$3*INDEX('College Enrollment Projections'!$AJ$2:$AP$62,MATCH('Campus Enrol Disaggregation'!$O13,'College Enrollment Projections'!$AI$2:$AI$62,0),MATCH('Campus Enrol Disaggregation'!P$2,'College Enrollment Projections'!$AJ$1:$AP$1,0)),50) -> 32200 | Q13: =MROUND(Q$3*INDEX('College Enrollment Projections'!$AJ$2:$AP$62,MATCH('Campus Enrol Disaggregation'!$O13,'College Enrollment Projections'!$AI$2:$AI$62,0),MATCH('Campus Enrol Disaggregation'!Q$2,'College Enrollment Projections'!$AJ$1:$AP$1,0)),50) -> 0 | R13: =MROUND(R$3*INDEX('College Enrollment Projections'!$AJ$2:$AP$62,MATCH('Campus Enrol Disaggregation'!$O13,'College Enrollment Projections'!$AI$2:$AI$62,0),MATCH('Campus Enrol Disaggregation'!R$2,'College Enrollment Projections'!$AJ$1:$AP$1,0)),50) -> 10450 | S13: =MROUND(S$3*INDEX('College Enrollment Projections'!$AJ$2:$AP$62,MATCH('Campus Enrol Disaggregation'!$O13,'College Enrollment Projections'!$AI$2:$AI$62,0),MATCH('Campus Enrol Disaggregation'!S$2,'College Enrollment Projections'!$AJ$1:$AP$1,0)),50) -> 3650 | T13: =MROUND(T$3*INDEX('College Enrollment Projections'!$AJ$2:$AP$62,MATCH('Campus Enrol Disaggregation'!$O13,'College Enrollment Projections'!$AI$2:$AI$62,0),MATCH('Campus Enrol Disaggregation'!T$2,'College Enrollment Projections'!$AJ$1:$AP$1,0)),50) -> 900 | U13: =MROUND(U$3*INDEX('College Enrollment Projections'!$AJ$2:$AP$62,MATCH('Campus Enrol Disaggregation'!$O13,'College Enrollment Projections'!$AI$2:$AI$62,0),MATCH('Campus Enrol Disaggregation'!U$2,'College Enrollment Projections'!$AJ$1:$AP$1,0)),50) -> 3250 | V13: =MROUND(V$3*INDEX('College Enrollment Projections'!$AJ$2:$AP$62,MATCH('Campus Enrol Disaggregation'!$O13,'College Enrollment Projections'!$AI$2:$AI$62,0),MATCH('Campus Enrol Disaggregation'!V$2,'College Enrollment Projections'!$AJ$1:$AP$1,0)),50) -> 24350 | W13: =MROUND(INDEX('MAG College Enrollment Forecast'!$B$4:$H$64,MATCH($O13,'MAG College Enrollment Forecast'!$A$4:$A$64,0),MATCH(W$4,'MAG College Enrollment Forecast'!$B$1:$H$1,0)),50) -> 18150 | X13: =MROUND(INDEX('MAG College Enrollment Forecast'!$B$4:$H$64,MATCH($O13,'MAG College Enrollment Forecast'!$A$4:$A$64,0),MATCH(X$4,'MAG College Enrollment Forecast'!$B$1:$H$1,0)),50) -> 0 | Y13: =MROUND(INDEX('MAG College Enrollment Forecast'!$B$4:$H$64,MATCH($O13,'MAG College Enrollment Forecast'!$A$4:$A$64,0),MATCH(Y$4,'MAG College Enrollment Forecast'!$B$1:$H$1,0)),50) -> 0 | Z13: =MROUND(INDEX('MAG College Enrollment Forecast'!$B$4:$H$64,MATCH($O13,'MAG College Enrollment Forecast'!$A$4:$A$64,0),MATCH(Z$4,'MAG College Enrollment Forecast'!$B$1:$H$1,0)),50) -> 0 | AA13: =MROUND(AA$3*INDEX('College Enrollment Projections'!$AJ$2:$AP$62,MATCH('Campus Enrol Disaggregation'!$O13,'College Enrollment Projections'!$AI$2:$AI$62,0),MATCH('Campus Enrol Disaggregation'!AA$2,'College Enrollment Projections'!$AJ$1:$AP$1,0)),50) -> 10450 | AB13: =MROUND(AB$3*INDEX('College Enrollment Projections'!$AJ$2:$AP$62,MATCH('Campus Enrol Disaggregation'!$O13,'College Enrollment Projections'!$AI$2:$AI$62,0),MATCH('Campus Enrol Disaggregation'!AB$2,'College Enrollment Projections'!$AJ$1:$AP$1,0)),50) -> 2750 | AC13: =MROUND(AC$3*INDEX('College Enrollment Projections'!$AJ$2:$AP$62,MATCH('Campus Enrol Disaggregation'!$O13,'College Enrollment Projections'!$AI$2:$AI$62,0),MATCH('Campus Enrol Disaggregation'!AC$2,'College Enrollment Projections'!$AJ$1:$AP$1,0)),50) -> 0 | AD13: =SUM(P13:AC13) -> 106150
