Workbook
Name ArtExpFactors: 'Cap1hr1ln V8'!$B$43:$E$52
Name ArtExpFactors: 'Cap1hr1ln V8.3x'!$B$55:$E$64
Name ArtExpFactors: #REF!
Name ATypeCap: 'Cap1hr1ln V8'!$B$65:$G$66
Name ATypeCap: 'Cap1hr1ln V8.3x'!$B$77:$G$78
Name ATypeCap: #REF!
Name Export_SpdCap: Export!$A$3:$M$37
Name Export_VDF: Export!$P$3:$T$9
Name FwyCapFactors: 'Cap1hr1ln V8'!$B$73:$D$84
Name FwyCapFactors: 'Cap1hr1ln V8.3x'!$B$85:$D$97
Name FwyCapFactors: #REF!
Name FwyFleLookup: 'Cap1hr1ln V8'!$F$73:$G$80
Name FwyFleLookup: 'Cap1hr1ln V8.3x'!$F$85:$G$92
Name FwyFleLookup: #REF!

Sheet Export
A1: Speed & Capacity Lookup Table | P1: Volume Delay Function Parameters
A3: ;FT | B3: SPDAT1 | C3: SPDAT2 | D3: SPDAT3 | E3: SPDAT4 | F3: SPDAT5 | G3: CAPLN1 | H3: CAPLN2 | I3: CAPLN3 | J3: CAPLN4 | K3: CAPLN5 | L3: CAPLN6 | M3: CAPLN7 | P3: ;LINKCLASS | Q3: COEF | R3: EXP | S3: MAXVC | T3: NOTE
A4: 1 | B4: =ROUND('SFF 8.3'!C5, 0) -> 30 | C4: =ROUND('SFF 8.3'!D5, 0) -> 24 | D4: =ROUND('SFF 8.3'!E5, 0) -> 20 | E4: =ROUND('SFF 8.3'!F5, 0) -> 17 | F4: =ROUND('SFF 8.3'!G5, 0) -> 14 | G4: ='Cap1hr1ln V8.32b'!C4 -> 10000 | H4: ='Cap1hr1ln V8.32b'!D4 -> 10000 | I4: ='Cap1hr1ln V8.32b'!E4 -> 10000 | J4: ='Cap1hr1ln V8.32b'!F4 -> 10000 | K4: ='Cap1hr1ln V8.32b'!G4 -> 10000 | L4: ='Cap1hr1ln V8.32b'!H4 -> 10000 | M4: ='Cap1hr1ln V8.32b'!I4 -> 10000 | P4: 1 | Q4: ='VDF V8.3x'!B5 -> 0.7 | R4: ='VDF V8.3x'!B6 -> 8 | S4: ='VDF V8.3x'!B7 -> 1.44 | T4: Freeway
A5: 2 | B5: =ROUND('SFF 8.3'!C6, 0) -> 58 | C5: =ROUND('SFF 8.3'!D6, 0) -> 48 | D5: =ROUND('SFF 8.3'!E6, 0) -> 38 | E5: =ROUND('SFF 8.3'!F6, 0) -> 32 | F5: =ROUND('SFF 8.3'!G6, 0) -> 24 | G5: ='Cap1hr1ln V8.32b'!C5 -> 968 | H5: ='Cap1hr1ln V8.32b'!D5 -> 929 | I5: ='Cap1hr1ln V8.32b'!E5 -> 890 | J5: ='Cap1hr1ln V8.32b'!F5 -> 869 | K5: ='Cap1hr1ln V8.32b'!G5 -> 849 | L5: ='Cap1hr1ln V8.32b'!H5 -> 830 | M5: ='Cap1hr1ln V8.32b'!I5 -> 810 | P5: 2 | Q5: ='VDF V8.3x'!C5 -> 0.7 | R5: ='VDF V8.3x'!C6 -> 3 | S5: ='VDF V8.3x'!C7 -> 1.65 | T5: Ramp
A6: 3 | B6: =ROUND('SFF 8.3'!C7, 0) -> 55 | C6: =ROUND('SFF 8.3'!D7, 0) -> 43 | D6: =ROUND('SFF 8.3'!E7, 0) -> 35 | E6: =ROUND('SFF 8.3'!F7, 0) -> 30 | F6: =ROUND('SFF 8.3'!G7, 0) -> 21 | G6: ='Cap1hr1ln V8.32b'!C6 -> 894 | H6: ='Cap1hr1ln V8.32b'!D6 -> 858 | I6: ='Cap1hr1ln V8.32b'!E6 -> 822 | J6: ='Cap1hr1ln V8.32b'!F6 -> 803 | K6: ='Cap1hr1ln V8.32b'!G6 -> 784 | L6: ='Cap1hr1ln V8.32b'!H6 -> 766 | M6: ='Cap1hr1ln V8.32b'!I6 -> 748 | P6: 3 | Q6: ='VDF V8.3x'!D5 -> 0.6 | R6: ='VDF V8.3x'!D6 -> 6 | S6: ='VDF V8.3x'!D7 -> 1.55 | T6: Expressway
A7: 4 | B7: =ROUND('SFF 8.3'!C8, 0) -> 48 | C7: =ROUND('SFF 8.3'!D8, 0) -> 38 | D7: =ROUND('SFF 8.3'!E8, 0) -> 34 | E7: =ROUND('SFF 8.3'!F8, 0) -> 28 | F7: =ROUND('SFF 8.3'!G8, 0) -> 19 | G7: ='Cap1hr1ln V8.32b'!C7 -> 733 | H7: ='Cap1hr1ln V8.32b'!D7 -> 703 | I7: ='Cap1hr1ln V8.32b'!E7 -> 674 | J7: ='Cap1hr1ln V8.32b'!F7 -> 658 | K7: ='Cap1hr1ln V8.32b'!G7 -> 643 | L7: ='Cap1hr1ln V8.32b'!H7 -> 628 | M7: ='Cap1hr1ln V8.32b'!I7 -> 613 | P7: 4 | Q7: ='VDF V8.3x'!E5 -> 0.6 | R7: ='VDF V8.3x'!E6 -> 4 | S7: ='VDF V8.3x'!E7 -> 1.8 | T7: Arterial
A8: 5 | B8: =ROUND('SFF 8.3'!C9, 0) -> 42 | C8: =ROUND('SFF 8.3'!D9, 0) -> 32 | D8: =ROUND('SFF 8.3'!E9, 0) -> 26 | E8: =ROUND('SFF 8.3'!F9, 0) -> 23 | F8: =ROUND('SFF 8.3'!G9, 0) -> 15 | G8: ='Cap1hr1ln V8.32b'!C8 -> 515 | H8: ='Cap1hr1ln V8.32b'!D8 -> 494 | I8: ='Cap1hr1ln V8.32b'!E8 -> 473 | J8: ='Cap1hr1ln V8.32b'!F8 -> 462 | K8: ='Cap1hr1ln V8.32b'!G8 -> 451 | L8: ='Cap1hr1ln V8.32b'!H8 -> 441 | M8: ='Cap1hr1ln V8.32b'!I8 -> 431 | P8: 5 | Q8: ='VDF V8.3x'!F5 -> 0.6 | R8: ='VDF V8.3x'!F6 -> 3 | S8: ='VDF V8.3x'!F7 -> 1.85 | T8: Collector & Local
A9: 6 | B9: =ROUND('SFF 8.3'!C10, 0) -> 30 | C9: =ROUND('SFF 8.3'!D10, 0) -> 24 | D9: =ROUND('SFF 8.3'!E10, 0) -> 20 | E9: =ROUND('SFF 8.3'!F10, 0) -> 17 | F9: =ROUND('SFF 8.3'!G10, 0) -> 14 | G9: ='Cap1hr1ln V8.32b'!C9 -> 412 | H9: ='Cap1hr1ln V8.32b'!D9 -> 395 | I9: ='Cap1hr1ln V8.32b'!E9 -> 378 | J9: ='Cap1hr1ln V8.32b'!F9 -> 370 | K9: ='Cap1hr1ln V8.32b'!G9 -> 361 | L9: ='Cap1hr1ln V8.32b'!H9 -> 353 | M9: ='Cap1hr1ln V8.32b'!I9 -> 344 | P9: 6 | Q9: ='VDF V8.3x'!G5 -> 0.7 | R9: ='VDF V8.3x'!G6 -> 8 | S9: ='VDF V8.3x'!G7 -> 1.44 | T9: Managed Freeway
A10: 7 | B10: =ROUND('SFF 8.3'!C11, 0) -> 15 | C10: =ROUND('SFF 8.3'!D11, 0) -> 15 | D10: =ROUND('SFF 8.3'!E11, 0) -> 15 | E10: =ROUND('SFF 8.3'!F11, 0) -> 15 | F10: =ROUND('SFF 8.3'!G11, 0) -> 15 | G10: ='Cap1hr1ln V8.32b'!C10 -> 300 | H10: ='Cap1hr1ln V8.32b'!D10 -> 300 | I10: ='Cap1hr1ln V8.32b'!E10 -> 300 | J10: ='Cap1hr1ln V8.32b'!F10 -> 300 | K10: ='Cap1hr1ln V8.32b'!G10 -> 300 | L10: ='Cap1hr1ln V8.32b'!H10 -> 300 | M10: ='Cap1hr1ln V8.32b'!I10 -> 300
A11: 12 | B11: =ROUND('SFF 8.3'!C15, 0) -> 56 | C11: =B11 -> 56 | D11: =C11 -> 56 | E11: =D11 -> 56 | F11: =E11 -> 56 | G11: ='Cap1hr1ln V8.32b'!C11 -> 1102 | H11: ='Cap1hr1ln V8.32b'!D11 -> 1058 | I11: ='Cap1hr1ln V8.32b'!E11 -> 1025 | J11: ='Cap1hr1ln V8.32b'!F11 -> 1003 | K11: ='Cap1hr1ln V8.32b'!G11 -> 981 | L11: ='Cap1hr1ln V8.32b'!H11 -> 960 | M11: ='Cap1hr1ln V8.32b'!I11 -> 940
A12: 13 | B12: =ROUND('SFF 8.3'!C16, 0) -> 53 | C12: =B12 -> 53 | D12: =C12 -> 53 | E12: =D12 -> 53 | F12: =E12 -> 53 | G12: ='Cap1hr1ln V8.32b'!C12 -> 1064 | H12: ='Cap1hr1ln V8.32b'!D12 -> 1021 | I12: ='Cap1hr1ln V8.32b'!E12 -> 990 | J12: ='Cap1hr1ln V8.32b'!F12 -> 968 | K12: ='Cap1hr1ln V8.32b'!G12 -> 947 | L12: ='Cap1hr1ln V8.32b'!H12 -> 927 | M12: ='Cap1hr1ln V8.32b'!I12 -> 907
A13: 14 | B13: =ROUND('SFF 8.3'!C17, 0) -> 48 | C13: =B13 -> 48 | D13: =C13 -> 48 | E13: =D13 -> 48 | F13: =E13 -> 48 | G13: ='Cap1hr1ln V8.32b'!C13 -> 1026 | H13: ='Cap1hr1ln V8.32b'!D13 -> 985 | I13: ='Cap1hr1ln V8.32b'!E13 -> 954 | J13: ='Cap1hr1ln V8.32b'!F13 -> 934 | K13: ='Cap1hr1ln V8.32b'!G13 -> 914 | L13: ='Cap1hr1ln V8.32b'!H13 -> 894 | M13: ='Cap1hr1ln V8.32b'!I13 -> 875
A14: 15 | B14: =ROUND('SFF 8.3'!C18, 0) -> 43 | C14: =B14 -> 43 | D14: =C14 -> 43 | E14: =D14 -> 43 | F14: =E14 -> 43 | G14: ='Cap1hr1ln V8.32b'!C14 -> 988 | H14: ='Cap1hr1ln V8.32b'!D14 -> 948 | I14: ='Cap1hr1ln V8.32b'!E14 -> 919 | J14: ='Cap1hr1ln V8.32b'!F14 -> 899 | K14: ='Cap1hr1ln V8.32b'!G14 -> 880 | L14: ='Cap1hr1ln V8.32b'!H14 -> 861 | M14: ='Cap1hr1ln V8.32b'!I14 -> 842
A15: 20 | B15: =ROUND('SFF 8.3'!C20, 0) -> 35 | C15: =B15 -> 35 | D15: =C15 -> 35 | E15: =D15 -> 35 | F15: =E15 -> 35 | G15: ='Cap1hr1ln V8.32b'!C15 -> 1325 | H15: ='Cap1hr1ln V8.32b'!D15 -> 1060 | I15: ='Cap1hr1ln V8.32b'!E15 -> 848 | J15: ='Cap1hr1ln V8.32b'!F15 -> 848 | K15: ='Cap1hr1ln V8.32b'!G15 -> 848 | L15: ='Cap1hr1ln V8.32b'!H15 -> 848 | M15: ='Cap1hr1ln V8.32b'!I15 -> 848
A16: 21 | B16: =ROUND('SFF 8.3'!C21, 0) -> 55 | C16: =B16 -> 55 | D16: =C16 -> 55 | E16: =D16 -> 55 | F16: =E16 -> 55 | G16: ='Cap1hr1ln V8.32b'!C16 -> 1473 | H16: ='Cap1hr1ln V8.32b'!D16 -> 1473 | I16: ='Cap1hr1ln V8.32b'!E16 -> 1473 | J16: ='Cap1hr1ln V8.32b'!F16 -> 1443 | K16: ='Cap1hr1ln V8.32b'!G16 -> 1399 | L16: ='Cap1hr1ln V8.32b'!H16 -> 1340 | M16: ='Cap1hr1ln V8.32b'!I16 -> 1296
A17: 22 | B17: =ROUND('SFF 8.3'!C22, 0) -> 65 | C17: =B17 -> 65 | D17: =C17 -> 65 | E17: =D17 -> 65 | F17: =E17 -> 65 | G17: ='Cap1hr1ln V8.32b'!C17 -> 1922 | H17: ='Cap1hr1ln V8.32b'!D17 -> 1922 | I17: ='Cap1hr1ln V8.32b'!E17 -> 1922 | J17: ='Cap1hr1ln V8.32b'!F17 -> 1884 | K17: ='Cap1hr1ln V8.32b'!G17 -> 1826 | L17: ='Cap1hr1ln V8.32b'!H17 -> 1749 | M17: ='Cap1hr1ln V8.32b'!I17 -> 1691
A18: 23 | B18: =ROUND('SFF 8.3'!C23, 0) -> 75 | C18: =B18 -> 75 | D18: =C18 -> 75 | E18: =D18 -> 75 | F18: =E18 -> 75 | G18: ='Cap1hr1ln V8.32b'!C18 -> 1964 | H18: ='Cap1hr1ln V8.32b'!D18 -> 1964 | I18: ='Cap1hr1ln V8.32b'!E18 -> 1964 | J18: ='Cap1hr1ln V8.32b'!F18 -> 1924 | K18: ='Cap1hr1ln V8.32b'!G18 -> 1866 | L18: ='Cap1hr1ln V8.32b'!H18 -> 1787 | M18: ='Cap1hr1ln V8.32b'!I18 -> 1728
A19: 24 | B19: =ROUND('SFF 8.3'!C24, 0) -> 73 | C19: =B19 -> 73 | D19: =C19 -> 73 | E19: =D19 -> 73 | F19: =E19 -> 73 | G19: ='Cap1hr1ln V8.32b'!C19 -> 2664 | H19: ='Cap1hr1ln V8.32b'!D19 -> 2314 | I19: ='Cap1hr1ln V8.32b'!E19 -> 2197 | J19: ='Cap1hr1ln V8.32b'!F19 -> 2099 | K19: ='Cap1hr1ln V8.32b'!G19 -> 2006 | L19: ='Cap1hr1ln V8.32b'!H19 -> 1904 | M19: ='Cap1hr1ln V8.32b'!I19 -> 1828
A20: 25 | B20: =ROUND('SFF 8.3'!C25, 0) -> 78 | C20: =B20 -> 78 | D20: =C20 -> 78 | E20: =D20 -> 78 | F20: =E20 -> 78 | G20: ='Cap1hr1ln V8.32b'!C20 -> 2006 | H20: ='Cap1hr1ln V8.32b'!D20 -> 2006 | I20: ='Cap1hr1ln V8.32b'!E20 -> 2006 | J20: ='Cap1hr1ln V8.32b'!F20 -> 1965 | K20: ='Cap1hr1ln V8.32b'!G20 -> 1905 | L20: ='Cap1hr1ln V8.32b'!H20 -> 1825 | M20: ='Cap1hr1ln V8.32b'!I20 -> 1765
A21: 26 | B21: =ROUND('SFF 8.3'!C26, 0) -> 75 | C21: =B21 -> 75 | D21: =C21 -> 75 | E21: =D21 -> 75 | F21: =E21 -> 75 | G21: ='Cap1hr1ln V8.32b'!C21 -> 2706 | H21: ='Cap1hr1ln V8.32b'!D21 -> 2356 | I21: ='Cap1hr1ln V8.32b'!E21 -> 2239 | J21: ='Cap1hr1ln V8.32b'!F21 -> 2140 | K21: ='Cap1hr1ln V8.32b'!G21 -> 2045 | L21: ='Cap1hr1ln V8.32b'!H21 -> 1942 | M21: ='Cap1hr1ln V8.32b'!I21 -> 1865
A22: 27 | B22: =ROUND('SFF 8.3'!C27, 0) -> 77 | C22: =B22 -> 77 | D22: =C22 -> 77 | E22: =D22 -> 77 | F22: =E22 -> 77 | G22: ='Cap1hr1ln V8.32b'!C22 -> 2706 | H22: ='Cap1hr1ln V8.32b'!D22 -> 2356 | I22: ='Cap1hr1ln V8.32b'!E22 -> 2239 | J22: ='Cap1hr1ln V8.32b'!F22 -> 2140 | K22: ='Cap1hr1ln V8.32b'!G22 -> 2045 | L22: ='Cap1hr1ln V8.32b'!H22 -> 1942 | M22: ='Cap1hr1ln V8.32b'!I22 -> 1865
A23: 28 | B23: =ROUND('SFF 8.3'!C28, 0) -> 23 | C23: =B23 -> 23 | D23: =C23 -> 23 | E23: =D23 -> 23 | F23: =E23 -> 23 | G23: ='Cap1hr1ln V8.32b'!C23 -> 1200 | H23: ='Cap1hr1ln V8.32b'!D23 -> 900 | I23: ='Cap1hr1ln V8.32b'!E23 -> 600 | J23: ='Cap1hr1ln V8.32b'!F23 -> 600 | K23: ='Cap1hr1ln V8.32b'!G23 -> 600 | L23: ='Cap1hr1ln V8.32b'!H23 -> 600 | M23: ='Cap1hr1ln V8.32b'!I23 -> 600
A24: 29 | B24: =ROUND('SFF 8.3'!C29, 0) -> 26 | C24: =B24 -> 26 | D24: =C24 -> 26 | E24: =D24 -> 26 | F24: =E24 -> 26 | G24: ='Cap1hr1ln V8.32b'!C24 -> 894 | H24: ='Cap1hr1ln V8.32b'!D24 -> 858 | I24: ='Cap1hr1ln V8.32b'!E24 -> 822 | J24: ='Cap1hr1ln V8.32b'!F24 -> 803 | K24: ='Cap1hr1ln V8.32b'!G24 -> 784 | L24: ='Cap1hr1ln V8.32b'!H24 -> 766 | M24: ='Cap1hr1ln V8.32b'!I24 -> 748
A25: 30 | B25: =ROUND('SFF 8.3'!C31, 0) -> 35 | C25: =B25 -> 35 | D25: =C25 -> 35 | E25: =D25 -> 35 | F25: =E25 -> 35 | G25: ='Cap1hr1ln V8.32b'!C25 -> 1325 | H25: ='Cap1hr1ln V8.32b'!D25 -> 1060 | I25: ='Cap1hr1ln V8.32b'!E25 -> 848 | J25: ='Cap1hr1ln V8.32b'!F25 -> 848 | K25: ='Cap1hr1ln V8.32b'!G25 -> 848 | L25: ='Cap1hr1ln V8.32b'!H25 -> 848 | M25: ='Cap1hr1ln V8.32b'!I25 -> 848
A26: 31 | B26: =ROUND('SFF 8.3'!C32, 0) -> 55 | C26: =B26 -> 55 | D26: =C26 -> 55 | E26: =D26 -> 55 | F26: =E26 -> 55 | G26: ='Cap1hr1ln V8.32b'!C26 -> 1473 | H26: ='Cap1hr1ln V8.32b'!D26 -> 1473 | I26: ='Cap1hr1ln V8.32b'!E26 -> 1473 | J26: ='Cap1hr1ln V8.32b'!F26 -> 1443 | K26: ='Cap1hr1ln V8.32b'!G26 -> 1399 | L26: ='Cap1hr1ln V8.32b'!H26 -> 1340 | M26: ='Cap1hr1ln V8.32b'!I26 -> 1296
A27: 32 | B27: =ROUND('SFF 8.3'!C33, 0) -> 65 | C27: =B27 -> 65 | D27: =C27 -> 65 | E27: =D27 -> 65 | F27: =E27 -> 65 | G27: ='Cap1hr1ln V8.32b'!C27 -> 1693 | H27: ='Cap1hr1ln V8.32b'!D27 -> 1693 | I27: ='Cap1hr1ln V8.32b'!E27 -> 1693 | J27: ='Cap1hr1ln V8.32b'!F27 -> 1660 | K27: ='Cap1hr1ln V8.32b'!G27 -> 1609 | L27: ='Cap1hr1ln V8.32b'!H27 -> 1541 | M27: ='Cap1hr1ln V8.32b'!I27 -> 1490
A28: 33 | B28: =ROUND('SFF 8.3'!C34, 0) -> 75 | C28: =B28 -> 75 | D28: =C28 -> 75 | E28: =D28 -> 75 | F28: =E28 -> 75 | G28: ='Cap1hr1ln V8.32b'!C28 -> 1730 | H28: ='Cap1hr1ln V8.32b'!D28 -> 1730 | I28: ='Cap1hr1ln V8.32b'!E28 -> 1730 | J28: ='Cap1hr1ln V8.32b'!F28 -> 1696 | K28: ='Cap1hr1ln V8.32b'!G28 -> 1644 | L28: ='Cap1hr1ln V8.32b'!H28 -> 1574 | M28: ='Cap1hr1ln V8.32b'!I28 -> 1523
A29: 34 | B29: =ROUND('SFF 8.3'!C35, 0) -> 73 | C29: =B29 -> 73 | D29: =C29 -> 73 | E29: =D29 -> 73 | F29: =E29 -> 73 | G29: ='Cap1hr1ln V8.32b'!C29 -> 2430 | H29: ='Cap1hr1ln V8.32b'!D29 -> 2080 | I29: ='Cap1hr1ln V8.32b'!E29 -> 1964 | J29: ='Cap1hr1ln V8.32b'!F29 -> 1871 | K29: ='Cap1hr1ln V8.32b'!G29 -> 1784 | L29: ='Cap1hr1ln V8.32b'!H29 -> 1691 | M29: ='Cap1hr1ln V8.32b'!I29 -> 1623
A30: 35 | B30: =ROUND('SFF 8.3'!C36, 0) -> 80 | C30: =B30 -> 80 | D30: =C30 -> 80 | E30: =D30 -> 80 | F30: =E30 -> 80 | G30: ='Cap1hr1ln V8.32b'!C30 -> 1767 | H30: ='Cap1hr1ln V8.32b'!D30 -> 1767 | I30: ='Cap1hr1ln V8.32b'!E30 -> 1767 | J30: ='Cap1hr1ln V8.32b'!F30 -> 1732 | K30: ='Cap1hr1ln V8.32b'!G30 -> 1679 | L30: ='Cap1hr1ln V8.32b'!H30 -> 1608 | M30: ='Cap1hr1ln V8.32b'!I30 -> 1555
A31: 36 | B31: =ROUND('SFF 8.3'!C37, 0) -> 77 | C31: =B31 -> 77 | D31: =C31 -> 77 | E31: =D31 -> 77 | F31: =E31 -> 77 | G31: ='Cap1hr1ln V8.32b'!C31 -> 2467 | H31: ='Cap1hr1ln V8.32b'!D31 -> 2117 | I31: ='Cap1hr1ln V8.32b'!E31 -> 2000 | J31: ='Cap1hr1ln V8.32b'!F31 -> 1907 | K31: ='Cap1hr1ln V8.32b'!G31 -> 1819 | L31: ='Cap1hr1ln V8.32b'!H31 -> 1725 | M31: ='Cap1hr1ln V8.32b'!I31 -> 1655
A32: 37 | B32: =ROUND('SFF 8.3'!C38, 0) -> 77 | C32: =B32 -> 77 | D32: =C32 -> 77 | E32: =D32 -> 77 | F32: =E32 -> 77 | G32: ='Cap1hr1ln V8.32b'!C32 -> 1767 | H32: ='Cap1hr1ln V8.32b'!D32 -> 1767 | I32: ='Cap1hr1ln V8.32b'!E32 -> 1767 | J32: ='Cap1hr1ln V8.32b'!F32 -> 1732 | K32: ='Cap1hr1ln V8.32b'!G32 -> 1679 | L32: ='Cap1hr1ln V8.32b'!H32 -> 1608 | M32: ='Cap1hr1ln V8.32b'!I32 -> 1555
A33: 38 | B33: =ROUND('SFF 8.3'!C39, 0) -> 77 | C33: =B33 -> 77 | D33: =C33 -> 77 | E33: =D33 -> 77 | F33: =E33 -> 77 | G33: ='Cap1hr1ln V8.32b'!C33 -> 1767 | H33: ='Cap1hr1ln V8.32b'!D33 -> 1767 | I33: ='Cap1hr1ln V8.32b'!E33 -> 1767 | J33: ='Cap1hr1ln V8.32b'!F33 -> 1732 | K33: ='Cap1hr1ln V8.32b'!G33 -> 1679 | L33: ='Cap1hr1ln V8.32b'!H33 -> 1608 | M33: ='Cap1hr1ln V8.32b'!I33 -> 1555
A34: 39 | B34: =ROUND('SFF 8.3'!C40, 0) -> 77 | C34: =B34 -> 77 | D34: =C34 -> 77 | E34: =D34 -> 77 | F34: =E34 -> 77 | G34: ='Cap1hr1ln V8.32b'!C34 -> 1767 | H34: ='Cap1hr1ln V8.32b'!D34 -> 1767 | I34: ='Cap1hr1ln V8.32b'!E34 -> 1767 | J34: ='Cap1hr1ln V8.32b'!F34 -> 1732 | K34: ='Cap1hr1ln V8.32b'!G34 -> 1679 | L34: ='Cap1hr1ln V8.32b'!H34 -> 1608 | M34: ='Cap1hr1ln V8.32b'!I34 -> 1555
A35: 40 | B35: =ROUND('SFF 8.3'!C41, 0) -> 84 | C35: =B35 -> 84 | D35: =C35 -> 84 | E35: =D35 -> 84 | F35: =E35 -> 84 | G35: ='Cap1hr1ln V8.32b'!C35 -> 2685 | H35: ='Cap1hr1ln V8.32b'!D35 -> 2335 | I35: ='Cap1hr1ln V8.32b'!E35 -> 2218 | J35: ='Cap1hr1ln V8.32b'!F35 -> 2120 | K35: ='Cap1hr1ln V8.32b'!G35 -> 2025 | L35: ='Cap1hr1ln V8.32b'!H35 -> 1923 | M35: ='Cap1hr1ln V8.32b'!I35 -> 1846
A36: 41 | B36: =ROUND('SFF 8.3'!C42, 0) -> 23 | C36: =B36 -> 23 | D36: =C36 -> 23 | E36: =D36 -> 23 | F36: =E36 -> 23 | G36: ='Cap1hr1ln V8.32b'!C36 -> 1200 | H36: ='Cap1hr1ln V8.32b'!D36 -> 900 | I36: ='Cap1hr1ln V8.32b'!E36 -> 600 | J36: ='Cap1hr1ln V8.32b'!F36 -> 600 | K36: ='Cap1hr1ln V8.32b'!G36 -> 600 | L36: ='Cap1hr1ln V8.32b'!H36 -> 600 | M36: ='Cap1hr1ln V8.32b'!I36 -> 600
A37: 42 | B37: =ROUND('SFF 8.3'!C43, 0) -> 26 | C37: =B37 -> 26 | D37: =C37 -> 26 | E37: =D37 -> 26 | F37: =E37 -> 26 | G37: ='Cap1hr1ln V8.32b'!C37 -> 894 | H37: ='Cap1hr1ln V8.32b'!D37 -> 858 | I37: ='Cap1hr1ln V8.32b'!E37 -> 822 | J37: ='Cap1hr1ln V8.32b'!F37 -> 803 | K37: ='Cap1hr1ln V8.32b'!G37 -> 784 | L37: ='Cap1hr1ln V8.32b'!H37 -> 766 | M37: ='Cap1hr1ln V8.32b'!I37 -> 748

Sheet SFF 8.3
A1: Free Flow Speed v8.3
C2: Speed by Area Type
A3: New | C3: 1 | D3: 2 | E3: 3 | F3: 4 | G3: 5
A4: FT | B4: Functional Type | C4: Rural | D4: Transition | E4: Suburban | F4: Urban | G4: CBD-Like
A5: 1 | B5: Centroid Connector / Local | C5: =1 / ((1/C53) + (C65*C$77/3600)) -> 30 | D5: =1 / ((1/D53) + (D65*D$77/3600)) -> 24 | E5: =1 / ((1/E53) + (E65*E$77/3600)) -> 20.16 | F5: =1 / ((1/F53) + (F65*F$77/3600)) -> 17.0347 | G5: =1 / ((1/G53) + (G65*G$77/3600)) -> 13.535792
A6: 2 | B6: Principal Arterial | C6: =1 / ((1/C54) + (C66*C$77/3600)) -> 58 | D6: =1 / ((1/D54) + (D66*D$77/3600)) -> 47.710843 | E6: =1 / ((1/E54) + (E66*E$77/3600)) -> 38.297872 | F6: =1 / ((1/F54) + (F66*F$77/3600)) -> 32.22394 | G6: =1 / ((1/G54) + (G66*G$77/3600)) -> 24.347826
A7: 3 | B7: Minor Arterial | C7: =1 / ((1/C55) + (C67*C$77/3600)) -> 55 | D7: =1 / ((1/D55) + (D67*D$77/3600)) -> 42.739726 | E7: =1 / ((1/E55) + (E67*E$77/3600)) -> 34.750462 | F7: =1 / ((1/F55) + (F67*F$77/3600)) -> 30.12094 | G7: =1 / ((1/G55) + (G67*G$77/3600)) -> 21.290323
A8: 4 | B8: Major Collector | C8: =1 / ((1/C56) + (C68*C$77/3600)) -> 48 | D8: =1 / ((1/D56) + (D68*D$77/3600)) -> 38.463287 | E8: =1 / ((1/E56) + (E68*E$77/3600)) -> 33.563032 | F8: =1 / ((1/F56) + (F68*F$77/3600)) -> 27.906977 | G8: =1 / ((1/G56) + (G68*G$77/3600)) -> 18.666667
A9: 5 | B9: Minor Collector | C9: =C8-6 -> 42 | D9: =D8-6 -> 32.463287 | E9: =E8-8 -> 25.563032 | F9: =F8-5 -> 22.906977 | G9: =G8-4 -> 14.666667
A10: 6 | B10: Local | C10: =C5 -> 30 | D10: =D5 -> 24 | E10: =E5 -> 20.16 | F10: =F5 -> 17.0347 | G10: =G5 -> 13.535792
A11: 7 | B11: Unpaved | C11: 15 | D11: =C11 -> 15 | E11: =D11 -> 15 | F11: =E11 -> 15 | G11: =F11 -> 15
A13: New | C13: New | D13: Old
A14: FT | B14: Functional Type | C14: Speed | D14: Speed | E14: (These do not vary by Area Type)
A15: 12 | B15: Expressway, posted 60-70 mph | C15: =1 / ((1/C58) + (C70*C79/3600)) -> 56.124722
A16: 13 | B16: Expressway, posted 55-65 mph | C16: =1 / ((1/C59) + (C71*C80/3600)) -> 53.333333
A17: 14 | B17: Expressway, posted 50-60 mph | C17: =1 / ((1/C60) + (C72*C81/3600)) -> 47.710843
A18: 15 | B18: Expressway, posted 45-55 mph | C18: =1 / ((1/C61) + (C73*C82/3600)) -> 42.60355
A20: 20 | B20: =#REF! -> #REF! | C20: =C31 -> 35
A21: 21 | B21: =#REF! -> #REF! | C21: =C32 -> 55
A22: 22 | B22: =#REF! -> #REF! | C22: =C33 -> 65
A23: 23 | B23: =#REF! -> #REF! | C23: =C34 -> 75
A24: 24 | B24: =#REF! -> #REF! | C24: =C35 -> 73
A25: 25 | B25: =#REF! -> #REF! | C25: 78
A26: 26 | B26: =#REF! -> #REF! | C26: 75
A27: 27 | B27: =#REF! -> #REF! | C27: =C38 -> 77
A28: 28 | B28: =#REF! -> #REF! | C28: =C42 -> 23
A29: 29 | B29: =#REF! -> #REF! | C29: =C43 -> 26
A31: 30 | B31: =#REF! -> #REF! | C31: 35
A32: 31 | B32: =#REF! -> #REF! | C32: 55
A33: 32 | B33: =#REF! -> #REF! | C33: 65
A34: 33 | B34: =#REF! -> #REF! | C34: 75
A35: 34 | B35: =#REF! -> #REF! | C35: 73
A36: 35 | B36: =#REF! -> #REF! | C36: 80
A37: 36 | B37: =#REF! -> #REF! | C37: 77
A38: 37 | B38: =#REF! -> #REF! | C38: 77
A39: 38 | B39: =#REF! -> #REF! | C39: 77
A40: 39 | B40: =#REF! -> #REF! | C40: 77
A41: 40 | B41: =#REF! -> #REF! | C41: 84
A42: 41 | B42: =#REF! -> #REF! | C42: 23
A43: 42 | B43: =#REF! -> #REF! | C43: 26
...

Sheet Cap1hr1ln V8.32b
B1: Capacity Lookup Table | K1: Arterial / Expressway Capacity Calculation Parameters | U1: Freeway Capacity Calculation Parameters | AE1: Update MM Capacity Based on VicRoads Capacity
B3: FT | C3: CAPLN1 | D3: CAPLN2 | E3: CAPLN3 | F3: CAPLN4 | G3: CAPLN5 | H3: CAPLN6 | I3: CAPLN7 | K3: Cap1hr1ln = Saturation Flow Rate * Fgrn * Fbb * Flu * Fatype | U3: Cap1hr = (Saturation Flow Rate * PHF * Flu * LANES) + AuxLaneCapacity
B4: 1 | C4: =ROUND(VLOOKUP($B4, $K$11:$S$23, COLUMNS($K$11:M$11), FALSE), 0) -> 10000 | D4: =ROUND(VLOOKUP($B4, $K$11:$S$23, COLUMNS($K$11:N$11), FALSE), 0) -> 10000 | E4: =ROUND(VLOOKUP($B4, $K$11:$S$23, COLUMNS($K$11:O$11), FALSE), 0) -> 10000 | F4: =ROUND(VLOOKUP($B4, $K$11:$S$23, COLUMNS($K$11:P$11), FALSE), 0) -> 10000 | G4: =ROUND(VLOOKUP($B4, $K$11:$S$23, COLUMNS($K$11:Q$11), FALSE), 0) -> 10000 | H4: =ROUND(VLOOKUP($B4, $K$11:$S$23, COLUMNS($K$11:R$11), FALSE), 0) -> 10000 | I4: =ROUND(VLOOKUP($B4, $K$11:$S$23, COLUMNS($K$11:S$11), FALSE), 0) -> 10000 | U4: Cap1hr1ln = Cap1hr / LANES ;distributes AuxVolAtCapacity across the GP lanes | AE4: Notes
B5: 2 | C5: =ROUND(VLOOKUP($B5, $K$11:$S$23, COLUMNS($K$11:M$11), FALSE), 0) -> 968 | D5: =ROUND(VLOOKUP($B5, $K$11:$S$23, COLUMNS($K$11:N$11), FALSE), 0) -> 929 | E5: =ROUND(VLOOKUP($B5, $K$11:$S$23, COLUMNS($K$11:O$11), FALSE), 0) -> 890 | F5: =ROUND(VLOOKUP($B5, $K$11:$S$23, COLUMNS($K$11:P$11), FALSE), 0) -> 869 | G5: =ROUND(VLOOKUP($B5, $K$11:$S$23, COLUMNS($K$11:Q$11), FALSE), 0) -> 849 | H5: =ROUND(VLOOKUP($B5, $K$11:$S$23, COLUMNS($K$11:R$11), FALSE), 0) -> 830 | I5: =ROUND(VLOOKUP($B5, $K$11:$S$23, COLUMNS($K$11:S$11), FALSE), 0) -> 810 | K5: Note: Travel model adjusts capacities for truck volumes , thus no heavy vehicle adjustment (Fhv) are applied | AE5: Current TDM assumes a bit too much capacity increase due to MM compared to VicRoads emperical data
B6: 3 | C6: =ROUND(VLOOKUP($B6, $K$11:$S$23, COLUMNS($K$11:M$11), FALSE), 0) -> 894 | D6: =ROUND(VLOOKUP($B6, $K$11:$S$23, COLUMNS($K$11:N$11), FALSE), 0) -> 858 | E6: =ROUND(VLOOKUP($B6, $K$11:$S$23, COLUMNS($K$11:O$11), FALSE), 0) -> 822 | F6: =ROUND(VLOOKUP($B6, $K$11:$S$23, COLUMNS($K$11:P$11), FALSE), 0) -> 803 | G6: =ROUND(VLOOKUP($B6, $K$11:$S$23, COLUMNS($K$11:Q$11), FALSE), 0) -> 784 | H6: =ROUND(VLOOKUP($B6, $K$11:$S$23, COLUMNS($K$11:R$11), FALSE), 0) -> 766 | I6: =ROUND(VLOOKUP($B6, $K$11:$S$23, COLUMNS($K$11:S$11), FALSE), 0) -> 748 | K6: Note: Arterial & collector capacities are adjusted up or down by 5% as area type moves away from suburban | U6: Note: Travel model adjusts capacities for truck volumes , thus no heavy vehicle adjustment (Fhv) are applied | AE6: Change TDM MM Capacity to reflect 18% improvement instead of 21%
B7: 4 | C7: =ROUND(VLOOKUP($B7, $K$11:$S$23, COLUMNS($K$11:M$11), FALSE), 0) -> 733 | D7: =ROUND(VLOOKUP($B7, $K$11:$S$23, COLUMNS($K$11:N$11), FALSE), 0) -> 703 | E7: =ROUND(VLOOKUP($B7, $K$11:$S$23, COLUMNS($K$11:O$11), FALSE), 0) -> 674 | F7: =ROUND(VLOOKUP($B7, $K$11:$S$23, COLUMNS($K$11:P$11), FALSE), 0) -> 658 | G7: =ROUND(VLOOKUP($B7, $K$11:$S$23, COLUMNS($K$11:Q$11), FALSE), 0) -> 643 | H7: =ROUND(VLOOKUP($B7, $K$11:$S$23, COLUMNS($K$11:R$11), FALSE), 0) -> 628 | I7: =ROUND(VLOOKUP($B7, $K$11:$S$23, COLUMNS($K$11:S$11), FALSE), 0) -> 613 | U7: Note: Fwy off ramp capacity is 10% higher than a minor arterial
B8: 5 | C8: =ROUND(VLOOKUP($B8, $K$11:$S$23, COLUMNS($K$11:M$11), FALSE), 0) -> 515 | D8: =ROUND(VLOOKUP($B8, $K$11:$S$23, COLUMNS($K$11:N$11), FALSE), 0) -> 494 | E8: =ROUND(VLOOKUP($B8, $K$11:$S$23, COLUMNS($K$11:O$11), FALSE), 0) -> 473 | F8: =ROUND(VLOOKUP($B8, $K$11:$S$23, COLUMNS($K$11:P$11), FALSE), 0) -> 462 | G8: =ROUND(VLOOKUP($B8, $K$11:$S$23, COLUMNS($K$11:Q$11), FALSE), 0) -> 451 | H8: =ROUND(VLOOKUP($B8, $K$11:$S$23, COLUMNS($K$11:R$11), FALSE), 0) -> 441 | I8: =ROUND(VLOOKUP($B8, $K$11:$S$23, COLUMNS($K$11:S$11), FALSE), 0) -> 431
B9: 6 | C9: =ROUND(VLOOKUP($B9, $K$11:$S$23, COLUMNS($K$11:M$11), FALSE), 0) -> 412 | D9: =ROUND(VLOOKUP($B9, $K$11:$S$23, COLUMNS($K$11:N$11), FALSE), 0) -> 395 | E9: =ROUND(VLOOKUP($B9, $K$11:$S$23, COLUMNS($K$11:O$11), FALSE), 0) -> 378 | F9: =ROUND(VLOOKUP($B9, $K$11:$S$23, COLUMNS($K$11:P$11), FALSE), 0) -> 370 | G9: =ROUND(VLOOKUP($B9, $K$11:$S$23, COLUMNS($K$11:Q$11), FALSE), 0) -> 361 | H9: =ROUND(VLOOKUP($B9, $K$11:$S$23, COLUMNS($K$11:R$11), FALSE), 0) -> 353 | I9: =ROUND(VLOOKUP($B9, $K$11:$S$23, COLUMNS($K$11:S$11), FALSE), 0) -> 344 | K9: Calculate capacity per hour per lane | U9: Calculate capacity per hour per lane | AE9: Lanes | AF9: Non-Managed Motorways | AG9: Managed Motorways | AH9: Difference | AI9: % Difference
B10: 7 | C10: =ROUND(VLOOKUP($B10, $K$11:$S$23, COLUMNS($K$11:M$11), FALSE), 0) -> 300 | D10: =ROUND(VLOOKUP($B10, $K$11:$S$23, COLUMNS($K$11:N$11), FALSE), 0) -> 300 | E10: =ROUND(VLOOKUP($B10, $K$11:$S$23, COLUMNS($K$11:O$11), FALSE), 0) -> 300 | F10: =ROUND(VLOOKUP($B10, $K$11:$S$23, COLUMNS($K$11:P$11), FALSE), 0) -> 300 | G10: =ROUND(VLOOKUP($B10, $K$11:$S$23, COLUMNS($K$11:Q$11), FALSE), 0) -> 300 | H10: =ROUND(VLOOKUP($B10, $K$11:$S$23, COLUMNS($K$11:R$11), FALSE), 0) -> 300 | I10: =ROUND(VLOOKUP($B10, $K$11:$S$23, COLUMNS($K$11:S$11), FALSE), 0) -> 300 | AE10: VicRoads
B11: 12 | C11: =ROUND(VLOOKUP($B11, $K$11:$S$23, COLUMNS($K$11:M$11), FALSE), 0) -> 1102 | D11: =ROUND(VLOOKUP($B11, $K$11:$S$23, COLUMNS($K$11:N$11), FALSE), 0) -> 1058 | E11: =ROUND(VLOOKUP($B11, $K$11:$S$23, COLUMNS($K$11:O$11), FALSE), 0) -> 1025 | F11: =ROUND(VLOOKUP($B11, $K$11:$S$23, COLUMNS($K$11:P$11), FALSE), 0) -> 1003 | G11: =ROUND(VLOOKUP($B11, $K$11:$S$23, COLUMNS($K$11:Q$11), FALSE), 0) -> 981 | H11: =ROUND(VLOOKUP($B11, $K$11:$S$23, COLUMNS($K$11:R$11), FALSE), 0) -> 960 | I11: =ROUND(VLOOKUP($B11, $K$11:$S$23, COLUMNS($K$11:S$11), FALSE), 0) -> 940 | K11: FT | L11: Description | M11: 1 lane | N11: 2 lanes | O11: 3 lanes | P11: 4 lanes | Q11: 5 lanes | R11: 6 lanes | S11: 7 lanes | U11: FT | V11: Description | W11: 1 lane | X11: 2 lanes | Y11: 3 lanes | Z11: 4 lanes | AA11: 5 lanes | AB11: 6 lanes | AC11: 7 lanes | AE11: 2 | AF11: 1775 | AG11: 2088 | AH11: =AG11-AF11 -> 313 | AI11: =AH11 / AF11 -> 0.17633803
B12: 13 | C12: =ROUND(VLOOKUP($B12, $K$11:$S$23, COLUMNS($K$11:M$11), FALSE), 0) -> 1064 | D12: =ROUND(VLOOKUP($B12, $K$11:$S$23, COLUMNS($K$11:N$11), FALSE), 0) -> 1021 | E12: =ROUND(VLOOKUP($B12, $K$11:$S$23, COLUMNS($K$11:O$11), FALSE), 0) -> 990 | F12: =ROUND(VLOOKUP($B12, $K$11:$S$23, COLUMNS($K$11:P$11), FALSE), 0) -> 968 | G12: =ROUND(VLOOKUP($B12, $K$11:$S$23, COLUMNS($K$11:Q$11), FALSE), 0) -> 947 | H12: =ROUND(VLOOKUP($B12, $K$11:$S$23, COLUMNS($K$11:R$11), FALSE), 0) -> 927 | I12: =ROUND(VLOOKUP($B12, $K$11:$S$23, COLUMNS($K$11:S$11), FALSE), 0) -> 907 | K12: 1 | L12: Centroid Connector | M12: 10000 | N12: =M12 -> 10000 | O12: =N12 -> 10000 | P12: =O12 -> 10000 | Q12: =P12 -> 10000 | R12: =Q12 -> 10000 | S12: =R12 -> 10000 | U12: 20 | V12: MM: fwy-to-fwy loop ramp | W12: =W23 -> 1325.25 | X12: =X23 -> 1060.2 | Y12: =Y23 -> 848.16 | Z12: =Z23 -> 848.16 | AA12: =AA23 -> 848.16 | AB12: =AB23 -> 848.16 | AC12: =AC23 -> 848.16 | AE12: 3 | AF12: 1717 | AG12: 2017 | AH12: =AG12-AF12 -> 300 | AI12: =AH12 / AF12 -> 0.17472335
B13: 14 | C13: =ROUND(VLOOKUP($B13, $K$11:$S$23, COLUMNS($K$11:M$11), FALSE), 0) -> 1026 | D13: =ROUND(VLOOKUP($B13, $K$11:$S$23, COLUMNS($K$11:N$11), FALSE), 0) -> 985 | E13: =ROUND(VLOOKUP($B13, $K$11:$S$23, COLUMNS($K$11:O$11), FALSE), 0) -> 954 | F13: =ROUND(VLOOKUP($B13, $K$11:$S$23, COLUMNS($K$11:P$11), FALSE), 0) -> 934 | G13: =ROUND(VLOOKUP($B13, $K$11:$S$23, COLUMNS($K$11:Q$11), FALSE), 0) -> 914 | H13: =ROUND(VLOOKUP($B13, $K$11:$S$23, COLUMNS($K$11:R$11), FALSE), 0) -> 894 | I13: =ROUND(VLOOKUP($B13, $K$11:$S$23, COLUMNS($K$11:S$11), FALSE), 0) -> 875 | K13: 2 | L13: Principal Arterial | M13: =$O34 * M$27 * M$29 -> 968.24 | N13: =$O34 * N$27 * N$29 -> 929.214 | O13: =$O34 * O$27 * O$29 -> 890.0892 | P13: =$O34 * P$27 * P$29 -> 869.44 | Q13: =P13*P13/O13 -> 849.26984 | R13: =Q13*Q13/P13 -> 829.56761 | S13: =R13*R13/Q13 -> 810.32245 | U13: 21 | V13: MM: C-D road, flyover ramp | W13: =W24 -> 1472.5 | X13: =X24 -> 1472.5 | Y13: =Y24 -> 1472.5 | Z13: =Z24 -> 1443.05 | AA13: =AA24 -> 1398.875 | AB13: =AB24 -> 1339.975 | AC13: =AC24 -> 1295.8 | AE13: 4 | AF13: 1656 | AG13: 1950 | AH13: =AG13-AF13 -> 294 | AI13: =AH13 / AF13 -> 0.17753623
B14: 15 | C14: =ROUND(VLOOKUP($B14, $K$11:$S$23, COLUMNS($K$11:M$11), FALSE), 0) -> 988 | D14: =ROUND(VLOOKUP($B14, $K$11:$S$23, COLUMNS($K$11:N$11), FALSE), 0) -> 948 | E14: =ROUND(VLOOKUP($B14, $K$11:$S$23, COLUMNS($K$11:O$11), FALSE), 0) -> 919 | F14: =ROUND(VLOOKUP($B14, $K$11:$S$23, COLUMNS($K$11:P$11), FALSE), 0) -> 899 | G14: =ROUND(VLOOKUP($B14, $K$11:$S$23, COLUMNS($K$11:Q$11), FALSE), 0) -> 880 | H14: =ROUND(VLOOKUP($B14, $K$11:$S$23, COLUMNS($K$11:R$11), FALSE), 0) -> 861 | I14: =ROUND(VLOOKUP($B14, $K$11:$S$23, COLUMNS($K$11:S$11), FALSE), 0) -> 842 | K14: 3 | L14: Minor Arterial | M14: =$O35 * M$27 * M$29 -> 893.76 | N14: =$O35 * N$27 * N$29 -> 857.736 | O14: =$O35 * O$27 * O$29 -> 821.6208 | P14: =$O35 * P$27 * P$29 -> 802.56 | Q14: =P14*P14/O14 -> 783.94139 | R14: =Q14*Q14/P14 -> 765.75472 | S14: =R14*R14/Q14 -> 747.98996 | U14: 22 | V14: MM: posted 55-60 mph | W14: =($Z48*W$39*W$38 + $AA48) / W$38 -> 1921.9806 | X14: =($Z48*X$39*X$38 + $AA48) / X$38 -> 1921.9806 | Y14: =($Z48*Y$39*Y$38 + $AA48) / Y$38 -> 1921.9806 | Z14: =($Z48*Z$39*Z$38 + $AA48) / Z$38 -> 1883.541 | AA14: =($Z48*AA$39*AA$38 + $AA48) / AA$38 -> 1825.8816 | AB14: =($Z48*AB$39*AB$38 + $AA48) / AB$38 -> 1749.0024 | AC14: =($Z48*AC$39*AC$38 + $AA48) / AC$38 -> 1691.3429 | AE14: 5 | AF14: 1575 | AG14: 1855 | AH14: =AG14-AF14 -> 280 | AI14: =AH14 / AF14 -> 0.17777778
B15: 20 | C15: =ROUND(VLOOKUP($B15, $U$11:$AC$35, COLUMNS($U$11:W$11), FALSE), 0) -> 1325 | D15: =ROUND(VLOOKUP($B15, $U$11:$AC$35, COLUMNS($U$11:X$11), FALSE), 0) -> 1060 | E15: =ROUND(VLOOKUP($B15, $U$11:$AC$35, COLUMNS($U$11:Y$11), FALSE), 0) -> 848 | F15: =ROUND(VLOOKUP($B15, $U$11:$AC$35, COLUMNS($U$11:Z$11), FALSE), 0) -> 848 | G15: =ROUND(VLOOKUP($B15, $U$11:$AC$35, COLUMNS($U$11:AA$11), FALSE), 0) -> 848 | H15: =ROUND(VLOOKUP($B15, $U$11:$AC$35, COLUMNS($U$11:AB$11), FALSE), 0) -> 848 | I15: =ROUND(VLOOKUP($B15, $U$11:$AC$35, COLUMNS($U$11:AC$11), FALSE), 0) -> 848 | K15: 4 | L15: Major Collector | M15: =$O36 * M$27 * M$29 -> 733.04 | N15: =$O36 * N$27 * N$29 -> 703.494 | O15: =$O36 * O$27 * O$29 -> 673.8732 | P15: =$O36 * P$27 * P$29 -> 658.24 | Q15: =P15*P15/O15 -> 642.96947 | R15: =Q15*Q15/P15 -> 628.05321 | S15: =R15*R15/Q15 -> 613.48299 | U15: 23 | V15: MM: posted 65 mph, no aux lane | W15: =($Z49*W$39*W$38 + $AA49) / W$38 -> 1963.7628 | X15: =($Z49*X$39*X$38 + $AA49) / X$38 -> 1963.7628 | Y15: =($Z49*Y$39*Y$38 + $AA49) / Y$38 -> 1963.7628 | Z15: =($Z49*Z$39*Z$38 + $AA49) / Z$38 -> 1924.4876 | AA15: =($Z49*AA$39*AA$38 + $AA49) / AA$38 -> 1865.5747 | AB15: =($Z49*AB$39*AB$38 + $AA49) / AB$38 -> 1787.0242 | AC15: =($Z49*AC$39*AC$38 + $AA49) / AC$38 -> 1728.1113
B16: 21 | C16: =ROUND(VLOOKUP($B16, $U$11:$AC$35, COLUMNS($U$11:W$11), FALSE), 0) -> 1473 | D16: =ROUND(VLOOKUP($B16, $U$11:$AC$35, COLUMNS($U$11:X$11), FALSE), 0) -> 1473 | E16: =ROUND(VLOOKUP($B16, $U$11:$AC$35, COLUMNS($U$11:Y$11), FALSE), 0) -> 1473 | F16: =ROUND(VLOOKUP($B16, $U$11:$AC$35, COLUMNS($U$11:Z$11), FALSE), 0) -> 1443 | G16: =ROUND(VLOOKUP($B16, $U$11:$AC$35, COLUMNS($U$11:AA$11), FALSE), 0) -> 1399 | H16: =ROUND(VLOOKUP($B16, $U$11:$AC$35, COLUMNS($U$11:AB$11), FALSE), 0) -> 1340 | I16: =ROUND(VLOOKUP($B16, $U$11:$AC$35, COLUMNS($U$11:AC$11), FALSE), 0) -> 1296 | K16: 5 | L16: Minor Collector | M16: =$O37 * M$27 * M$29 -> 514.5 | N16: =$O37 * N$27 * N$29 -> 493.7625 | O16: =$O37 * O$27 * O$29 -> 472.9725 | P16: =$O37 * P$27 * P$29 -> 462 | Q16: =P16*P16/O16 -> 451.28205 | R16: =Q16*Q16/P16 -> 440.81275 | S16: =R16*R16/Q16 -> 430.58632 | U16: 24 | V16: MM: posted 65 mph, aux lane | W16: =($Z50*W$39*W$38 + $AA50) / W$38 -> 2663.7628 | X16: =($Z50*X$39*X$38 + $AA50) / X$38 -> 2313.7628 | Y16: =($Z50*Y$39*Y$38 + $AA50) / Y$38 -> 2197.0961 | Z16: =($Z50*Z$39*Z$38 + $AA50) / Z$38 -> 2099.4876 | AA16: =($Z50*AA$39*AA$38 + $AA50) / AA$38 -> 2005.5747 | AB16: =($Z50*AB$39*AB$38 + $AA50) / AB$38 -> 1903.6908 | AC16: =($Z50*AC$39*AC$38 + $AA50) / AC$38 -> 1828.1113 | AE16: Travel Demand Model
B17: 22 | C17: =ROUND(VLOOKUP($B17, $U$11:$AC$35, COLUMNS($U$11:W$11), FALSE), 0) -> 1922 | D17: =ROUND(VLOOKUP($B17, $U$11:$AC$35, COLUMNS($U$11:X$11), FALSE), 0) -> 1922 | E17: =ROUND(VLOOKUP($B17, $U$11:$AC$35, COLUMNS($U$11:Y$11), FALSE), 0) -> 1922 | F17: =ROUND(VLOOKUP($B17, $U$11:$AC$35, COLUMNS($U$11:Z$11), FALSE), 0) -> 1884 | G17: =ROUND(VLOOKUP($B17, $U$11:$AC$35, COLUMNS($U$11:AA$11), FALSE), 0) -> 1826 | H17: =ROUND(VLOOKUP($B17, $U$11:$AC$35, COLUMNS($U$11:AB$11), FALSE), 0) -> 1749 | I17: =ROUND(VLOOKUP($B17, $U$11:$AC$35, COLUMNS($U$11:AC$11), FALSE), 0) -> 1691 | K17: 6 | L17: Local | M17: =M16 * 0.8 -> 411.6 | N17: =N16 * 0.8 -> 395.01 | O17: =O16 * 0.8 -> 378.378 | P17: =P16 * 0.8 -> 369.6 | Q17: =P17*P17/O17 -> 361.02564 | R17: =Q17*Q17/P17 -> 352.6502 | S17: =R17*R17/Q17 -> 344.46906 | U17: 25 | V17: MM: posted 75 mph, no aux lane | W17: =($Z51*W$39*W$38 + $AA51) / W$38 -> 2005.545 | X17: =($Z51*X$39*X$38 + $AA51) / X$38 -> 2005.545 | Y17: =($Z51*Y$39*Y$38 + $AA51) / Y$38 -> 2005.545 | Z17: =($Z51*Z$39*Z$38 + $AA51) / Z$38 -> 1965.4341 | AA17: =($Z51*AA$39*AA$38 + $AA51) / AA$38 -> 1905.2677 | AB17: =($Z51*AB$39*AB$38 + $AA51) / AB$38 -> 1825.046 | AC17: =($Z51*AC$39*AC$38 + $AA51) / AC$38 -> 1764.8796 | AE17: 2 | AF17: 1730 | AG17: 2100 | AH17: =AG17-AF17 -> 370 | AI17: =AH17 / AF17 -> 0.21387283
B18: 23 | C18: =ROUND(VLOOKUP($B18, $U$11:$AC$35, COLUMNS($U$11:W$11), FALSE), 0) -> 1964 | D18: =ROUND(VLOOKUP($B18, $U$11:$AC$35, COLUMNS($U$11:X$11), FALSE), 0) -> 1964 | E18: =ROUND(VLOOKUP($B18, $U$11:$AC$35, COLUMNS($U$11:Y$11), FALSE), 0) -> 1964 | F18: =ROUND(VLOOKUP($B18, $U$11:$AC$35, COLUMNS($U$11:Z$11), FALSE), 0) -> 1924 | G18: =ROUND(VLOOKUP($B18, $U$11:$AC$35, COLUMNS($U$11:AA$11), FALSE), 0) -> 1866 | H18: =ROUND(VLOOKUP($B18, $U$11:$AC$35, COLUMNS($U$11:AB$11), FALSE), 0) -> 1787 | I18: =ROUND(VLOOKUP($B18, $U$11:$AC$35, COLUMNS($U$11:AC$11), FALSE), 0) -> 1728 | K18: 7 | L18: Unpaved | M18: 300 | N18: =M18 -> 300 | O18: =N18 -> 300 | P18: =O18 -> 300 | Q18: =P18 -> 300 | R18: =Q18 -> 300 | S18: =R18 -> 300 | U18: 26 | V18: MM: posted 75 mph, aux lane | W18: =($Z52*W$39*W$38 + $AA52) / W$38 -> 2705.545 | X18: =($Z52*X$39*X$38 + $AA52) / X$38 -> 2355.545 | Y18: =($Z52*Y$39*Y$38 + $AA52) / Y$38 -> 2238.8783 | Z18: =($Z52*Z$39*Z$38 + $AA52) / Z$38 -> 2140.4341 | AA18: =($Z52*AA$39*AA$38 + $AA52) / AA$38 -> 2045.2677 | AB18: =($Z52*AB$39*AB$38 + $AA52) / AB$38 -> 1941.7126 | AC18: =($Z52*AC$39*AC$38 + $AA52) / AC$38 -> 1864.8796 | AE18: 3 | AF18: 1730 | AG18: 2100 | AH18: =AG18-AF18 -> 370 | AI18: =AH18 / AF18 -> 0.21387283
B19: 24 | C19: =ROUND(VLOOKUP($B19, $U$11:$AC$35, COLUMNS($U$11:W$11), FALSE), 0) -> 2664 | D19: =ROUND(VLOOKUP($B19, $U$11:$AC$35, COLUMNS($U$11:X$11), FALSE), 0) -> 2314 | E19: =ROUND(VLOOKUP($B19, $U$11:$AC$35, COLUMNS($U$11:Y$11), FALSE), 0) -> 2197 | F19: =ROUND(VLOOKUP($B19, $U$11:$AC$35, COLUMNS($U$11:Z$11), FALSE), 0) -> 2099 | G19: =ROUND(VLOOKUP($B19, $U$11:$AC$35, COLUMNS($U$11:AA$11), FALSE), 0) -> 2006 | H19: =ROUND(VLOOKUP($B19, $U$11:$AC$35, COLUMNS($U$11:AB$11), FALSE), 0) -> 1904 | I19: =ROUND(VLOOKUP($B19, $U$11:$AC$35, COLUMNS($U$11:AC$11), FALSE), 0) -> 1828 | U19: 27 | V19: place holder | W19: =W18 -> 2705.545 | X19: =X18 -> 2355.545 | Y19: =Y18 -> 2238.8783 | Z19: =Z18 -> 2140.4341 | AA19: =AA18 -> 2045.2677 | AB19: =AB18 -> 1941.7126 | AC19: =AC18 -> 1864.8796 | AE19: 4 | AF19: 1696 | AG19: 2058 | AH19: =AG19-AF19 -> 362 | AI19: =AH19 / AF19 -> 0.2134434
B20: 25 | C20: =ROUND(VLOOKUP($B20, $U$11:$AC$35, COLUMNS($U$11:W$11), FALSE), 0) -> 2006 | D20: =ROUND(VLOOKUP($B20, $U$11:$AC$35, COLUMNS($U$11:X$11), FALSE), 0) -> 2006 | E20: =ROUND(VLOOKUP($B20, $U$11:$AC$35, COLUMNS($U$11:Y$11), FALSE), 0) -> 2006 | F20: =ROUND(VLOOKUP($B20, $U$11:$AC$35, COLUMNS($U$11:Z$11), FALSE), 0) -> 1965 | G20: =ROUND(VLOOKUP($B20, $U$11:$AC$35, COLUMNS($U$11:AA$11), FALSE), 0) -> 1905 | H20: =ROUND(VLOOKUP($B20, $U$11:$AC$35, COLUMNS($U$11:AB$11), FALSE), 0) -> 1825 | I20: =ROUND(VLOOKUP($B20, $U$11:$AC$35, COLUMNS($U$11:AC$11), FALSE), 0) -> 1765 | K20: 12 | L20: Expressway, posted 60-70 mph | M20: =$O39 * M$28 * M$30 -> 1102 | N20: =$O39 * N$28 * N$30 -> 1057.92 | O20: =$O39 * O$28 * O$30 -> 1024.86 | P20: =$O39 * P$28 * P$30 -> 1002.82 | Q20: =P20*P20/O20 -> 981.25398 | R20: =Q20*Q20/P20 -> 960.15174 | S20: =R20*R20/Q20 -> 939.50332 | U20: 28 | V20: MM: On-ramp | W20: =W34 -> 1200 | X20: =X34 -> 900 | Y20: =Y34 -> 600 | Z20: =Z34 -> 600 | AA20: =AA34 -> 600 | AB20: =AB34 -> 600 | AC20: =AC34 -> 600 | AE20: 5 | AF20: 1644 | AG20: 1995 | AH20: =AG20-AF20 -> 351 | AI20: =AH20 / AF20 -> 0.21350365
B21: 26 | C21: =ROUND(VLOOKUP($B21, $U$11:$AC$35, COLUMNS($U$11:W$11), FALSE), 0) -> 2706 | D21: =ROUND(VLOOKUP($B21, $U$11:$AC$35, COLUMNS($U$11:X$11), FALSE), 0) -> 2356 | E21: =ROUND(VLOOKUP($B21, $U$11:$AC$35, COLUMNS($U$11:Y$11), FALSE), 0) -> 2239 | F21: =ROUND(VLOOKUP($B21, $U$11:$AC$35, COLUMNS($U$11:Z$11), FALSE), 0) -> 2140 | G21: =ROUND(VLOOKUP($B21, $U$11:$AC$35, COLUMNS($U$11:AA$11), FALSE), 0) -> 2045 | H21: =ROUND(VLOOKUP($B21, $U$11:$AC$35, COLUMNS($U$11:AB$11), FALSE), 0) -> 1942 | I21: =ROUND(VLOOKUP($B21, $U$11:$AC$35, COLUMNS($U$11:AC$11), FALSE), 0) -> 1865 | K21: 13 | L21: Expressway, posted 55-65 mph | M21: =$O40 * M$28 * M$30 -> 1064 | N21: =$O40 * N$28 * N$30 -> 1021.44 | O21: =$O40 * O$28 * O$30 -> 989.52 | P21: =$O40 * P$28 * P$30 -> 968.24 | Q21: =P21*P21/O21 -> 947.41763 | R21: =Q21*Q21/P21 -> 927.04306 | S21: =R21*R21/Q21 -> 907.10665 | U21: 29 | V21: MM: Off-ramp | W21: =W35 -> 893.76 | X21: =X35 -> 857.736 | Y21: =Y35 -> 821.6208 | Z21: =Z35 -> 802.56 | AA21: =AA35 -> 783.94139 | AB21: =AB35 -> 765.75472 | AC21: =AC35 -> 747.98996
B22: 27 | C22: =ROUND(VLOOKUP($B22, $U$11:$AC$35, COLUMNS($U$11:W$11), FALSE), 0) -> 2706 | D22: =ROUND(VLOOKUP($B22, $U$11:$AC$35, COLUMNS($U$11:X$11), FALSE), 0) -> 2356 | E22: =ROUND(VLOOKUP($B22, $U$11:$AC$35, COLUMNS($U$11:Y$11), FALSE), 0) -> 2239 | F22: =ROUND(VLOOKUP($B22, $U$11:$AC$35, COLUMNS($U$11:Z$11), FALSE), 0) -> 2140 | G22: =ROUND(VLOOKUP($B22, $U$11:$AC$35, COLUMNS($U$11:AA$11), FALSE), 0) -> 2045 | H22: =ROUND(VLOOKUP($B22, $U$11:$AC$35, COLUMNS($U$11:AB$11), FALSE), 0) -> 1942 | I22: =ROUND(VLOOKUP($B22, $U$11:$AC$35, COLUMNS($U$11:AC$11), FALSE), 0) -> 1865 | K22: 14 | L22: Expressway, posted 50-60 mph | M22: =$O41 * M$28 * M$30 -> 1026 | N22: =$O41 * N$28 * N$30 -> 984.96 | O22: =$O41 * O$28 * O$30 -> 954.18 | P22: =$O41 * P$28 * P$30 -> 933.66 | Q22: =P22*P22/O22 -> 913.58129 | R22: =Q22*Q22/P22 -> 893.93438 | S22: =R22*R22/Q22 -> 874.70999
B23: 28 | C23: =ROUND(VLOOKUP($B23, $U$11:$AC$35, COLUMNS($U$11:W$11), FALSE), 0) -> 1200 | D23: =ROUND(VLOOKUP($B23, $U$11:$AC$35, COLUMNS($U$11:X$11), FALSE), 0) -> 900 | E23: =ROUND(VLOOKUP($B23, $U$11:$AC$35, COLUMNS($U$11:Y$11), FALSE), 0) -> 600 | F23: =ROUND(VLOOKUP($B23, $U$11:$AC$35, COLUMNS($U$11:Z$11), FALSE), 0) -> 600 | G23: =ROUND(VLOOKUP($B23, $U$11:$AC$35, COLUMNS($U$11:AA$11), FALSE), 0) -> 600 | H23: =ROUND(VLOOKUP($B23, $U$11:$AC$35, COLUMNS($U$11:AB$11), FALSE), 0) -> 600 | I23: =ROUND(VLOOKUP($B23, $U$11:$AC$35, COLUMNS($U$11:AC$11), FALSE), 0) -> 600 | K23: 15 | L23: Expressway, posted 45-55 mph | M23: =$O42 * M$28 * M$30 -> 988 | N23: =$O42 * N$28 * N$30 -> 948.48 | O23: =$O42 * O$28 * O$30 -> 918.84 | P23: =$O42 * P$28 * P$30 -> 899.08 | Q23: =P23*P23/O23 -> 879.74495 | R23: =Q23*Q23/P23 -> 860.8257 | S23: =R23*R23/Q23 -> 842.31332 | U23: 30 | V23: Fwy: fwy-to-fwy loop ramp | W23: =($Y46*W$39*W$38 + $AA46) / W$38 -> 1325.25 | X23: =W23*0.8 -> 1060.2 | Y23: =X23*0.8 -> 848.16 | Z23: =Y23 -> 848.16 | AA23: =Z23 -> 848.16 | AB23: =AA23 -> 848.16 | AC23: =AB23 -> 848.16
B24: 29 | C24: =ROUND(VLOOKUP($B24, $U$11:$AC$35, COLUMNS($U$11:W$11), FALSE), 0) -> 894 | D24: =ROUND(VLOOKUP($B24, $U$11:$AC$35, COLUMNS($U$11:X$11), FALSE), 0) -> 858 | E24: =ROUND(VLOOKUP($B24, $U$11:$AC$35, COLUMNS($U$11:Y$11), FALSE), 0) -> 822 | F24: =ROUND(VLOOKUP($B24, $U$11:$AC$35, COLUMNS($U$11:Z$11), FALSE), 0) -> 803 | G24: =ROUND(VLOOKUP($B24, $U$11:$AC$35, COLUMNS($U$11:AA$11), FALSE), 0) -> 784 | H24: =ROUND(VLOOKUP($B24, $U$11:$AC$35, COLUMNS($U$11:AB$11), FALSE), 0) -> 766 | I24: =ROUND(VLOOKUP($B24, $U$11:$AC$35, COLUMNS($U$11:AC$11), FALSE), 0) -> 748 | U24: 31 | V24: Fwy: C-D road, flyover ramp | W24: =($Y47*W$39*W$38 + $AA47) / W$38 -> 1472.5 | X24: =($Y47*X$39*X$38 + $AA47) / X$38 -> 1472.5 | Y24: =($Y47*Y$39*Y$38 + $AA47) / Y$38 -> 1472.5 | Z24: =($Y47*Z$39*Z$38 + $AA47) / Z$38 -> 1443.05 | AA24: =($Y47*AA$39*AA$38 + $AA47) / AA$38 -> 1398.875 | AB24: =($Y47*AB$39*AB$38 + $AA47) / AB$38 -> 1339.975 | AC24: =($Y47*AC$39*AC$38 + $AA47) / AC$38 -> 1295.8 | AE24: Typical Freeway
B25: 30 | C25: =ROUND(VLOOKUP($B25, $U$11:$AC$35, COLUMNS($U$11:W$11), FALSE), 0) -> 1325 | D25: =ROUND(VLOOKUP($B25, $U$11:$AC$35, COLUMNS($U$11:X$11), FALSE), 0) -> 1060 | E25: =ROUND(VLOOKUP($B25, $U$11:$AC$35, COLUMNS($U$11:Y$11), FALSE), 0) -> 848 | F25: =ROUND(VLOOKUP($B25, $U$11:$AC$35, COLUMNS($U$11:Z$11), FALSE), 0) -> 848 | G25: =ROUND(VLOOKUP($B25, $U$11:$AC$35, COLUMNS($U$11:AA$11), FALSE), 0) -> 848 | H25: =ROUND(VLOOKUP($B25, $U$11:$AC$35, COLUMNS($U$11:AB$11), FALSE), 0) -> 848 | I25: =ROUND(VLOOKUP($B25, $U$11:$AC$35, COLUMNS($U$11:AC$11), FALSE), 0) -> 848 | U25: 32 | V25: Fwy: posted 55-60 mph | W25: =($Y48*W$39*W$38 + $AA48) / W$38 -> 1693.375 | X25: =($Y48*X$39*X$38 + $AA48) / X$38 -> 1693.375 | Y25: =($Y48*Y$39*Y$38 + $AA48) / Y$38 -> 1693.375 | Z25: =($Y48*Z$39*Z$38 + $AA48) / Z$38 -> 1659.5075 | AA25: =($Y48*AA$39*AA$38 + $AA48) / AA$38 -> 1608.7062 | AB25: =($Y48*AB$39*AB$38 + $AA48) / AB$38 -> 1540.9712 | AC25: =($Y48*AC$39*AC$38 + $AA48) / AC$38 -> 1490.17 | AE25: Lanes | AF25: VicRoads | AG25: TDM | AH25: Difference | AI25: % Difference
B26: 31 | C26: =ROUND(VLOOKUP($B26, $U$11:$AC$35, COLUMNS($U$11:W$11), FALSE), 0) -> 1473 | D26: =ROUND(VLOOKUP($B26, $U$11:$AC$35, COLUMNS($U$11:X$11), FALSE), 0) -> 1473 | E26: =ROUND(VLOOKUP($B26, $U$11:$AC$35, COLUMNS($U$11:Y$11), FALSE), 0) -> 1473 | F26: =ROUND(VLOOKUP($B26, $U$11:$AC$35, COLUMNS($U$11:Z$11), FALSE), 0) -> 1443 | G26: =ROUND(VLOOKUP($B26, $U$11:$AC$35, COLUMNS($U$11:AA$11), FALSE), 0) -> 1399 | H26: =ROUND(VLOOKUP($B26, $U$11:$AC$35, COLUMNS($U$11:AB$11), FALSE), 0) -> 1340 | I26: =ROUND(VLOOKUP($B26, $U$11:$AC$35, COLUMNS($U$11:AC$11), FALSE), 0) -> 1296 | L26: Lanes | M26: 1 | N26: 2 | O26: 3 | P26: 4 | U26: 33 | V26: Fwy: posted 65 mph, no aux lane | W26: =($Y49*W$39*W$38 + $AA49) / W$38 -> 1730.1875 | X26: =($Y49*X$39*X$38 + $AA49) / X$38 -> 1730.1875 | Y26: =($Y49*Y$39*Y$38 + $AA49) / Y$38 -> 1730.1875 | Z26: =($Y49*Z$39*Z$38 + $AA49) / Z$38 -> 1695.5838 | AA26: =($Y49*AA$39*AA$38 + $AA49) / AA$38 -> 1643.6781 | AB26: =($Y49*AB$39*AB$38 + $AA49) / AB$38 -> 1574.4706 | AC26: =($Y49*AC$39*AC$38 + $AA49) / AC$38 -> 1522.565 | AE26: 2 | AF26: =AF11 -> 1775 | AG26: =AF17 -> 1730 | AH26: =AG26-AF26 -> -45 | AI26: =AH26/AF26 -> -0.025352113
B27: 32 | C27: =ROUND(VLOOKUP($B27, $U$11:$AC$35, COLUMNS($U$11:W$11), FALSE), 0) -> 1693 | D27: =ROUND(VLOOKUP($B27, $U$11:$AC$35, COLUMNS($U$11:X$11), FALSE), 0) -> 1693 | E27: =ROUND(VLOOKUP($B27, $U$11:$AC$35, COLUMNS($U$11:Y$11), FALSE), 0) -> 1693 | F27: =ROUND(VLOOKUP($B27, $U$11:$AC$35, COLUMNS($U$11:Z$11), FALSE), 0) -> 1660 | G27: =ROUND(VLOOKUP($B27, $U$11:$AC$35, COLUMNS($U$11:AA$11), FALSE), 0) -> 1609 | H27: =ROUND(VLOOKUP($B27, $U$11:$AC$35, COLUMNS($U$11:AB$11), FALSE), 0) -> 1541 | I27: =ROUND(VLOOKUP($B27, $U$11:$AC$35, COLUMNS($U$11:AC$11), FALSE), 0) -> 1490 | L27: Bus Blockage Factors (Fbb) - Arterials | M27: 0.98 | N27: 0.99 | O27: 0.99 | P27: 1 | U27: 34 | V27: Fwy: posted 65 mph, aux lane | W27: =($Y50*W$39*W$38 + $AA50) / W$38 -> 2430.1875 | X27: =($Y50*X$39*X$38 + $AA50) / X$38 -> 2080.1875 | Y27: =($Y50*Y$39*Y$38 + $AA50) / Y$38 -> 1963.5208 | Z27: =($Y50*Z$39*Z$38 + $AA50) / Z$38 -> 1870.5838 | AA27: =($Y50*AA$39*AA$38 + $AA50) / AA$38 -> 1783.6781 | AB27: =($Y50*AB$39*AB$38 + $AA50) / AB$38 -> 1691.1373 | AC27: =($Y50*AC$39*AC$38 + $AA50) / AC$38 -> 1622.565 | AE27: 3 | AF27: =AF12 -> 1717 | AG27: =AF18 -> 1730 | AH27: =AG27-AF27 -> 13 | AI27: =AH27/AF27 -> 0.0075713454
B28: 33 | C28: =ROUND(VLOOKUP($B28, $U$11:$AC$35, COLUMNS($U$11:W$11), FALSE), 0) -> 1730 | D28: =ROUND(VLOOKUP($B28, $U$11:$AC$35, COLUMNS($U$11:X$11), FALSE), 0) -> 1730 | E28: =ROUND(VLOOKUP($B28, $U$11:$AC$35, COLUMNS($U$11:Y$11), FALSE), 0) -> 1730 | F28: =ROUND(VLOOKUP($B28, $U$11:$AC$35, COLUMNS($U$11:Z$11), FALSE), 0) -> 1696 | G28: =ROUND(VLOOKUP($B28, $U$11:$AC$35, COLUMNS($U$11:AA$11), FALSE), 0) -> 1644 | H28: =ROUND(VLOOKUP($B28, $U$11:$AC$35, COLUMNS($U$11:AB$11), FALSE), 0) -> 1574 | I28: =ROUND(VLOOKUP($B28, $U$11:$AC$35, COLUMNS($U$11:AC$11), FALSE), 0) -> 1523 | L28: Bus Blockage Factors (Fbb) - Expressways | M28: 1 | N28: 1 | O28: 1 | P28: 1 | U28: 35 | V28: Fwy: posted 75 mph, no aux lane | W28: =($Y51*W$39*W$38 + $AA51) / W$38 -> 1767 | X28: =($Y51*X$39*X$38 + $AA51) / X$38 -> 1767 | Y28: =($Y51*Y$39*Y$38 + $AA51) / Y$38 -> 1767 | Z28: =($Y51*Z$39*Z$38 + $AA51) / Z$38 -> 1731.66 | AA28: =($Y51*AA$39*AA$38 + $AA51) / AA$38 -> 1678.65 | AB28: =($Y51*AB$39*AB$38 + $AA51) / AB$38 -> 1607.97 | AC28: =($Y51*AC$39*AC$38 + $AA51) / AC$38 -> 1554.96 | AE28: 4 | AF28: =AF13 -> 1656 | AG28: =AF19 -> 1696 | AH28: =AG28-AF28 -> 40 | AI28: =AH28/AF28 -> 0.024154589
B29: 34 | C29: =ROUND(VLOOKUP($B29, $U$11:$AC$35, COLUMNS($U$11:W$11), FALSE), 0) -> 2430 | D29: =ROUND(VLOOKUP($B29, $U$11:$AC$35, COLUMNS($U$11:X$11), FALSE), 0) -> 2080 | E29: =ROUND(VLOOKUP($B29, $U$11:$AC$35, COLUMNS($U$11:Y$11), FALSE), 0) -> 1964 | F29: =ROUND(VLOOKUP($B29, $U$11:$AC$35, COLUMNS($U$11:Z$11), FALSE), 0) -> 1871 | G29: =ROUND(VLOOKUP($B29, $U$11:$AC$35, COLUMNS($U$11:AA$11), FALSE), 0) -> 1784 | H29: =ROUND(VLOOKUP($B29, $U$11:$AC$35, COLUMNS($U$11:AB$11), FALSE), 0) -> 1691 | I29: =ROUND(VLOOKUP($B29, $U$11:$AC$35, COLUMNS($U$11:AC$11), FALSE), 0) -> 1623 | L29: Lane Utilization Factor (Flu) - Arterials | M29: 1 | N29: 0.95 | O29: 0.91 | P29: 0.88 | U29: 36 | V29: Fwy: posted 75 mph, aux lane | W29: =($Y52*W$39*W$38 + $AA52) / W$38 -> 2467 | X29: =($Y52*X$39*X$38 + $AA52) / X$38 -> 2117 | Y29: =($Y52*Y$39*Y$38 + $AA52) / Y$38 -> 2000.3333 | Z29: =($Y52*Z$39*Z$38 + $AA52) / Z$38 -> 1906.66 | AA29: =($Y52*AA$39*AA$38 + $AA52) / AA$38 -> 1818.65 | AB29: =($Y52*AB$39*AB$38 + $AA52) / AB$38 -> 1724.6367 | AC29: =($Y52*AC$39*AC$38 + $AA52) / AC$38 -> 1654.96 | AE29: 5 | AF29: =AF14 -> 1575 | AG29: =AF20 -> 1644 | AH29: =AG29-AF29 -> 69 | AI29: =AH29/AF29 -> 0.043809524
B30: 35 | C30: =ROUND(VLOOKUP($B30, $U$11:$AC$35, COLUMNS($U$11:W$11), FALSE), 0) -> 1767 | D30: =ROUND(VLOOKUP($B30, $U$11:$AC$35, COLUMNS($U$11:X$11), FALSE), 0) -> 1767 | E30: =ROUND(VLOOKUP($B30, $U$11:$AC$35, COLUMNS($U$11:Y$11), FALSE), 0) -> 1767 | F30: =ROUND(VLOOKUP($B30, $U$11:$AC$35, COLUMNS($U$11:Z$11), FALSE), 0) -> 1732 | G30: =ROUND(VLOOKUP($B30, $U$11:$AC$35, COLUMNS($U$11:AA$11), FALSE), 0) -> 1679 | H30: =ROUND(VLOOKUP($B30, $U$11:$AC$35, COLUMNS($U$11:AB$11), FALSE), 0) -> 1608 | I30: =ROUND(VLOOKUP($B30, $U$11:$AC$35, COLUMNS($U$11:AC$11), FALSE), 0) -> 1555 | L30: Lane Utilization Factor (Flu) - Expressways | M30: 1 | N30: 0.96 | O30: 0.93 | P30: 0.91 | U30: 37 | V30: Fwy: HOV lane | W30: =($Y53*W$39*W$38 + $AA53) / W$38 -> 1767 | X30: =($Y53*X$39*X$38 + $AA53) / X$38 -> 1767 | Y30: =($Y53*Y$39*Y$38 + $AA53) / Y$38 -> 1767 | Z30: =($Y53*Z$39*Z$38 + $AA53) / Z$38 -> 1731.66 | AA30: =($Y53*AA$39*AA$38 + $AA53) / AA$38 -> 1678.65 | AB30: =($Y53*AB$39*AB$38 + $AA53) / AB$38 -> 1607.97 | AC30: =($Y53*AC$39*AC$38 + $AA53) / AC$38 -> 1554.96
B31: 36 | C31: =ROUND(VLOOKUP($B31, $U$11:$AC$35, COLUMNS($U$11:W$11), FALSE), 0) -> 2467 | D31: =ROUND(VLOOKUP($B31, $U$11:$AC$35, COLUMNS($U$11:X$11), FALSE), 0) -> 2117 | E31: =ROUND(VLOOKUP($B31, $U$11:$AC$35, COLUMNS($U$11:Y$11), FALSE), 0) -> 2000 | F31: =ROUND(VLOOKUP($B31, $U$11:$AC$35, COLUMNS($U$11:Z$11), FALSE), 0) -> 1907 | G31: =ROUND(VLOOKUP($B31, $U$11:$AC$35, COLUMNS($U$11:AA$11), FALSE), 0) -> 1819 | H31: =ROUND(VLOOKUP($B31, $U$11:$AC$35, COLUMNS($U$11:AB$11), FALSE), 0) -> 1725 | I31: =ROUND(VLOOKUP($B31, $U$11:$AC$35, COLUMNS($U$11:AC$11), FALSE), 0) -> 1655 | U31: 38 | V31: Fwy: Managed lane | W31: =W30 -> 1767 | X31: =X30 -> 1767 | Y31: =Y30 -> 1767 | Z31: =Z30 -> 1731.66 | AA31: =AA30 -> 1678.65 | AB31: =AB30 -> 1607.97 | AC31: =AC30 -> 1554.96 | AE31: Managed Motorways
B32: 37 | C32: =ROUND(VLOOKUP($B32, $U$11:$AC$35, COLUMNS($U$11:W$11), FALSE), 0) -> 1767 | D32: =ROUND(VLOOKUP($B32, $U$11:$AC$35, COLUMNS($U$11:X$11), FALSE), 0) -> 1767 | E32: =ROUND(VLOOKUP($B32, $U$11:$AC$35, COLUMNS($U$11:Y$11), FALSE), 0) -> 1767 | F32: =ROUND(VLOOKUP($B32, $U$11:$AC$35, COLUMNS($U$11:Z$11), FALSE), 0) -> 1732 | G32: =ROUND(VLOOKUP($B32, $U$11:$AC$35, COLUMNS($U$11:AA$11), FALSE), 0) -> 1679 | H32: =ROUND(VLOOKUP($B32, $U$11:$AC$35, COLUMNS($U$11:AB$11), FALSE), 0) -> 1608 | I32: =ROUND(VLOOKUP($B32, $U$11:$AC$35, COLUMNS($U$11:AC$11), FALSE), 0) -> 1555 | U32: 39 | V32: Fwy: Managed lane access | W32: =W31 -> 1767 | X32: =X31 -> 1767 | Y32: =Y31 -> 1767 | Z32: =Z31 -> 1731.66 | AA32: =AA31 -> 1678.65 | AB32: =AB31 -> 1607.97 | AC32: =AC31 -> 1554.96 | AE32: Lanes | AF32: VicRoads | AG32: TDM | AH32: Difference | AI32: % Difference
B33: 38 | C33: =ROUND(VLOOKUP($B33, $U$11:$AC$35, COLUMNS($U$11:W$11), FALSE), 0) -> 1767 | D33: =ROUND(VLOOKUP($B33, $U$11:$AC$35, COLUMNS($U$11:X$11), FALSE), 0) -> 1767 | E33: =ROUND(VLOOKUP($B33, $U$11:$AC$35, COLUMNS($U$11:Y$11), FALSE), 0) -> 1767 | F33: =ROUND(VLOOKUP($B33, $U$11:$AC$35, COLUMNS($U$11:Z$11), FALSE), 0) -> 1732 | G33: =ROUND(VLOOKUP($B33, $U$11:$AC$35, COLUMNS($U$11:AA$11), FALSE), 0) -> 1679 | H33: =ROUND(VLOOKUP($B33, $U$11:$AC$35, COLUMNS($U$11:AB$11), FALSE), 0) -> 1608 | I33: =ROUND(VLOOKUP($B33, $U$11:$AC$35, COLUMNS($U$11:AC$11), FALSE), 0) -> 1555 | K33: FT | L33: Description | M33: Saturation Flow Rate | N33: % Green Time Factor (Fgrn) | O33: Saturation Flow Rate w/ Fgrn | U33: 40 | V33: Fwy: Tollway | W33: =AVERAGE(W16,W18) -> 2684.6539 | X33: =AVERAGE(X16,X18) -> 2334.6539 | Y33: =AVERAGE(Y16,Y18) -> 2217.9872 | Z33: =AVERAGE(Z16,Z18) -> 2119.9608 | AA33: =AVERAGE(AA16,AA18) -> 2025.4212 | AB33: =AVERAGE(AB16,AB18) -> 1922.7017 | AC33: =AVERAGE(AC16,AC18) -> 1846.4954 | AE33: 2 | AF33: =AG11 -> 2088 | AG33: =AG17 -> 2100 | AH33: =AG33-AF33 -> 12 | AI33: =AH33/AF33 -> 0.0057471264
B34: 39 | C34: =ROUND(VLOOKUP($B34, $U$11:$AC$35, COLUMNS($U$11:W$11), FALSE), 0) -> 1767 | D34: =ROUND(VLOOKUP($B34, $U$11:$AC$35, COLUMNS($U$11:X$11), FALSE), 0) -> 1767 | E34: =ROUND(VLOOKUP($B34, $U$11:$AC$35, COLUMNS($U$11:Y$11), FALSE), 0) -> 1767 | F34: =ROUND(VLOOKUP($B34, $U$11:$AC$35, COLUMNS($U$11:Z$11), FALSE), 0) -> 1732 | G34: =ROUND(VLOOKUP($B34, $U$11:$AC$35, COLUMNS($U$11:AA$11), FALSE), 0) -> 1679 | H34: =ROUND(VLOOKUP($B34, $U$11:$AC$35, COLUMNS($U$11:AB$11), FALSE), 0) -> 1608 | I34: =ROUND(VLOOKUP($B34, $U$11:$AC$35, COLUMNS($U$11:AC$11), FALSE), 0) -> 1555 | K34: 2 | L34: Principal Arterial | M34: 1900 | N34: 0.52 | O34: =M34 * N34 -> 988 | U34: 41 | V34: Fwy: On-ramp | W34: 1200 | X34: 900 | Y34: 600 | Z34: =Y34 -> 600 | AA34: =Z34 -> 600 | AB34: =AA34 -> 600 | AC34: =AB34 -> 600 | AE34: 3 | AF34: =AG12 -> 2017 | AG34: =AG18 -> 2100 | AH34: =AG34-AF34 -> 83 | AI34: =AH34/AF34 -> 0.041150223
B35: 40 | C35: =ROUND(VLOOKUP($B35, $U$11:$AC$35, COLUMNS($U$11:W$11), FALSE), 0) -> 2685 | D35: =ROUND(VLOOKUP($B35, $U$11:$AC$35, COLUMNS($U$11:X$11), FALSE), 0) -> 2335 | E35: =ROUND(VLOOKUP($B35, $U$11:$AC$35, COLUMNS($U$11:Y$11), FALSE), 0) -> 2218 | F35: =ROUND(VLOOKUP($B35, $U$11:$AC$35, COLUMNS($U$11:Z$11), FALSE), 0) -> 2120 | G35: =ROUND(VLOOKUP($B35, $U$11:$AC$35, COLUMNS($U$11:AA$11), FALSE), 0) -> 2025 | H35: =ROUND(VLOOKUP($B35, $U$11:$AC$35, COLUMNS($U$11:AB$11), FALSE), 0) -> 1923 | I35: =ROUND(VLOOKUP($B35, $U$11:$AC$35, COLUMNS($U$11:AC$11), FALSE), 0) -> 1846 | K35: 3 | L35: Minor Arterial | M35: 1900 | N35: 0.48 | O35: =M35 * N35 -> 912 | U35: 42 | V35: Fwy: Off-ramp | W35: =M14 -> 893.76 | X35: =N14 -> 857.736 | Y35: =O14 -> 821.6208 | Z35: =P14 -> 802.56 | AA35: =Q14 -> 783.94139 | AB35: =R14 -> 765.75472 | AC35: =S14 -> 747.98996 | AE35: 4 | AF35: =AG13 -> 1950 | AG35: =AG19 -> 2058 | AH35: =AG35-AF35 -> 108 | AI35: =AH35/AF35 -> 0.055384615
B36: 41 | C36: =ROUND(VLOOKUP($B36, $U$11:$AC$35, COLUMNS($U$11:W$11), FALSE), 0) -> 1200 | D36: =ROUND(VLOOKUP($B36, $U$11:$AC$35, COLUMNS($U$11:X$11), FALSE), 0) -> 900 | E36: =ROUND(VLOOKUP($B36, $U$11:$AC$35, COLUMNS($U$11:Y$11), FALSE), 0) -> 600 | F36: =ROUND(VLOOKUP($B36, $U$11:$AC$35, COLUMNS($U$11:Z$11), FALSE), 0) -> 600 | G36: =ROUND(VLOOKUP($B36, $U$11:$AC$35, COLUMNS($U$11:AA$11), FALSE), 0) -> 600 | H36: =ROUND(VLOOKUP($B36, $U$11:$AC$35, COLUMNS($U$11:AB$11), FALSE), 0) -> 600 | I36: =ROUND(VLOOKUP($B36, $U$11:$AC$35, COLUMNS($U$11:AC$11), FALSE), 0) -> 600 | K36: 4 | L36: Major Collector | M36: 1700 | N36: 0.44 | O36: =M36 * N36 -> 748 | AE36: 5 | AF36: =AG14 -> 1855 | AG36: =AG20 -> 1995 | AH36: =AG36-AF36 -> 140 | AI36: =AH36/AF36 -> 0.075471698
B37: 42 | C37: =ROUND(VLOOKUP($B37, $U$11:$AC$35, COLUMNS($U$11:W$11), FALSE), 0) -> 894 | D37: =ROUND(VLOOKUP($B37, $U$11:$AC$35, COLUMNS($U$11:X$11), FALSE), 0) -> 858 | E37: =ROUND(VLOOKUP($B37, $U$11:$AC$35, COLUMNS($U$11:Y$11), FALSE), 0) -> 822 | F37: =ROUND(VLOOKUP($B37, $U$11:$AC$35, COLUMNS($U$11:Z$11), FALSE), 0) -> 803 | G37: =ROUND(VLOOKUP($B37, $U$11:$AC$35, COLUMNS($U$11:AA$11), FALSE), 0) -> 784 | H37: =ROUND(VLOOKUP($B37, $U$11:$AC$35, COLUMNS($U$11:AB$11), FALSE), 0) -> 766 | I37: =ROUND(VLOOKUP($B37, $U$11:$AC$35, COLUMNS($U$11:AC$11), FALSE), 0) -> 748 | K37: 5 | L37: Minor Collector | M37: 1500 | N37: 0.35 | O37: =M37 * N37 -> 525
V38: Lanes | W38: 1 | X38: 2 | Y38: 3 | Z38: 4 | AA38: 5 | AB38: 6 | AC38: 7
K39: 12 | L39: Expressway, posted 60-70 mph | M39: 1900 | N39: 0.58 | O39: =M39 * N39 -> 1102 | V39: Lane Utilization Factor (Flu) | W39: 1 | X39: 1 | Y39: 1 | Z39: 0.98 | AA39: 0.95 | AB39: 0.91 | AC39: 0.88
K40: 13 | L40: Expressway, posted 55-65 mph | M40: 1900 | N40: 0.56 | O40: =M40 * N40 -> 1064
K41: 14 | L41: Expressway, posted 50-60 mph | M41: 1900 | N41: 0.54 | O41: =M41 * N41 -> 1026
...

Sheet VDF V8.3x
A1: Volume Delay Function Curves v8.3
B3: Fwy | C3: Ramp | D3: Exp | E3: Art | F3: Col | G3: MM | H3: Bng | I3: Art | J3: Col
A4: Typ FFS | B4: 67 | C4: 23 | D4: 50 | E4: 40 | F4: 30 | G4: =B4 -> 67 | H4: 50 | I4: 35 | J4: 20
A5: Coeficient | B5: 0.7 | C5: 0.7 | D5: 0.6 | E5: 0.6 | F5: 0.6 | G5: =B5 -> 0.7 | H5: 0.7 | I5: 0.6 | J5: 0.2
A6: Exponent | B6: 8 | C6: 3 | D6: 6 | E6: 4 | F6: 3 | G6: =B6 -> 8 | H6: 6 | I6: 4 | J6: 5
A7: Max | B7: 1.44 | C7: 1.65 | D7: 1.55 | E7: 1.8 | F7: 1.85 | G7: 1.44
A8: Max V/C ratio (to prevent speeds from getting unrealistically low during assignment)
A10: V/C | B10: =CONCATENATE(B3, " (x=", B5, ", y=", B6, ")") -> Fwy (x=0.7, y=8) | C10: =CONCATENATE(C3, " (x=", C5, ", y=", C6, ")") -> Ramp (x=0.7, y=3) | D10: =CONCATENATE(D3, " (x=", D5, ", y=", D6, ")") -> Exp (x=0.6, y=6) | E10: =CONCATENATE(E3, " (x=", E5, ", y=", E6, ")") -> Art (x=0.6, y=4) | F10: =CONCATENATE(F3, " (x=", F5, ", y=", F6, ")") -> Col (x=0.6, y=3) | G10: =CONCATENATE(G3, " (x=", G5, ", y=", G6, ")") -> MM (x=0.7, y=8) | H10: =CONCATENATE(H3, " (x=", H5, ", y=", H6, ")") -> Bng (x=0.7, y=6) | I10: =CONCATENATE(I3, " (x=", I5, ", y=", I6, ")") -> Art (x=0.6, y=4) | J10: =CONCATENATE(J3, " (x=", J5, ", y=", J6, ")") -> Col (x=0.2, y=5)
A11: 0 | B11: =MAX(IF($A11>B$7, B$4/(1+B$5*(B$7^B$6)), B$4/(1+B$5*($A11^B$6)) ), B$7) -> 67 | C11: =MAX(IF($A11>C$7, C$4/(1+C$5*(C$7^C$6)), C$4/(1+C$5*($A11^C$6)) ), C$7) -> 23 | D11: =MAX(IF($A11>D$7, D$4/(1+D$5*(D$7^D$6)), D$4/(1+D$5*($A11^D$6)) ), D$7) -> 50 | E11: =MAX(IF($A11>E$7, E$4/(1+E$5*(E$7^E$6)), E$4/(1+E$5*($A11^E$6)) ), E$7) -> 40 | F11: =MAX(IF($A11>F$7, F$4/(1+F$5*(F$7^F$6)), F$4/(1+F$5*($A11^F$6)) ), F$7) -> 30 | G11: =MAX(IF($A11>G$7, G$4/(1+G$5*(G$7^G$6)), G$4/(1+G$5*($A11^G$6)) ), G$7) -> 67 | H11: =H$4/(1+H$5*($A11^H$6)) -> 50 | I11: =I$4/(1+I$5*($A11^I$6)) -> 35 | J11: =J$4/(1+J$5*($A11^J$6)) -> 20
A12: 0.1 | B12: =MAX(IF($A12>B$7, B$4/(1+B$5*(B$7^B$6)), B$4/(1+B$5*($A12^B$6)) ), B$7) -> 67 | C12: =MAX(IF($A12>C$7, C$4/(1+C$5*(C$7^C$6)), C$4/(1+C$5*($A12^C$6)) ), C$7) -> 22.983911 | D12: =MAX(IF($A12>D$7, D$4/(1+D$5*(D$7^D$6)), D$4/(1+D$5*($A12^D$6)) ), D$7) -> 49.99997 | E12: =MAX(IF($A12>E$7, E$4/(1+E$5*(E$7^E$6)), E$4/(1+E$5*($A12^E$6)) ), E$7) -> 39.9976 | F12: =MAX(IF($A12>F$7, F$4/(1+F$5*(F$7^F$6)), F$4/(1+F$5*($A12^F$6)) ), F$7) -> 29.982011 | G12: =MAX(IF($A12>G$7, G$4/(1+G$5*(G$7^G$6)), G$4/(1+G$5*($A12^G$6)) ), G$7) -> 67 | H12: =H$4/(1+H$5*($A12^H$6)) -> 49.999965 | I12: =I$4/(1+I$5*($A12^I$6)) -> 34.9979 | J12: =J$4/(1+J$5*($A12^J$6)) -> 19.99996
A13: 0.5 | B13: =MAX(IF($A13>B$7, B$4/(1+B$5*(B$7^B$6)), B$4/(1+B$5*($A13^B$6)) ), B$7) -> 66.817296 | C13: =MAX(IF($A13>C$7, C$4/(1+C$5*(C$7^C$6)), C$4/(1+C$5*($A13^C$6)) ), C$7) -> 21.149425 | D13: =MAX(IF($A13>D$7, D$4/(1+D$5*(D$7^D$6)), D$4/(1+D$5*($A13^D$6)) ), D$7) -> 49.535604 | E13: =MAX(IF($A13>E$7, E$4/(1+E$5*(E$7^E$6)), E$4/(1+E$5*($A13^E$6)) ), E$7) -> 38.554217 | F13: =MAX(IF($A13>F$7, F$4/(1+F$5*(F$7^F$6)), F$4/(1+F$5*($A13^F$6)) ), F$7) -> 27.906977 | G13: =MAX(IF($A13>G$7, G$4/(1+G$5*(G$7^G$6)), G$4/(1+G$5*($A13^G$6)) ), G$7) -> 66.817296 | H13: =H$4/(1+H$5*($A13^H$6)) -> 49.459042 | I13: =I$4/(1+I$5*($A13^I$6)) -> 33.73494 | J13: =J$4/(1+J$5*($A13^J$6)) -> 19.875776
A14: =A13+0.1 -> 0.6 | B14: =MAX(IF($A14>B$7, B$4/(1+B$5*(B$7^B$6)), B$4/(1+B$5*($A14^B$6)) ), B$7) -> 66.221414 | C14: =MAX(IF($A14>C$7, C$4/(1+C$5*(C$7^C$6)), C$4/(1+C$5*($A14^C$6)) ), C$7) -> 19.979152 | D14: =MAX(IF($A14>D$7, D$4/(1+D$5*(D$7^D$6)), D$4/(1+D$5*($A14^D$6)) ), D$7) -> 48.638435 | E14: =MAX(IF($A14>E$7, E$4/(1+E$5*(E$7^E$6)), E$4/(1+E$5*($A14^E$6)) ), E$7) -> 37.114014 | F14: =MAX(IF($A14>F$7, F$4/(1+F$5*(F$7^F$6)), F$4/(1+F$5*($A14^F$6)) ), F$7) -> 26.558074 | G14: =MAX(IF($A14>G$7, G$4/(1+G$5*(G$7^G$6)), G$4/(1+G$5*($A14^G$6)) ), G$7) -> 66.221414 | H14: =H$4/(1+H$5*($A14^H$6)) -> 48.418684 | I14: =I$4/(1+I$5*($A14^I$6)) -> 32.474762 | J14: =J$4/(1+J$5*($A14^J$6)) -> 19.693723
A15: =A14+0.1 -> 0.7 | B15: =MAX(IF($A15>B$7, B$4/(1+B$5*(B$7^B$6)), B$4/(1+B$5*($A15^B$6)) ), B$7) -> 64.40118 | C15: =MAX(IF($A15>C$7, C$4/(1+C$5*(C$7^C$6)), C$4/(1+C$5*($A15^C$6)) ), C$7) -> 18.546891 | D15: =MAX(IF($A15>D$7, D$4/(1+D$5*(D$7^D$6)), D$4/(1+D$5*($A15^D$6)) ), D$7) -> 46.703246 | E15: =MAX(IF($A15>E$7, E$4/(1+E$5*(E$7^E$6)), E$4/(1+E$5*($A15^E$6)) ), E$7) -> 34.963201 | F15: =MAX(IF($A15>F$7, F$4/(1+F$5*(F$7^F$6)), F$4/(1+F$5*($A15^F$6)) ), F$7) -> 24.879748 | G15: =MAX(IF($A15>G$7, G$4/(1+G$5*(G$7^G$6)), G$4/(1+G$5*($A15^G$6)) ), G$7) -> 64.40118 | H15: =H$4/(1+H$5*($A15^H$6)) -> 46.195594 | I15: =I$4/(1+I$5*($A15^I$6)) -> 30.592801 | J15: =J$4/(1+J$5*($A15^J$6)) -> 19.349583
A16: =A15+0.1 -> 0.8 | B16: =MAX(IF($A16>B$7, B$4/(1+B$5*(B$7^B$6)), B$4/(1+B$5*($A16^B$6)) ), B$7) -> 59.958449 | C16: =MAX(IF($A16>C$7, C$4/(1+C$5*(C$7^C$6)), C$4/(1+C$5*($A16^C$6)) ), C$7) -> 16.931684 | D16: =MAX(IF($A16>D$7, D$4/(1+D$5*(D$7^D$6)), D$4/(1+D$5*($A16^D$6)) ), D$7) -> 43.204517 | E16: =MAX(IF($A16>E$7, E$4/(1+E$5*(E$7^E$6)), E$4/(1+E$5*($A16^E$6)) ), E$7) -> 32.108913 | F16: =MAX(IF($A16>F$7, F$4/(1+F$5*(F$7^F$6)), F$4/(1+F$5*($A16^F$6)) ), F$7) -> 22.949816 | G16: =MAX(IF($A16>G$7, G$4/(1+G$5*(G$7^G$6)), G$4/(1+G$5*($A16^G$6)) ), G$7) -> 59.958449 | H16: =H$4/(1+H$5*($A16^H$6)) -> 42.247542 | I16: =I$4/(1+I$5*($A16^I$6)) -> 28.095299 | J16: =J$4/(1+J$5*($A16^J$6)) -> 18.769896
A17: =A16+0.1 -> 0.9 | B17: =MAX(IF($A17>B$7, B$4/(1+B$5*(B$7^B$6)), B$4/(1+B$5*($A17^B$6)) ), B$7) -> 51.485904 | C17: =MAX(IF($A17>C$7, C$4/(1+C$5*(C$7^C$6)), C$4/(1+C$5*($A17^C$6)) ), C$7) -> 15.228762 | D17: =MAX(IF($A17>D$7, D$4/(1+D$5*(D$7^D$6)), D$4/(1+D$5*($A17^D$6)) ), D$7) -> 37.911397 | E17: =MAX(IF($A17>E$7, E$4/(1+E$5*(E$7^E$6)), E$4/(1+E$5*($A17^E$6)) ), E$7) -> 28.701405 | F17: =MAX(IF($A17>F$7, F$4/(1+F$5*(F$7^F$6)), F$4/(1+F$5*($A17^F$6)) ), F$7) -> 20.871017 | G17: =MAX(IF($A17>G$7, G$4/(1+G$5*(G$7^G$6)), G$4/(1+G$5*($A17^G$6)) ), G$7) -> 51.485904 | H17: =H$4/(1+H$5*($A17^H$6)) -> 36.442918 | I17: =I$4/(1+I$5*($A17^I$6)) -> 25.113729 | J17: =J$4/(1+J$5*($A17^J$6)) -> 17.88752
A18: =A17+0.1 -> 1 | B18: =MAX(IF($A18>B$7, B$4/(1+B$5*(B$7^B$6)), B$4/(1+B$5*($A18^B$6)) ), B$7) -> 39.411765 | C18: =MAX(IF($A18>C$7, C$4/(1+C$5*(C$7^C$6)), C$4/(1+C$5*($A18^C$6)) ), C$7) -> 13.529412 | D18: =MAX(IF($A18>D$7, D$4/(1+D$5*(D$7^D$6)), D$4/(1+D$5*($A18^D$6)) ), D$7) -> 31.25 | E18: =MAX(IF($A18>E$7, E$4/(1+E$5*(E$7^E$6)), E$4/(1+E$5*($A18^E$6)) ), E$7) -> 25 | F18: =MAX(IF($A18>F$7, F$4/(1+F$5*(F$7^F$6)), F$4/(1+F$5*($A18^F$6)) ), F$7) -> 18.75 | G18: =MAX(IF($A18>G$7, G$4/(1+G$5*(G$7^G$6)), G$4/(1+G$5*($A18^G$6)) ), G$7) -> 39.411765 | H18: =H$4/(1+H$5*($A18^H$6)) -> 29.411765 | I18: =I$4/(1+I$5*($A18^I$6)) -> 21.875 | J18: =J$4/(1+J$5*($A18^J$6)) -> 16.666667
