Workbook
Name export_data: Export!$B$2:$C$43

Sheet Export
B2: ;V/C | C2: BTI
B3: 0 | C3: =ROUND(VLOOKUP(B3, 'Eqtn Simplified'!$B$7:$F$48, 5, FALSE),3) -> 0.04
B4: 0.05 | C4: =ROUND(VLOOKUP(B4, 'Eqtn Simplified'!$B$7:$F$48, 5, FALSE),3) -> 0.04
B5: 0.1 | C5: =ROUND(VLOOKUP(B5, 'Eqtn Simplified'!$B$7:$F$48, 5, FALSE),3) -> 0.04
B6: 0.15 | C6: =ROUND(VLOOKUP(B6, 'Eqtn Simplified'!$B$7:$F$48, 5, FALSE),3) -> 0.04
B7: 0.2 | C7: =ROUND(VLOOKUP(B7, 'Eqtn Simplified'!$B$7:$F$48, 5, FALSE),3) -> 0.04
B8: 0.25 | C8: =ROUND(VLOOKUP(B8, 'Eqtn Simplified'!$B$7:$F$48, 5, FALSE),3) -> 0.04
B9: 0.3 | C9: =ROUND(VLOOKUP(B9, 'Eqtn Simplified'!$B$7:$F$48, 5, FALSE),3) -> 0.04
B10: 0.35 | C10: =ROUND(VLOOKUP(B10, 'Eqtn Simplified'!$B$7:$F$48, 5, FALSE),3) -> 0.04
B11: 0.4 | C11: =ROUND(VLOOKUP(B11, 'Eqtn Simplified'!$B$7:$F$48, 5, FALSE),3) -> 0.04
B12: 0.45 | C12: =ROUND(VLOOKUP(B12, 'Eqtn Simplified'!$B$7:$F$48, 5, FALSE),3) -> 0.04
B13: 0.5 | C13: =ROUND(VLOOKUP(B13, 'Eqtn Simplified'!$B$7:$F$48, 5, FALSE),3) -> 0.04
B14: 0.55 | C14: =ROUND(VLOOKUP(B14, 'Eqtn Simplified'!$B$7:$F$48, 5, FALSE),3) -> 0.04
... B43: 2 | C43: =ROUND(VLOOKUP(B43, 'Eqtn Simplified'!$B$7:$F$48, 5, FALSE),3) -> 0.6

Sheet Eqtn Simplified
C1: x1 | D1: x2 | E1: y1 | F1: y2
B2: Low v/c | C2: 0 | D2: 0.6 | E2: 0.04
B3: High v/c | C3: =D2 -> 0.6 | D3: 0.8 | E3: =E2 -> 0.04 | F3: 0.2 | S3: max V/C | T3: 0.7 | W3: max V/C | X3: 1.3
B4: Super High v/c | C4: =D3 -> 0.8 | D4: 2 | E4: =F3 -> 0.2 | F4: 0.6 | S4: median | T4: =MEDIAN(T9:T352) -> 0.030377699 | W4: median | X4: =MEDIAN(X9:X355) -> 0.085052162
S5: mean | T5: =AVERAGE(T9:T352) -> 0.048946167 | W5: mean | X5: =AVERAGE(X9:X355) -> 0.22341034
B7: v/c | C7: =B2 -> Low v/c | D7: =B3 -> High v/c | E7: =B4 -> Super High v/c | F7: Total | R7: Phase 1 | V7: Phase 3
B8: 0 | C8: =IF(B8>=$C$2,IF(B8<$D$2,$E$2,""),"") -> 0.04 | D8: =IF(B8>=$C$3,IF(B8<=$D$3,($F$3-$E$3)/($D$3-$C$3)*(B8-$C$3)+$E$3,""),"") | E8: =IF(B8>$C$4,IF(B8<=$D$4,($F$4-$E$4)/($D$4-$C$4)*(B8-$C$4)+$E$4,""),"") | F8: =IF(ISNUMBER(C8)=TRUE,C8,IF(ISNUMBER(D8)=TRUE,D8,E8)) -> 0.04 | R8: Peak Speed | S8: V/C | T8: BTI | V8: Peak Speed | W8: V/C | X8: BTI
B9: 0.05 | C9: =IF(B9>=$C$2,IF(B9<$D$2,$E$2,""),"") -> 0.04 | D9: =IF(B9>=$C$3,IF(B9<=$D$3,($F$3-$E$3)/($D$3-$C$3)*(B9-$C$3)+$E$3,""),"") | E9: =IF(B9>$C$4,IF(B9<=$D$4,($F$4-$E$4)/($D$4-$C$4)*(B9-$C$4)+$E$4,""),"") | F9: =IF(ISNUMBER(C9)=TRUE,C9,IF(ISNUMBER(D9)=TRUE,D9,E9)) -> 0.04 | R9: 48.515376 | S9: 0.025838046 | T9: 0.023848377 | V9: 51.921288 | W9: 0.70198921 | X9: 0.025242217
B10: 0.1 | C10: =IF(B10>=$C$2,IF(B10<$D$2,$E$2,""),"") -> 0.04 | D10: =IF(B10>=$C$3,IF(B10<=$D$3,($F$3-$E$3)/($D$3-$C$3)*(B10-$C$3)+$E$3,""),"") | E10: =IF(B10>$C$4,IF(B10<=$D$4,($F$4-$E$4)/($D$4-$C$4)*(B10-$C$4)+$E$4,""),"") | F10: =IF(ISNUMBER(C10)=TRUE,C10,IF(ISNUMBER(D10)=TRUE,D10,E10)) -> 0.04 | R10: 59.077888 | S10: 0.026163472 | T10: 0.019541677 | V10: 59.077888 | W10: 0.70254297 | X10: 0.024964727
B11: 0.15 | C11: =IF(B11>=$C$2,IF(B11<$D$2,$E$2,""),"") -> 0.04 | D11: =IF(B11>=$C$3,IF(B11<=$D$3,($F$3-$E$3)/($D$3-$C$3)*(B11-$C$3)+$E$3,""),"") | E11: =IF(B11>$C$4,IF(B11<=$D$4,($F$4-$E$4)/($D$4-$C$4)*(B11-$C$4)+$E$4,""),"") | F11: =IF(ISNUMBER(C11)=TRUE,C11,IF(ISNUMBER(D11)=TRUE,D11,E11)) -> 0.04 | R11: 64.173905 | S11: 0.028516676 | T11: 0.11335713 | V11: 61.154601 | W11: 0.7047753 | X11: 0.08009935
B12: 0.2 | C12: =IF(B12>=$C$2,IF(B12<$D$2,$E$2,""),"") -> 0.04 | D12: =IF(B12>=$C$3,IF(B12<=$D$3,($F$3-$E$3)/($D$3-$C$3)*(B12-$C$3)+$E$3,""),"") | E12: =IF(B12>$C$4,IF(B12<=$D$4,($F$4-$E$4)/($D$4-$C$4)*(B12-$C$4)+$E$4,""),"") | F12: =IF(ISNUMBER(C12)=TRUE,C12,IF(ISNUMBER(D12)=TRUE,D12,E12)) -> 0.04 | R12: 48.515376 | S12: 0.029511089 | T12: 0.022363039 | V12: 59.980829 | W12: 0.70647589 | X12: 0.024569838
B13: 0.25 | C13: =IF(B13>=$C$2,IF(B13<$D$2,$E$2,""),"") -> 0.04 | D13: =IF(B13>=$C$3,IF(B13<=$D$3,($F$3-$E$3)/($D$3-$C$3)*(B13-$C$3)+$E$3,""),"") | E13: =IF(B13>$C$4,IF(B13<=$D$4,($F$4-$E$4)/($D$4-$C$4)*(B13-$C$4)+$E$4,""),"") | F13: =IF(ISNUMBER(C13)=TRUE,C13,IF(ISNUMBER(D13)=TRUE,D13,E13)) -> 0.04 | R13: 51.632551 | S13: 0.030188942 | T13: 0.036251315 | V13: 42.553717 | W13: 0.70845511 | X13: 0.032641605
B14: 0.3 | C14: =IF(B14>=$C$2,IF(B14<$D$2,$E$2,""),"") -> 0.04 | D14: =IF(B14>=$C$3,IF(B14<=$D$3,($F$3-$E$3)/($D$3-$C$3)*(B14-$C$3)+$E$3,""),"") | E14: =IF(B14>$C$4,IF(B14<=$D$4,($F$4-$E$4)/($D$4-$C$4)*(B14-$C$4)+$E$4,""),"") | F14: =IF(ISNUMBER(C14)=TRUE,C14,IF(ISNUMBER(D14)=TRUE,D14,E14)) -> 0.04 | R14: 61.154601 | S14: 0.032749894 | T14: 0.072696752 | V14: 51.632551 | W14: 0.70945858 | X14: 0.77117283
B15: 0.35 | C15: =IF(B15>=$C$2,IF(B15<$D$2,$E$2,""),"") -> 0.04 | D15: =IF(B15>=$C$3,IF(B15<=$D$3,($F$3-$E$3)/($D$3-$C$3)*(B15-$C$3)+$E$3,""),"") | E15: =IF(B15>$C$4,IF(B15<=$D$4,($F$4-$E$4)/($D$4-$C$4)*(B15-$C$4)+$E$4,""),"") | F15: =IF(ISNUMBER(C15)=TRUE,C15,IF(ISNUMBER(D15)=TRUE,D15,E15)) -> 0.04 | R15: 62.400682 | S15: 0.033289277 | T15: 0.13893654 | V15: 51.921288 | W15: 0.71135132 | X15: 0.030169242
B16: 0.4 | C16: =IF(B16>=$C$2,IF(B16<$D$2,$E$2,""),"") -> 0.04 | D16: =IF(B16>=$C$3,IF(B16<=$D$3,($F$3-$E$3)/($D$3-$C$3)*(B16-$C$3)+$E$3,""),"") | E16: =IF(B16>$C$4,IF(B16<=$D$4,($F$4-$E$4)/($D$4-$C$4)*(B16-$C$4)+$E$4,""),"") | F16: =IF(ISNUMBER(C16)=TRUE,C16,IF(ISNUMBER(D16)=TRUE,D16,E16)) -> 0.04 | R16: 71.995954 | S16: 0.033425146 | T16: 0.30253427 | V16: 56.942593 | W16: 0.71151017 | X16: 0.26691455
B17: 0.45 | C17: =IF(B17>=$C$2,IF(B17<$D$2,$E$2,""),"") -> 0.04 | D17: =IF(B17>=$C$3,IF(B17<=$D$3,($F$3-$E$3)/($D$3-$C$3)*(B17-$C$3)+$E$3,""),"") | E17: =IF(B17>$C$4,IF(B17<=$D$4,($F$4-$E$4)/($D$4-$C$4)*(B17-$C$4)+$E$4,""),"") | F17: =IF(ISNUMBER(C17)=TRUE,C17,IF(ISNUMBER(D17)=TRUE,D17,E17)) -> 0.04 | R17: 51.632551 | S17: 0.033450816 | T17: 0.032382954 | V17: 59.077888 | W17: 0.71646339 | X17: 0.018127422
B18: 0.5 | C18: =IF(B18>=$C$2,IF(B18<$D$2,$E$2,""),"") -> 0.04 | D18: =IF(B18>=$C$3,IF(B18<=$D$3,($F$3-$E$3)/($D$3-$C$3)*(B18-$C$3)+$E$3,""),"") | E18: =IF(B18>$C$4,IF(B18<=$D$4,($F$4-$E$4)/($D$4-$C$4)*(B18-$C$4)+$E$4,""),"") | F18: =IF(ISNUMBER(C18)=TRUE,C18,IF(ISNUMBER(D18)=TRUE,D18,E18)) -> 0.04 | R18: 59.29067 | S18: 0.03382844 | T18: 0.05863239 | V18: 48.515376 | W18: 0.71651309 | X18: 0.063362025
B19: 0.55 | C19: =IF(B19>=$C$2,IF(B19<$D$2,$E$2,""),"") -> 0.04 | D19: =IF(B19>=$C$3,IF(B19<=$D$3,($F$3-$E$3)/($D$3-$C$3)*(B19-$C$3)+$E$3,""),"") | E19: =IF(B19>$C$4,IF(B19<=$D$4,($F$4-$E$4)/($D$4-$C$4)*(B19-$C$4)+$E$4,""),"") | F19: =IF(ISNUMBER(C19)=TRUE,C19,IF(ISNUMBER(D19)=TRUE,D19,E19)) -> 0.04 | R19: 64.173905 | S19: 0.034241865 | T19: 0.1027113 | V19: 55.69206 | W19: 0.72220256 | X19: 0.024772562
B20: 0.6 | C20: =IF(B20>=$C$2,IF(B20<$D$2,$E$2,""),"") | D20: =IF(B20>=$C$3,IF(B20<=$D$3,($F$3-$E$3)/($D$3-$C$3)*(B20-$C$3)+$E$3,""),"") -> 0.04 | E20: =IF(B20>$C$4,IF(B20<=$D$4,($F$4-$E$4)/($D$4-$C$4)*(B20-$C$4)+$E$4,""),"") | F20: =IF(ISNUMBER(C20)=TRUE,C20,IF(ISNUMBER(D20)=TRUE,D20,E20)) -> 0.04 | R20: 67.751353 | S20: 0.034767526 | T20: 0.01549513 | V20: 67.751353 | W20: 0.72536299 | X20: 0.033004137
... B48: 2 | C48: =IF(B48>=$C$2,IF(B48<$D$2,$E$2,""),"") | D48: =IF(B48>=$C$3,IF(B48<=$D$3,($F$3-$E$3)/($D$3-$C$3)*(B48-$C$3)+$E$3,""),"") | E48: =IF(B48>$C$4,IF(B48<=$D$4,($F$4-$E$4)/($D$4-$C$4)*(B48-$C$4)+$E$4,""),"") -> 0.6 | F48: =IF(ISNUMBER(C48)=TRUE,C48,IF(ISNUMBER(D48)=TRUE,D48,E48)) -> 0.6 | R48: 65.071508 | S48: 0.044976783 | T48: 0.016413829 | V48: 59.980829 | W48: 0.78113938 | X48: 0.038570393
R49: 62.400682 | S49: 0.045068462 | T49: 0.18446698 | V49: 67.751353 | W49: 0.783762 | X49: 0.018789105
R50: 48.515376 | S50: 0.045125684 | T50: 0.016894349 | V50: 51.921288 | W50: 0.78622745 | X50: 0.18157213
R51: 42.553717 | S51: 0.046826638 | T51: 0.036207748 | V51: 62.400682 | W51: 0.78855464 | X51: 0.04648318
R52: 62.149292 | S52: 0.046843177 | T52: 0.045671511 | V52: 64.843986 | W52: 0.791307 | X52: 0.10001326
R53: 65.071508 | S53: 0.048647136 | T53: 0.017594123 | V53: 59.077888 | W53: 0.79158926 | X53: 0.38909961
R54: 61.154601 | S54: 0.048758772 | T54: 0.06132898 | V54: 66.120188 | W54: 0.79210309 | X54: 0.03056769
R55: 51.632551 | S55: 0.048878272 | T55: 0.032602732 | V55: 71.995954 | W55: 0.7926452 | X55: 0.094740087
R56: 51.632551 | S56: 0.049453782 | T56: 0.027774159 | V56: 59.980829 | W56: 0.79314828 | X56: 0.040119849
R57: 64.173905 | S57: 0.049549797 | T57: 0.11350337 | V57: 55.69206 | W57: 0.79383331 | X57: 0.10515205
R58: 59.29067 | S58: 0.052516854 | T58: 0.058734413 | V58: 59.980829 | W58: 0.79410029 | X58: 0.043075272
R59: 58.933844 | S59: 0.052870565 | T59: 0.01794838 | V59: 64.843986 | W59: 0.794656 | X59: 0.073535458
R60: 61.154601 | S60: 0.053782291 | T60: 0.079094866 | V60: 71.995954 | W60: 0.79528152 | X60: 0.073755734
... R167: 67.751353 | S167: 0.29908467 | T167: 0.014823633 | V167: 49.226236 | W167: 1.3504488 | X167: 0.51984233
R168: 71.995954 | S168: 0.30350468 | T168: 0.13077861
R169: 64.843986 | S169: 0.30504155 | T169: 0.12808594
R170: 56.942593 | S170: 0.30650925 | T170: 0.018892455
R171: 51.921288 | S171: 0.3080673 | T171: 0.012302818
R172: 64.173905 | S172: 0.31396079 | T172: 0.026481816
R173: 67.751353 | S173: 0.32147601 | T173: 0.016843084
R174: 61.154601 | S174: 0.3244566 | T174: 0.034939593
...

Sheet Data
A1: Peak Speed | B1: V/C | C1: BTI
A2: 48.515376 | B2: 0.025838046 | C2: 0.023848377
A3: 59.077888 | B3: 0.026163472 | C3: 0.019541677
A4: 64.173905 | B4: 0.028516676 | C4: 0.11335713
A5: 48.515376 | B5: 0.029511089 | C5: 0.022363039
A6: 51.632551 | B6: 0.030188942 | C6: 0.036251315
A7: 61.154601 | B7: 0.032749894 | C7: 0.072696752
A8: 62.400682 | B8: 0.033289277 | C8: 0.13893654
A9: 71.995954 | B9: 0.033425146 | C9: 0.30253427
A10: 51.632551 | B10: 0.033450816 | C10: 0.032382954
A11: 59.29067 | B11: 0.03382844 | C11: 0.05863239
A12: 64.173905 | B12: 0.034241865 | C12: 0.1027113
A13: 67.751353 | B13: 0.034767526 | C13: 0.01549513
... A505: 49.226236 | B505: 1.3542102 | C505: 0.18936216

Sheet Sort by Ave Sp
B1: 0 | C1: =G2 -> 42.553717 | D1: =G2 -> 42.553717 | E1: =G2 -> 42.553717 | F1: =G2 -> 42.553717 | G1: =G2 -> 42.553717 | H1: =L2 -> 48.515376 | I1: =L2 -> 48.515376 | J1: =L2 -> 48.515376 | K1: =L2 -> 48.515376 | L1: =L2 -> 48.515376 | M1: =Q2 -> 49.226236 | N1: =Q2 -> 49.226236 | O1: =Q2 -> 49.226236 | P1: =Q2 -> 49.226236 | Q1: =Q2 -> 49.226236 | R1: =V2 -> 51.632551 | S1: =V2 -> 51.632551 | T1: =V2 -> 51.632551 | U1: =V2 -> 51.632551 | V1: =V2 -> 51.632551 | W1: =AA2 -> 51.921288 | X1: =AA2 -> 51.921288 | Y1: =AA2 -> 51.921288 | Z1: =AA2 -> 51.921288 | AA1: =AA2 -> 51.921288 | AB1: =AF2 -> 55.69206 | AC1: =AF2 -> 55.69206 | AD1: =AF2 -> 55.69206 | AE1: =AF2 -> 55.69206 | AF1: =AF2 -> 55.69206 | AG1: =AK2 -> 56.942593 | AH1: =AK2 -> 56.942593 | AI1: =AK2 -> 56.942593 | AJ1: =AK2 -> 56.942593 | AK1: =AK2 -> 56.942593 | AL1: =AP2 -> 57.464179 | AM1: =AP2 -> 57.464179 | AN1: =AP2 -> 57.464179 | AO1: =AP2 -> 57.464179 | AP1: =AP2 -> 57.464179 | AQ1: =AU2 -> 58.933844 | AR1: =AU2 -> 58.933844 | AS1: =AU2 -> 58.933844 | AT1: =AU2 -> 58.933844 | AU1: =AU2 -> 58.933844 | AV1: =AZ2 -> 59.077888 | AW1: =AZ2 -> 59.077888 | AX1: =AZ2 -> 59.077888 | AY1: =AZ2 -> 59.077888 | AZ1: =AZ2 -> 59.077888 | BA1: =BE2 -> 59.29067 | BB1: =BE2 -> 59.29067 | BC1: =BE2 -> 59.29067 | BD1: =BE2 -> 59.29067 | BE1: =BE2 -> 59.29067 | BF1: =BJ2 -> 59.980829 | BG1: =BJ2 -> 59.980829 | BH1: =BJ2 -> 59.980829 | BI1: =BJ2 -> 59.980829 | BJ1: =BJ2 -> 59.980829 | BK1: =BO2 -> 61.154601 | BL1: =BO2 -> 61.154601 | BM1: =BO2 -> 61.154601 | BN1: =BO2 -> 61.154601 | BO1: =BO2 -> 61.154601 | BP1: =BT2 -> 62.149292 | BQ1: =BT2 -> 62.149292 | BR1: =BT2 -> 62.149292 | BS1: =BT2 -> 62.149292 | BT1: =BT2 -> 62.149292 | BU1: =BY2 -> 62.400682 | BV1: =BY2 -> 62.400682 | BW1: =BY2 -> 62.400682 | BX1: =BY2 -> 62.400682 | BY1: =BY2 -> 62.400682 | BZ1: =CD2 -> 64.173905 | CA1: =CD2 -> 64.173905 | CB1: =CD2 -> 64.173905 | CC1: =CD2 -> 64.173905 | CD1: =CD2 -> 64.173905 | CE1: =CI2 -> 64.843986 | CF1: =CI2 -> 64.843986 | CG1: =CI2 -> 64.843986 | CH1: =CI2 -> 64.843986 | CI1: =CI2 -> 64.843986 | CJ1: =CN2 -> 65.071508 | CK1: =CN2 -> 65.071508 | CL1: =CN2 -> 65.071508 | CM1: =CN2 -> 65.071508 | CN1: =CN2 -> 65.071508 | CO1: =CS2 -> 66.120188 | CP1: =CS2 -> 66.120188 | CQ1: =CS2 -> 66.120188 | CR1: =CS2 -> 66.120188 | CS1: =CS2 -> 66.120188 | CT1: =CX2 -> 67.751353 | CU1: =CX2 -> 67.751353 | CV1: =CX2 -> 67.751353 | CW1: =CX2 -> 67.751353 | CX1: =CX2 -> 67.751353 | CY1: =DC2 -> 71.995954 | CZ1: =DC2 -> 71.995954 | DA1: =DC2 -> 71.995954 | DB1: =DC2 -> 71.995954 | DC1: =DC2 -> 71.995954
F2: Ave Peak Period Speed | G2: 42.553717 | K2: Ave Peak Period Speed | L2: 48.515376 | P2: Ave Peak Period Speed | Q2: 49.226236 | U2: Ave Peak Period Speed | V2: 51.632551 | Z2: Ave Peak Period Speed | AA2: 51.921288 | AE2: Ave Peak Period Speed | AF2: 55.69206 | AJ2: Ave Peak Period Speed | AK2: 56.942593 | AO2: Ave Peak Period Speed | AP2: 57.464179 | AT2: Ave Peak Period Speed | AU2: 58.933844 | AY2: Ave Peak Period Speed | AZ2: 59.077888 | BD2: Ave Peak Period Speed | BE2: 59.29067 | BI2: Ave Peak Period Speed | BJ2: 59.980829 | BN2: Ave Peak Period Speed | BO2: 61.154601 | BS2: Ave Peak Period Speed | BT2: 62.149292 | BX2: Ave Peak Period Speed | BY2: 62.400682 | CC2: Ave Peak Period Speed | CD2: 64.173905 | CH2: Ave Peak Period Speed | CI2: 64.843986 | CM2: Ave Peak Period Speed | CN2: 65.071508 | CR2: Ave Peak Period Speed | CS2: 66.120188 | CW2: Ave Peak Period Speed | CX2: 67.751353 | DB2: Ave Peak Period Speed | DC2: 71.995954 | DG2: Ave Peak Period Speed
F3: MP | G3: SB_302.0 | K3: MP | L3: SB_291.7 | P3: MP | Q3: SB_297.3 | U3: MP | V3: SB_287.7 | Z3: MP | AA3: NB_292.3 | AE3: MP | AF3: SB_295.3 | AJ3: MP | AK3: NB_309.0 | AO3: MP | AP3: NB_316.0 | AT3: MP | AU3: NB_279.9 | AY3: MP | AZ3: SB_290.1 | BD3: MP | BE3: NB_318.2 | BI3: MP | BJ3: NB_283.0 | BN3: MP | BO3: SB_319.1 | BS3: MP | BT3: NB_288.6 | BX3: MP | BY3: SB_314.0 | CC3: MP | CD3: SB_314.5 | CH3: MP | CI3: NB_302.0 | CM3: MP | CN3: NB_304.9 | CR3: MP | CS3: NB_297.4 | CW3: MP | CX3: SB_310.4 | DB3: MP | DC3: SB_308.1 | DG3: MP | DH3: Template
F4: Location | G4: SB I-15 4500 South | K4: Location | L4: SB I-15 N of 123rd | P4: Location | Q4: SB I-15 at 7700 South | U4: Location | V4: SB I-15 S of 14600 South | Z4: Location | AA4: NB I-15 11400 S | AE4: Location | AF4: SB I-15 at 90th | AJ4: Location | AK4: NB I-15 600 North | AO4: Location | AP4: NB I-15 1900 South (Woodscross) | AT4: Location | AU4: NB I-15 at Lehi Main | AY4: Location | AZ4: SB I-15 at Bangerter | BD4: Location | BE4: NB I-15 S of US-89 On-ramp | BI4: Location | BJ4: NB I-15 2300 West Lehi | BN4: Location | BO4: SB I-15 Parish Lane | BS4: Location | BT4: NB I-15 14600 South | BX4: Location | BY4: SB I-15 NSL at Center | CC4: Location | CD4: SB I-15 NSL between 1100 N and Center | CH4: Location | CI4: NB I-15 N of 4500 South | CM4: Location | CN4: NB I-15 at 1800 South | CR4: Location | CS4: NB I-15 S of 7200 South | CW4: Location | CX4: SB I-15 N of 1100 North | DB4: Location | DC4: SB I-15 200 South | DG4: Location | DH4: #REF!
F5: Lanes | G5: 4 | K5: Lanes | L5: 4 | P5: Lanes | Q5: 4 | U5: Lanes | V5: 4 | Z5: Lanes | AA5: 4 | AE5: Lanes | AF5: 4 | AJ5: Lanes | AK5: 3 | AO5: Lanes | AP5: 4 | AT5: Lanes | AU5: 3 | AY5: Lanes | AZ5: 3 | BD5: Lanes | BE5: 4 | BI5: Lanes | BJ5: 3 | BN5: Lanes | BO5: 4 | BS5: Lanes | BT5: 3 | BX5: Lanes | BY5: 3 | CC5: Lanes | CD5: 5 | CH5: Lanes | CI5: 4 | CM5: Lanes | CN5: 4 | CR5: Lanes | CS5: 4 | CW5: Lanes | CX5: 3 | DB5: Lanes | DC5: 3 | DG5: Lanes | DH5: #REF!
F6: Type | G6: Basic | K6: Type | L6: Basic | P6: Type | Q6: Weave (5 to 4, 1 on then 2 off, 6 total) | U6: Type | V6: Merge | Z6: Type | AA6: basic | AE6: Type | AF6: Basic & Aux lane | AJ6: Type | AK6: Basic | AO6: Type | AP6: Weave | AT6: Type | AU6: Basic | AY6: Type | AZ6: Basic | BD6: Type | BE6: Basic | BI6: Type | BJ6: weave | BN6: Type | BO6: Basic | BS6: Type | BT6: Weave + Aux | BX6: Type | BY6: Basic + 2 aux | CC6: Type | CD6: Weave | CH6: Type | CI6: Weave + aux | CM6: Type | CN6: Merge Area | CR6: Type | CS6: Weave + aux | CW6: Type | CX6: Weave | DB6: Type | DC6: Basic | DG6: Type | DH6: #REF!
B7: 0 | C7: 42.553717 | D7: 42.553717 | E7: 42.553717 | F7: 42.553717 | G7: 42.553717 | H7: 48.515376 | I7: 48.515376 | J7: 48.515376 | K7: 48.515376 | L7: 48.515376 | M7: 49.226236 | N7: 49.226236 | O7: 49.226236 | P7: 49.226236 | Q7: 49.226236 | R7: 51.632551 | S7: 51.632551 | T7: 51.632551 | U7: 51.632551 | V7: 51.632551 | W7: 51.921288 | X7: 51.921288 | Y7: 51.921288 | Z7: 51.921288 | AA7: 51.921288 | AB7: 55.69206 | AC7: 55.69206 | AD7: 55.69206 | AE7: 55.69206 | AF7: 55.69206 | AG7: 56.942593 | AH7: 56.942593 | AI7: 56.942593 | AJ7: 56.942593 | AK7: 56.942593 | AL7: 57.464179 | AM7: 57.464179 | AN7: 57.464179 | AO7: 57.464179 | AP7: 57.464179 | AQ7: 58.933844 | AR7: 58.933844 | AS7: 58.933844 | AT7: 58.933844 | AU7: 58.933844 | AV7: 59.077888 | AW7: 59.077888 | AX7: 59.077888 | AY7: 59.077888 | AZ7: 59.077888 | BA7: 59.29067 | BB7: 59.29067 | BC7: 59.29067 | BD7: 59.29067 | BE7: 59.29067 | BF7: 59.980829 | BG7: 59.980829 | BH7: 59.980829 | BI7: 59.980829 | BJ7: 59.980829 | BK7: 61.154601 | BL7: 61.154601 | BM7: 61.154601 | BN7: 61.154601 | BO7: 61.154601 | BP7: 62.149292 | BQ7: 62.149292 | BR7: 62.149292 | BS7: 62.149292 | BT7: 62.149292 | BU7: 62.400682 | BV7: 62.400682 | BW7: 62.400682 | BX7: 62.400682 | BY7: 62.400682 | BZ7: 64.173905 | CA7: 64.173905 | CB7: 64.173905 | CC7: 64.173905 | CD7: 64.173905 | CE7: 64.843986 | CF7: 64.843986 | CG7: 64.843986 | CH7: 64.843986 | CI7: 64.843986 | CJ7: 65.071508 | CK7: 65.071508 | CL7: 65.071508 | CM7: 65.071508 | CN7: 65.071508 | CO7: 66.120188 | CP7: 66.120188 | CQ7: 66.120188 | CR7: 66.120188 | CS7: 66.120188 | CT7: 67.751353 | CU7: 67.751353 | CV7: 67.751353 | CW7: 67.751353 | CX7: 67.751353 | CY7: 71.995954 | CZ7: 71.995954 | DA7: 71.995954 | DB7: 71.995954 | DC7: 71.995954
C8: BTI | D8: Vol | E8: Cap | F8: v/c | G8: BTI | H8: BTI | I8: Vol | J8: Cap | K8: v/c | L8: BTI | M8: BTI | N8: Vol | O8: Cap | P8: v/c | Q8: BTI | R8: BTI | S8: Vol | T8: Cap | U8: v/c | V8: BTI | W8: BTI | X8: Vol | Y8: Cap | Z8: v/c | AA8: BTI | AB8: BTI | AC8: Vol | AD8: Cap | AE8: v/c | AF8: BTI | AG8: BTI | AH8: Vol | AI8: Cap | AJ8: v/c | AK8: BTI | AL8: BTI | AM8: Vol | AN8: Cap | AO8: v/c | AP8: BTI | AQ8: BTI | AR8: Vol | AS8: Cap | AT8: v/c | AU8: BTI | AV8: BTI | AW8: Vol | AX8: Cap | AY8: v/c | AZ8: BTI | BA8: BTI | BB8: Vol | BC8: Cap | BD8: v/c | BE8: BTI | BF8: BTI | BG8: Vol | BH8: Cap | BI8: v/c | BJ8: BTI | BK8: BTI | BL8: Vol | BM8: Cap | BN8: v/c | BO8: BTI | BP8: BTI | BQ8: Vol | BR8: Cap | BS8: v/c | BT8: BTI | BU8: BTI | BV8: Vol | BW8: Cap | BX8: v/c | BY8: BTI | BZ8: BTI | CA8: Vol | CB8: Cap | CC8: v/c | CD8: BTI | CE8: BTI | CF8: Vol | CG8: Cap | CH8: v/c | CI8: BTI | CJ8: BTI | CK8: Vol | CL8: Cap | CM8: v/c | CN8: BTI | CO8: BTI | CP8: Vol | CQ8: Cap | CR8: v/c | CS8: BTI | CT8: BTI | CU8: Vol | CV8: Cap | CW8: v/c | CX8: BTI | CY8: BTI | CZ8: Vol | DA8: Cap | DB8: v/c | DC8: BTI | DD8: BTI | DE8: Vol | DF8: Cap | DG8: v/c | DH8: BTI
B9: 0 | C9: 0.030405379 | D9: 188.57942 | E9: 1696 | F9: 0.11119069 | G9: =C9 -> 0.030405379 | H9: 0.018555927 | I9: 152.76957 | J9: 1871 | K9: 0.081651296 | L9: =H9 -> 0.018555927 | M9: 0.017755055 | N9: 289.33987 | O9: 1871 | P9: 0.15464451 | Q9: =M9 -> 0.017755055 | R9: 0.029170931 | S9: 145.9038 | T9: 1696 | U9: 0.086028186 | V9: =R9 -> 0.029170931 | W9: 0.022728948 | X9: 127.71141 | Y9: 1696 | Z9: 0.075301539 | AA9: =W9 -> 0.022728948 | AB9: 0.030350018 | AC9: 202.89709 | AD9: 1871 | AE9: 0.10844313 | AF9: =AB9 -> 0.030350018 | AG9: 0.017271782 | AH9: 166.12747 | AI9: 1730 | AJ9: 0.096027441 | AK9: =AG9 -> 0.017271782 | AL9: 0.084126589 | AM9: 163.17937 | AN9: 1696 | AO9: 0.096214252 | AP9: =AL9 -> 0.084126589 | AQ9: 0.01865764 | AR9: 152.9697 | AS9: 1730 | AT9: 0.08842179 | AU9: =AQ9 -> 0.01865764 | AV9: 0.019541677 | AW9: 45.262806 | AX9: 1730 | AY9: 0.026163472 | AZ9: =AV9 -> 0.019541677 | BA9: 0.067965083 | BB9: 141.75839 | BC9: 1696 | BD9: 0.083583956 | BE9: =BA9 -> 0.067965083 | BF9: 0.051600963 | BG9: 186.68456 | BH9: 1730 | BI9: 0.10791015 | BJ9: =BF9 -> 0.051600963 | BK9: 0.079094866 | BL9: 91.214765 | BM9: 1696 | BN9: 0.053782291 | BO9: =BK9 -> 0.079094866 | BP9: 0.035041795 | BQ9: 154.26398 | BR9: 1964 | BS9: 0.078545816 | BT9: =BP9 -> 0.035041795 | BU9: 0.13893654 | BV9: 65.380139 | BW9: 1964 | BX9: 0.033289277 | BY9: =BU9 -> 0.13893654 | BZ9: 0.11350337 | CA9: 81.459867 | CB9: 1644 | CC9: 0.049549797 | CD9: =BZ9 -> 0.11350337 | CE9: 0.12370865 | CF9: 164.72036 | CG9: 1871 | CH9: 0.088038673 | CI9: =CE9 -> 0.12370865 | CJ9: 0.025406246 | CK9: 134.48322 | CL9: 1696 | CM9: 0.079294352 | CN9: =CJ9 -> 0.025406246 | CO9: 0.027362778 | CP9: 172.0179 | CQ9: 1871 | CR9: 0.091939015 | CS9: =CO9 -> 0.027362778 | CT9: 0.018154938 | CU9: 119.98817 | CV9: 1730 | CW9: 0.069357326 | CX9: =CT9 -> 0.018154938 | CY9: 0.18755175 | CZ9: 106.21924 | DA9: 1730 | DB9: 0.061398404 | DC9: =CY9 -> 0.18755175 | DD9: #REF! | DE9: #REF! | DF9: #REF! | DG9: #REF! | DH9: =DD9 -> #REF!
B10: 0.041666667 | C10: 0.03219863 | D10: 117.95787 | E10: 1696 | F10: 0.069550632 | G10: =C10 -> 0.03219863 | H10: 0.016894349 | I10: 84.430155 | J10: 1871 | K10: 0.045125684 | L10: =H10 -> 0.016894349 | M10: 0.021981372 | N10: 169.9568 | O10: 1871 | P10: 0.090837415 | Q10: =M10 -> 0.021981372 | R10: 0.027774159 | S10: 83.873614 | T10: 1696 | U10: 0.049453782 | V10: =R10 -> 0.027774159 | W10: 0.01519747 | X10: 76.177384 | Y10: 1696 | Z10: 0.04491591 | AA10: =W10 -> 0.01519747 | AB10: 0.028405268 | AC10: 116.44889 | AD10: 1871 | AE10: 0.06223885 | AF10: =AB10 -> 0.028405268 | AG10: 0.013425878 | AH10: 94.643275 | AI10: 1730 | AJ10: 0.054707095 | AK10: =AG10 -> 0.013425878 | AL10: 0.088158068 | AM10: 101.04251 | AN10: 1696 | AO10: 0.059576949 | AP10: =AL10 -> 0.088158068 | AQ10: 0.01794838 | AR10: 91.466077 | AS10: 1730 | AT10: 0.052870565 | AU10: =AQ10 -> 0.01794838 | AV10: 0.017338148 | AW10: 113.23203 | AX10: 1730 | AY10: 0.065452038 | AZ10: =AV10 -> 0.017338148 | BA10: 0.058734413 | BB10: 89.068584 | BC10: 1696 | BD10: 0.052516854 | BE10: =BA10 -> 0.058734413 | BF10: 0.062681671 | BG10: 119.2609 | BH10: 1730 | BI10: 0.068936937 | BJ10: =BF10 -> 0.062681671 | BK10: 0.070602581 | BL10: 66.993318 | BM10: 1696 | BN10: 0.039500777 | BO10: =BK10 -> 0.070602581 | BP10: 0.045671511 | BQ10: 92 | BR10: 1964 | BS10: 0.046843177 | BT10: =BP10 -> 0.045671511 | BU10: 0.12827219 | BV10: 109.60426 | BW10: 1964 | BX10: 0.055806651 | BY10: =BU10 -> 0.12827219 | BZ10: 0.1027113 | CA10: 56.293626 | CB10: 1644 | CC10: 0.034241865 | CD10: =BZ10 -> 0.1027113 | CE10: 0.12870872 | CF10: 102.09091 | CG10: 1871 | CH10: 0.05456489 | CI10: =CE10 -> 0.12870872 | CJ10: 0.017594123 | CK10: 82.505543 | CL10: 1696 | CM10: 0.048647136 | CN10: =CJ10 -> 0.017594123 | CO10: 0.022253199 | CP10: 104.14856 | CQ10: 1871 | CR10: 0.055664649 | CS10: =CO10 -> 0.022253199 | CT10: 0.016913291 | CU10: 75.427729 | CV10: 1730 | CW10: 0.043599843 | CX10: =CT10 -> 0.016913291 | CY10: 0.29022007 | CZ10: 71.635556 | DA10: 1730 | DB10: 0.041407836 | DC10: =CY10 -> 0.29022007
B11: 0.083333333 | C11: 0.036207748 | D11: 79.417978 | E11: 1696 | F11: 0.046826638 | G11: =C11 -> 0.036207748 | H11: 0.022363039 | I11: 55.215247 | J11: 1871 | K11: 0.029511089 | L11: =H11 -> 0.022363039 | M11: 0.02115895 | N11: 120.03057 | O11: 1871 | P11: 0.064153163 | Q11: =M11 -> 0.02115895 | R11: 0.032382954 | S11: 56.732584 | T11: 1696 | U11: 0.033450816 | V11: =R11 -> 0.032382954 | W11: 0.024777357 | X11: 60.206742 | Y11: 1696 | Z11: 0.035499258 | AA11: =W11 -> 0.024777357 | AB11: 0.026899427 | AC11: 81.243848 | AD11: 1871 | AE11: 0.043422687 | AF11: =AB11 -> 0.026899427 | AG11: 0.016834761 | AH11: 68.776557 | AI11: 1730 | AJ11: 0.039755235 | AK11: =AG11 -> 0.016834761 | AL11: 0.090407562 | AM11: 75.430493 | AN11: 1696 | AO11: 0.044475527 | AP11: =AL11 -> 0.090407562 | AQ11: 0.018337116 | AR11: 66.551367 | AS11: 1730 | AT11: 0.038468998 | AU11: =AQ11 -> 0.018337116 | AV11: 0.015466279 | AW11: 76.303922 | AX11: 1730 | AY11: 0.044106313 | AZ11: =AV11 -> 0.015466279 | BA11: 0.064393838 | BB11: 62.677928 | BC11: 1696 | BD11: 0.036956325 | BE11: =BA11 -> 0.064393838 | BF11: 0.066827678 | BG11: 93.494407 | BH11: 1730 | BI11: 0.05404301 | BJ11: =BF11 -> 0.066827678 | BK11: 0.072696752 | BL11: 55.54382 | BM11: 1696 | BN11: 0.032749894 | BO11: =BK11 -> 0.072696752 | BP11: 0.043931536 | BQ11: 68.838951 | BR11: 1964 | BS11: 0.035050383 | BT11: =BP11 -> 0.043931536 | BU11: 0.18446698 | BV11: 88.51446 | BW11: 1964 | BX11: 0.045068462 | BY11: =BU11 -> 0.18446698 | BZ11: 0.11335713 | CA11: 46.881416 | CB11: 1644 | CC11: 0.028516676 | CD11: =BZ11 -> 0.11335713 | CE11: 0.11935726 | CF11: 81.347534 | CG11: 1871 | CH11: 0.043478105 | CI11: =CE11 -> 0.11935726 | CJ11: 0.020963032 | CK11: 65.426966 | CL11: 1696 | CM11: 0.038577221 | CN11: =CJ11 -> 0.020963032 | CO11: 0.025668324 | CP11: 83.580717 | CQ11: 1871 | CR11: 0.044671682 | CS11: =CO11 -> 0.025668324 | CT11: 0.01549513 | CU11: 60.14782 | CV11: 1730 | CW11: 0.034767526 | CX11: =CT11 -> 0.01549513 | CY11: 0.30253427 | CZ11: 57.825503 | DA11: 1730 | DB11: 0.033425146 | DC11: =CY11 -> 0.30253427
B12: 0.125 | C12: 0.033928877 | D12: 71.726058 | E12: 1696 | F12: 0.042291308 | G12: =C12 -> 0.033928877 | H12: 0.023848377 | I12: 48.342984 | J12: 1871 | K12: 0.025838046 | L12: =H12 -> 0.023848377 | M12: 0.023535915 | N12: 123.57267 | O12: 1871 | P12: 0.066046322 | Q12: =M12 -> 0.023535915 | R12: 0.036251315 | S12: 51.200445 | T12: 1696 | U12: 0.030188942 | V12: =R12 -> 0.036251315 | W12: 0.018428085 | X12: 74.801782 | Y12: 1696 | Z12: 0.044104824 | AA12: =W12 -> 0.018428085 | AB12: 0.021665885 | AC12: 83.681514 | AD12: 1871 | AE12: 0.044725556 | AF12: =AB12 -> 0.021665885 | AG12: 0.016873005 | AH12: 64.391464 | AI12: 1730 | AJ12: 0.0372205 | AK12: =AG12 -> 0.016873005 | AL12: 0.08149994 | AM12: 67.438202 | AN12: 1696 | AO12: 0.039763091 | AP12: =AL12 -> 0.08149994 | AQ12: 0.018797448 | AR12: 72.477876 | AS12: 1730 | AT12: 0.041894726 | AU12: =AQ12 -> 0.018797448 | AV12: 0.01574126 | AW12: 69.20915 | AX12: 1730 | AY12: 0.040005289 | AZ12: =AV12 -> 0.01574126 | BA12: 0.05863239 | BB12: 57.373034 | BC12: 1696 | BD12: 0.03382844 | BE12: =BA12 -> 0.05863239 | BF12: 0.048794563 | BG12: 106.91908 | BH12: 1730 | BI12: 0.061802936 | BJ12: =BF12 -> 0.048794563 | BK12: 0.06132898 | BL12: 82.694878 | BM12: 1696 | BN12: 0.048758772 | BO12: =BK12 -> 0.06132898 | BP12: 0.033938058 | BQ12: 81.689681 | BR12: 1964 | BS12: 0.041593524 | BT12: =BP12 -> 0.033938058 | BU12: 0.11832381 | BV12: 129.78387 | BW12: 1964 | BX12: 0.066081398 | BY12: =BU12 -> 0.11832381 | BZ12: 0.1094634 | CA12: 72.741203 | CB12: 1644 | CC12: 0.044246474 | CD12: =BZ12 -> 0.1094634 | CE12: 0.12239411 | CF12: 107.0245 | CG12: 1871 | CH12: 0.057201763 | CI12: =CE12 -> 0.12239411 | CJ12: 0.016413829 | CK12: 76.280624 | CL12: 1696 | CM12: 0.044976783 | CN12: =CJ12 -> 0.016413829 | CO12: 0.032731874 | CP12: 104.12695 | CQ12: 1871 | CR12: 0.055653099 | CS12: =CO12 -> 0.032731874 | CT12: 0.016714122 | CU12: 77.752212 | CV12: 1730 | CW12: 0.044943475 | CX12: =CT12 -> 0.016714122 | CY12: 0.30913316 | CZ12: 68.157387 | DA12: 1730 | DB12: 0.039397333 | DC12: =CY12 -> 0.30913316
B13: 0.16666667 | C13: 0.030462352 | D13: 115.02895 | E13: 1696 | F13: 0.067823675 | G13: =C13 -> 0.030462352 | H13: 0.019766656 | I13: 81.084633 | J13: 1871 | K13: 0.043337591 | L13: =H13 -> 0.019766656 | M13: 0.019101336 | N13: 265.16269 | O13: 1871 | P13: 0.14172244 | Q13: =M13 -> 0.019101336 | R13: 0.032602732 | S13: 82.89755 | T13: 1696 | U13: 0.048878272 | V13: =R13 -> 0.032602732 | W13: 0.01663349 | X13: 169.50557 | Y13: 1696 | Z13: 0.099944321 | AA13: =W13 -> 0.01663349 | AB13: 0.017210255 | AC13: 182.40757 | AD13: 1871 | AE13: 0.097492022 | AF13: =AB13 -> 0.017210255 | AG13: 0.019497545 | AH13: 106.9764 | AI13: 1730 | AJ13: 0.06183607 | AK13: =AG13 -> 0.019497545 | AL13: 0.057004626 | AM13: 109.87277 | AN13: 1696 | AO13: 0.064783472 | AP13: =AL13 -> 0.057004626 | AQ13: 0.016318449 | AR13: 165.91445 | AS13: 1730 | AT13: 0.095904309 | AU13: =AQ13 -> 0.016318449 | AV13: 0.021086925 | AW13: 114.47712 | AX13: 1730 | AY13: 0.066171748 | AZ13: =AV13 -> 0.021086925 | BA13: 0.049500256 | BB13: 91.669663 | BC13: 1696 | BD13: 0.054050509 | BE13: =BA13 -> 0.049500256 | BF13: 0.036997805 | BG13: 233.59226 | BH13: 1730 | BI13: 0.13502443 | BJ13: =BF13 -> 0.036997805 | BK13: 0.049501404 | BL13: 198.40535 | BM13: 1696 | BN13: 0.11698428 | BO13: =BK13 -> 0.049501404 | BP13: 0.025947014 | BQ13: 182.60134 | BR13: 1964 | BS13: 0.092974204 | BT13: =BP13 -> 0.025947014 | BU13: 0.088134149 | BV13: 290.52121 | BW13: 1964 | BX13: 0.14792322 | BY13: =BU13 -> 0.088134149 | BZ13: 0.074679301 | CA13: 167.52494 | CB13: 1644 | CC13: 0.10190082 | CD13: =BZ13 -> 0.074679301 | CE13: 0.1443691 | CF13: 223.30067 | CG13: 1871 | CH13: 0.1193483 | CI13: =CE13 -> 0.1443691 | CJ13: 0.021058983 | CK13: 172.64143 | CL13: 1696 | CM13: 0.10179329 | CN13: =CJ13 -> 0.021058983 | CO13: 0.026161575 | CP13: 223.91537 | CQ13: 1871 | CR13: 0.11967684 | CS13: =CO13 -> 0.026161575 | CT13: 0.014379869 | CU13: 156.9587 | CV13: 1730 | CW13: 0.090727573 | CX13: =CT13 -> 0.014379869 | CY13: 0.20916558 | CZ13: 130.03729 | DA13: 1730 | DB13: 0.075166061 | DC13: =CY13 -> 0.20916558
B14: 0.20833333 | C14: 0.034615771 | D14: 310.0692 | E14: 1696 | F14: 0.18282382 | G14: =C14 -> 0.034615771 | H14: 0.014456967 | I14: 305.34152 | J14: 1871 | K14: 0.16319696 | L14: =H14 -> 0.014456967 | M14: 0.012839027 | N14: 749.93682 | O14: 1871 | P14: 0.40082139 | Q14: =M14 -> 0.012839027 | R14: 0.026513435 | S14: 296.70759 | T14: 1696 | U14: 0.17494551 | V14: =R14 -> 0.026513435 | W14: 0.012302818 | X14: 522.48214 | Y14: 1696 | Z14: 0.3080673 | AA14: =W14 -> 0.012302818 | AB14: 0.019756407 | AC14: 523.1875 | AD14: 1871 | AE14: 0.27962988 | AF14: =AB14 -> 0.019756407 | AG14: 0.014404782 | AH14: 265.32743 | AI14: 1730 | AJ14: 0.15336846 | AK14: =AG14 -> 0.014404782 | AL14: 0.025604789 | AM14: 218.8058 | AN14: 1696 | AO14: 0.12901286 | AP14: =AL14 -> 0.025604789 | AQ14: 0.014694483 | AR14: 484.78171 | AS14: 1730 | AT14: 0.28022064 | AU14: =AQ14 -> 0.014694483 | AV14: 0.0159203 | AW14: 379.68301 | AX14: 1730 | AY14: 0.21946995 | AZ14: =AV14 -> 0.0159203 | BA14: 0.036324589 | BB14: 199.42342 | BC14: 1696 | BD14: 0.11758457 | BE14: =BA14 -> 0.036324589 | BF14: 0.027064656 | BG14: 634.03274 | BH14: 1730 | BI14: 0.36649291 | BJ14: =BF14 -> 0.027064656 | BK14: 0.024432099 | BL14: 605.79911 | BM14: 1696 | BN14: 0.35719287 | BO14: =BK14 -> 0.024432099 | BP14: 0.032322023 | BQ14: 531.60119 | BR14: 1964 | BS14: 0.2706727 | BT14: =BP14 -> 0.032322023 | BU14: 0.019679203 | BV14: 883.92727 | BW14: 1964 | BX14: 0.4500648 | BY14: =BU14 -> 0.019679203 | BZ14: 0.026481816 | CA14: 516.15154 | CB14: 1644 | CC14: 0.31396079 | CD14: =BZ14 -> 0.026481816 | CE14: 0.12479557 | CF14: 681.8683 | CG14: 1871 | CH14: 0.36444057 | CI14: =CE14 -> 0.12479557 | CJ14: 0.017423311 | CK14: 453.83259 | CL14: 1696 | CM14: 0.26758997 | CN14: =CJ14 -> 0.017423311 | CO14: 0.023023721 | CP14: 692.02232 | CQ14: 1871 | CR14: 0.36986762 | CS14: =CO14 -> 0.023023721 | CT14: 0.014823633 | CU14: 517.41648 | CV14: 1730 | CW14: 0.29908467 | CX14: =CT14 -> 0.014823633 | CY14: 0.12662913 | CZ14: 395.91964 | DA14: 1730 | DB14: 0.22885528 | DC14: =CY14 -> 0.12662913
B15: 0.25 | C15: 0.036270349 | D15: 789.42699 | E15: 1696 | F15: 0.46546403 | G15: =C15 -> 0.036270349 | H15: 0.019432057 | I15: 680.30752 | J15: 1871 | K15: 0.36360637 | L15: =H15 -> 0.019432057 | M15: 0.017822538 | N15: 1563.8095 | O15: 1871 | P15: 0.83581482 | Q15: =M15 -> 0.017822538 | R15: 0.037719298 | S15: 644.78097 | T15: 1696 | U15: 0.38017746 | V15: =R15 -> 0.037719298 | W15: 0.051989704 | X15: 1307.6858 | Y15: 1696 | Z15: 0.77104118 | AA15: =W15 -> 0.051989704 | AB15: 0.046873357 | AC15: 1186.3606 | AD15: 1871 | AE15: 0.63407836 | AF15: =AB15 -> 0.046873357 | AG15: 0.014243108 | AH15: 594.82301 | AI15: 1730 | AJ15: 0.34382833 | AK15: =AG15 -> 0.014243108 | AL15: 0.02885765 | AM15: 465.99115 | AN15: 1696 | AO15: 0.27475893 | AP15: =AL15 -> 0.02885765 | AQ15: 0.018400785 | AR15: 1096.9056 | AS15: 1730 | AT15: 0.63404948 | AU15: =AQ15 -> 0.018400785 | AV15: 0.023518562 | AW15: 780.33987 | AX15: 1730 | AY15: 0.45106351 | AZ15: =AV15 -> 0.023518562 | BA15: 0.030878587 | BB15: 428.82143 | BC15: 1696 | BD15: 0.25284282 | BE15: =BA15 -> 0.030878587 | BF15: 0.043075272 | BG15: 1373.7935 | BH15: 1730 | BI15: 0.79410029 | BJ15: =BF15 -> 0.043075272 | BK15: 0.059099844 | BL15: 1361.3252 | BM15: 1696 | BN15: 0.80266817 | BO15: =BK15 -> 0.059099844 | BP15: 0.045792657 | BQ15: 1370.5044 | BR15: 1964 | BS15: 0.69781284 | BT15: =BP15 -> 0.045792657 | BU15: 0.027670317 | BV15: 1956.7455 | BW15: 1964 | BX15: 0.99630624 | BY15: =BU15 -> 0.027670317 | BZ15: 0.03231948 | CA15: 1202.6474 | CB15: 1644 | CC15: 0.73153733 | CD15: =BZ15 -> 0.03231948 | CE15: 0.10001326 | CF15: 1480.5354 | CG15: 1871 | CH15: 0.791307 | CI15: =CE15 -> 0.10001326 | CJ15: 0.023345821 | CK15: 997.95133 | CL15: 1696 | CM15: 0.5884147 | CN15: =CJ15 -> 0.023345821 | CO15: 0.02407234 | CP15: 1618.3761 | CQ15: 1871 | CR15: 0.86497921 | CS15: =CO15 -> 0.02407234 | CT15: 0.033004137 | CU15: 1254.878 | CV15: 1730 | CW15: 0.72536299 | CX15: =CT15 -> 0.033004137 | CY15: 0.1191998 | CZ15: 925.80236 | DA15: 1730 | DB15: 0.53514587 | DC15: =CY15 -> 0.1191998
B16: 0.29166667 | C16: 0.031756296 | D16: 1290.6 | E16: 1696 | F16: 0.76096698 | G16: =C16 -> 0.031756296 | H16: 0.029625422 | I16: 1018.1867 | J16: 1871 | K16: 0.54419384 | L16: =H16 -> 0.029625422 | M16: 0.020681044 | N16: 2319.6109 | O16: 1871 | P16: 1.2397706 | Q16: =M16 -> 0.020681044 | R16: 0.04167373 | S16: 1020.72 | T16: 1696 | U16: 0.60183962 | V16: =R16 -> 0.04167373 | W16: 0.35996102 | X16: 1636.6489 | Y16: 1696 | Z16: 0.96500524 | AA16: =W16 -> 0.35996102 | AB16: 0.24392637 | AC16: 1821.4756 | AD16: 1871 | AE16: 0.97353049 | AF16: =AB16 -> 0.24392637 | AG16: 0.0099609609 | AH16: 741.96726 | AI16: 1730 | AJ16: 0.42888281 | AK16: =AG16 -> 0.0099609609 | AL16: 0.021716233 | AM16: 725.42129 | AN16: 1696 | AO16: 0.42772481 | AP16: =AL16 -> 0.021716233 | AQ16: 0.018688485 | AR16: 1383.7339 | AS16: 1730 | AT16: 0.7998462 | AU16: =AQ16 -> 0.018688485 | AV16: 0.022114465 | AW16: 1106.8746 | AX16: 1730 | AY16: 0.6398119 | AZ16: =AV16 -> 0.022114465 | BA16: 0.02645471 | BB16: 692.09641 | BC16: 1696 | BD16: 0.40807571 | BE16: =BA16 -> 0.02645471 | BF16: 0.31705365 | BG16: 1720.883 | BH16: 1730 | BI16: 0.99473004 | BJ16: =BF16 -> 0.31705365 | BK16: 0.19262057 | BL16: 1698.58 | BM16: 1696 | BN16: 1.0015212 | BO16: =BK16 -> 0.19262057 | BP16: 0.26512184 | BQ16: 1913.5081 | BR16: 1964 | BS16: 0.97429132 | BT16: =BP16 -> 0.26512184 | BU16: 0.12604304 | BV16: 2556.8777 | BW16: 1964 | BX16: 1.3018725 | BY16: =BU16 -> 0.12604304 | BZ16: 0.081859047 | CA16: 1586.6472 | CB16: 1644 | CC16: 0.96511389 | CD16: =BZ16 -> 0.081859047 | CE16: 0.091884002 | CF16: 2059.1942 | CG16: 1871 | CH16: 1.1005848 | CI16: =CE16 -> 0.091884002 | CJ16: 0.15748903 | CK16: 1415.4089 | CL16: 1696 | CM16: 0.83455713 | CN16: =CJ16 -> 0.15748903 | CO16: 0.067989764 | CP16: 2187.2378 | CQ16: 1871 | CR16: 1.1690207 | CS16: =CO16 -> 0.067989764 | CT16: 0.085052162 | CU16: 1819.8709 | CV16: 1730 | CW16: 1.0519485 | CX16: =CT16 -> 0.085052162 | CY16: 0.073755734 | CZ16: 1375.837 | DA16: 1730 | DB16: 0.79528152 | DC16: =CY16 -> 0.073755734
B17: 0.33333333 | C17: 0.040608171 | D17: 1427.0308 | E17: 1696 | F17: 0.84140965 | G17: =C17 -> 0.040608171 | H17: 0.025064857 | I17: 1073.0615 | J17: 1871 | K17: 0.573523 | L17: =H17 -> 0.025064857 | M17: 0.039416912 | N17: 2359.7706 | O17: 1871 | P17: 1.2612349 | Q17: =M17 -> 0.039416912 | R17: 0.036829929 | S17: 1104.9429 | T17: 1696 | U17: 0.65149933 | V17: =R17 -> 0.036829929 | W17: 0.81781313 | X17: 1506.8264 | Y17: 1696 | Z17: 0.88845895 | AA17: =W17 -> 0.81781313 | AB17: 0.43552905 | AC17: 1839.7854 | AD17: 1871 | AE17: 0.98331662 | AF17: =AB17 -> 0.43552905 | AG17: 0.015089733 | AH17: 800.93155 | AI17: 1730 | AJ17: 0.46296621 | AK17: =AG17 -> 0.015089733 | AL17: 0.026415959 | AM17: 819.26374 | AN17: 1696 | AO17: 0.48305645 | AP17: =AL17 -> 0.026415959 | AQ17: 0.035712164 | AR17: 1324.4565 | AS17: 1730 | AT17: 0.76558177 | AU17: =AQ17 -> 0.035712164 | AV17: 0.024964727 | AW17: 1215.3993 | AX17: 1730 | AY17: 0.70254297 | AZ17: =AV17 -> 0.024964727 | BA17: 0.019085019 | BB17: 753.39468 | BC17: 1696 | BD17: 0.44421856 | BE17: =BA17 -> 0.019085019 | BF17: 0.54601539 | BG17: 1652.8615 | BH17: 1730 | BI17: 0.95541129 | BJ17: =BF17 -> 0.54601539 | BK17: 0.31006402 | BL17: 1565.9189 | BM17: 1696 | BN17: 0.92330121 | BO17: =BK17 -> 0.31006402 | BP17: 0.97377666 | BQ17: 1756.6154 | BR17: 1964 | BS17: 0.89440702 | BT17: =BP17 -> 0.97377666 | BU17: 0.1980836 | BV17: 2369.2235 | BW17: 1964 | BX17: 1.2063256 | BY17: =BU17 -> 0.1980836 | BZ17: 0.20282407 | CA17: 1462.298 | CB17: 1644 | CC17: 0.88947568 | CD17: =BZ17 -> 0.20282407 | CE17: 0.25257005 | CF17: 1958.5793 | CG17: 1871 | CH17: 1.0468088 | CI17: =CE17 -> 0.25257005 | CJ17: 0.54650411 | CK17: 1411.4769 | CL17: 1696 | CM17: 0.83223875 | CN17: =CJ17 -> 0.54650411 | CO17: 0.14062821 | CP17: 2077.3319 | CQ17: 1871 | CR17: 1.1102789 | CS17: =CO17 -> 0.14062821 | CT17: 0.11341583 | CU17: 1779.1413 | CV17: 1730 | CW17: 1.0284054 | CX17: =CT17 -> 0.11341583 | CY17: 0.094740087 | CZ17: 1371.2762 | DA17: 1730 | DB17: 0.7926452 | DC17: =CY17 -> 0.094740087
B18: 0.375 | C18: 0.035564446 | D18: 1171.2769 | E18: 1696 | F18: 0.69061139 | G18: =C18 -> 0.035564446 | H18: 0.01511627 | I18: 908.14349 | J18: 1871 | K18: 0.48537867 | L18: =H18 -> 0.01511627 | M18: 0.040589742 | N18: 1971.4848 | O18: 1871 | P18: 1.0537065 | Q18: =M18 -> 0.040589742 | R18: 0.028519043 | S18: 932.78901 | T18: 1696 | U18: 0.54999352 | V18: =R18 -> 0.028519043 | W18: 0.18157213 | X18: 1333.4418 | Y18: 1696 | Z18: 0.78622745 | AA18: =W18 -> 0.18157213 | AB18: 0.10515205 | AC18: 1485.2621 | AD18: 1871 | AE18: 0.79383331 | AF18: =AB18 -> 0.10515205 | AG18: 0.010419272 | AH18: 811.58277 | AI18: 1730 | AJ18: 0.46912299 | AK18: =AG18 -> 0.010419272 | AL18: 0.029535966 | AM18: 799.24835 | AN18: 1696 | AO18: 0.47125492 | AP18: =AL18 -> 0.029535966 | AQ18: 0.016716469 | AR18: 1126.7588 | AS18: 1730 | AT18: 0.65130568 | AU18: =AQ18 -> 0.016716469 | AV18: 0.021644755 | AW18: 1120.1767 | AX18: 1730 | AY18: 0.64750096 | AZ18: =AV18 -> 0.021644755 | BA18: 0.035010268 | BB18: 725.67184 | BC18: 1696 | BD18: 0.42787255 | BE18: =BA18 -> 0.035010268 | BF18: 0.040119849 | BG18: 1372.1465 | BH18: 1730 | BI18: 0.79314828 | BJ18: =BF18 -> 0.040119849 | BK18: 0.08009935 | BL18: 1195.2989 | BM18: 1696 | BN18: 0.7047753 | BO18: =BK18 -> 0.08009935 | BP18: 0.14337135 | BQ18: 1449.4097 | BR18: 1964 | BS18: 0.73798864 | BT18: =BP18 -> 0.14337135 | BU18: 0.033719126 | BV18: 1754.1682 | BW18: 1964 | BX18: 0.89316101 | BY18: =BU18 -> 0.033719126 | BZ18: 0.036861586 | CA18: 1055.9576 | CB18: 1644 | CC18: 0.64230999 | CD18: =BZ18 -> 0.036861586 | CE18: 0.11787727 | CF18: 1658.9802 | CG18: 1871 | CH18: 0.88668104 | CI18: =CE18 -> 0.11787727 | CJ18: 0.082300002 | CK18: 1174.7599 | CL18: 1696 | CM18: 0.69266504 | CN18: =CJ18 -> 0.082300002 | CO18: 0.071861785 | CP18: 1747.2671 | CQ18: 1871 | CR18: 0.93386804 | CS18: =CO18 -> 0.071861785 | CT18: 0.018789105 | CU18: 1355.9083 | CV18: 1730 | CW18: 0.783762 | CX18: =CT18 -> 0.018789105 | CY18: 0.08530511 | CZ18: 1059.4068 | DA18: 1730 | DB18: 0.61237385 | DC18: =CY18 -> 0.08530511
B19: 0.41666667 | C19: 0.034368295 | D19: 1105.7511 | E19: 1696 | F19: 0.6519759 | G19: =C19 -> 0.034368295 | H19: 0.013923627 | I19: 864.86199 | J19: 1871 | K19: 0.46224585 | L19: =H19 -> 0.013923627 | M19: 0.014862879 | N19: 1822.7822 | O19: 1871 | P19: 0.97422887 | Q19: =M19 -> 0.014862879 | R19: 0.02636597 | S19: 854.90359 | T19: 1696 | U19: 0.50407051 | V19: =R19 -> 0.02636597 | W19: 0.027171137 | X19: 1142.5856 | Y19: 1696 | Z19: 0.67369433 | AA19: =W19 -> 0.027171137 | AB19: 0.024772562 | AC19: 1351.241 | AD19: 1871 | AE19: 0.72220256 | AF19: =AB19 -> 0.024772562 | AG19: 0.01421146 | AH19: 849.00448 | AI19: 1730 | AJ19: 0.49075404 | AK19: =AG19 -> 0.01421146 | AL19: 0.024345761 | AM19: 815.71973 | AN19: 1696 | AO19: 0.48096682 | AP19: =AL19 -> 0.024345761 | AQ19: 0.01451058 | AR19: 1044.5797 | AS19: 1730 | AT19: 0.6038033 | AU19: =AQ19 -> 0.01451058 | AV19: 0.016870901 | AW19: 1068.6368 | AX19: 1730 | AY19: 0.61770914 | AZ19: =AV19 -> 0.016870901 | BA19: 0.025432394 | BB19: 743.30995 | BC19: 1696 | BD19: 0.43827238 | BE19: =BA19 -> 0.025432394 | BF19: 0.024569838 | BG19: 1222.2033 | BH19: 1730 | BI19: 0.70647589 | BJ19: =BF19 -> 0.024569838 | BK19: 0.029806583 | BL19: 990.99103 | BM19: 1696 | BN19: 0.58431075 | BO19: =BK19 -> 0.029806583 | BP19: 0.022509182 | BQ19: 1267.8009 | BR19: 1964 | BS19: 0.64551981 | BT19: =BP19 -> 0.022509182 | BU19: 0.021430286 | BV19: 1443.1326 | BW19: 1964 | BX19: 0.73479255 | BY19: =BU19 -> 0.021430286 | BZ19: 0.033340398 | CA19: 849.75044 | CB19: 1644 | CC19: 0.51687983 | CD19: =BZ19 -> 0.033340398 | CE19: 0.086836518 | CF19: 1441.0563 | CG19: 1871 | CH19: 0.77020647 | CI19: =CE19 -> 0.086836518 | CJ19: 0.022596617 | CK19: 990.15471 | CL19: 1696 | CM19: 0.58381763 | CN19: =CJ19 -> 0.022596617 | CO19: 0.03056769 | CP19: 1482.0249 | CQ19: 1871 | CR19: 0.79210309 | CS19: =CO19 -> 0.03056769 | CT19: 0.021174682 | CU19: 1110.2373 | CV19: 1730 | CW19: 0.64175569 | CX19: =CT19 -> 0.021174682 | CY19: 0.11075001 | CZ19: 904.35575 | DA19: 1730 | DB19: 0.52274899 | DC19: =CY19 -> 0.11075001
B20: 0.45833333 | C20: 0.032641605 | D20: 1201.5399 | E20: 1696 | F20: 0.70845511 | G20: =C20 -> 0.032641605 | H20: 0.014386986 | I20: 921.26484 | J20: 1871 | K20: 0.49239168 | L20: =H20 -> 0.014386986 | M20: 0.01786332 | N20: 1934.9528 | O20: 1871 | P20: 1.0341811 | Q20: =M20 -> 0.01786332 | R20: 0.027018502 | S20: 910.33484 | T20: 1696 | U20: 0.53675403 | V20: =R20 -> 0.027018502 | W20: 0.020534088 | X20: 1175.7443 | Y20: 1696 | Z20: 0.69324546 | AA20: =W20 -> 0.020534088 | AB20: 0.021037948 | AC20: 1440.8447 | AD20: 1871 | AE20: 0.7700934 | AF20: =AB20 -> 0.021037948 | AG20: 0.012420491 | AH20: 901.1021 | AI20: 1730 | AJ20: 0.52086827 | AK20: =AG20 -> 0.012420491 | AL20: 0.024370526 | AM20: 894.28733 | AN20: 1696 | AO20: 0.52729206 | AP20: =AL20 -> 0.024370526 | AQ20: 0.01793148 | AR20: 1108.8602 | AS20: 1730 | AT20: 0.64095966 | AU20: =AQ20 -> 0.01793148 | AV20: 0.017612664 | AW20: 1119.4425 | AX20: 1730 | AY20: 0.64707658 | AZ20: =AV20 -> 0.017612664 | BA20: 0.035548921 | BB20: 809.29909 | BC20: 1696 | BD20: 0.47718107 | BE20: =BA20 -> 0.035548921 | BF20: 0.026240975 | BG20: 1284.4214 | BH20: 1730 | BI20: 0.7424401 | BJ20: =BF20 -> 0.026240975 | BK20: 0.037672293 | BL20: 990.24887 | BM20: 1696 | BN20: 0.58387315 | BO20: =BK20 -> 0.037672293 | BP20: 0.023057241 | BQ20: 1323.5921 | BR20: 1964 | BS20: 0.67392672 | BT20: =BP20 -> 0.023057241 | BU20: 0.018907086 | BV20: 1433.709 | BW20: 1964 | BX20: 0.7299944 | BY20: =BU20 -> 0.018907086 | BZ20: 0.03007455 | CA20: 844.28736 | CB20: 1644 | CC20: 0.51355679 | CD20: =BZ20 -> 0.03007455 | CE20: 0.073535458 | CF20: 1486.8014 | CG20: 1871 | CH20: 0.794656 | CI20: =CE20 -> 0.073535458 | CJ20: 0.013943537 | CK20: 1011.7765 | CL20: 1696 | CM20: 0.59656633 | CN20: =CJ20 -> 0.013943537 | CO20: 0.022320482 | CP20: 1514.8196 | CQ20: 1871 | CR20: 0.80963102 | CS20: =CO20 -> 0.022320482 | CT20: 0.011235689 | CU20: 1104.4 | CV20: 1730 | CW20: 0.6383815 | CX20: =CT20 -> 0.011235689 | CY20: 0.11582963 | CZ20: 907.42685 | DA20: 1730 | DB20: 0.52452419 | DC20: =CY20 -> 0.11582963
B21: 0.5 | C21: 0.035334196 | D21: 1267.2248 | E21: 1696 | F21: 0.74718442 | G21: =C21 -> 0.035334196 | H21: 0.01693675 | I21: 961.69037 | J21: 1871 | K21: 0.51399806 | L21: =H21 -> 0.01693675 | M21: 0.019677467 | N21: 2005.4402 | O21: 1871 | P21: 1.0718547 | Q21: =M21 -> 0.019677467 | R21: 0.035717615 | S21: 931.07045 | T21: 1696 | U21: 0.54898022 | V21: =R21 -> 0.035717615 | W21: 0.030169242 | X21: 1206.4518 | Y21: 1696 | Z21: 0.71135132 | AA21: =W21 -> 0.030169242 | AB21: 0.040690162 | AC21: 1497.0528 | AD21: 1871 | AE21: 0.80013509 | AF21: =AB21 -> 0.040690162 | AG21: 0.010703585 | AH21: 956.86905 | AI21: 1730 | AJ21: 0.5531035 | AK21: =AG21 -> 0.010703585 | AL21: 0.032128152 | AM21: 952.17273 | AN21: 1696 | AO21: 0.5614226 | AP21: =AL21 -> 0.032128152 | AQ21: 0.018488545 | AR21: 1146.4636 | AS21: 1730 | AT21: 0.66269574 | AU21: =AQ21 -> 0.018488545 | AV21: 0.019134539 | AW21: 1166.94 | AX21: 1730 | AY21: 0.67453179 | AZ21: =AV21 -> 0.019134539 | BA21: 0.027576111 | BB21: 867.55505 | BC21: 1696 | BD21: 0.5115301 | BE21: =BA21 -> 0.027576111 | BF21: 0.030595568 | BG21: 1339.9061 | BH21: 1730 | BI21: 0.77451217 | BJ21: =BF21 -> 0.030595568 | BK21: 0.03682124 | BL21: 987.58998 | BM21: 1696 | BN21: 0.58230541 | BO21: =BK21 -> 0.03682124 | BP21: 0.033379984 | BQ21: 1370.7125 | BR21: 1964 | BS21: 0.69791881 | BT21: =BP21 -> 0.033379984 | BU21: 0.020476113 | BV21: 1439.2736 | BW21: 1964 | BX21: 0.73282768 | BY21: =BU21 -> 0.020476113 | BZ21: 0.02605773 | CA21: 849.7964 | CB21: 1644 | CC21: 0.51690778 | CD21: =BZ21 -> 0.02605773 | CE21: 0.073188266 | CF21: 1496.9679 | CG21: 1871 | CH21: 0.80008973 | CI21: =CE21 -> 0.073188266 | CJ21: 0.016570702 | CK21: 1043.4747 | CL21: 1696 | CM21: 0.61525628 | CN21: =CJ21 -> 0.016570702 | CO21: 0.04239301 | CP21: 1543.383 | CQ21: 1871 | CR21: 0.8248974 | CS21: =CO21 -> 0.04239301 | CT21: 0.015584941 | CU21: 1078.9099 | CV21: 1730 | CW21: 0.62364735 | CX21: =CT21 -> 0.015584941 | CY21: 0.131434 | CZ21: 901.62424 | DA21: 1730 | DB21: 0.52117008 | DC21: =CY21 -> 0.131434
... B32: 0.95833333 | C32: 0.03549717 | D32: 365.22517 | E32: 1696 | F32: 0.21534503 | G32: =C32 -> 0.03549717 | H32: 0.020522703 | I32: 294.61589 | J32: 1871 | K32: 0.1574644 | L32: =H32 -> 0.020522703 | M32: 0.014398587 | N32: 546.73118 | O32: 1871 | P32: 0.29221335 | Q32: =M32 -> 0.014398587 | R32: 0.030685225 | S32: 269.6755 | T32: 1696 | U32: 0.15900678 | V32: =R32 -> 0.030685225 | W32: 0.021584183 | X32: 243.69316 | Y32: 1696 | Z32: 0.143687 | AA32: =W32 -> 0.021584183 | AB32: 0.031668779 | AC32: 387.35762 | AD32: 1871 | AE32: 0.2070324 | AF32: =AB32 -> 0.031668779 | AG32: 0.012540788 | AH32: 321.44915 | AI32: 1730 | AJ32: 0.18580876 | AK32: =AG32 -> 0.012540788 | AL32: 0.073838194 | AM32: 302.28859 | AN32: 1696 | AO32: 0.1782362 | AP32: =AL32 -> 0.073838194 | AQ32: 0.015504479 | AR32: 314.87341 | AS32: 1730 | AT32: 0.18200775 | AU32: =AQ32 -> 0.015504479 | AV32: 0.018916673 | AW32: 376.56053 | AX32: 1730 | AY32: 0.21766505 | AZ32: =AV32 -> 0.018916673 | BA32: 0.084243677 | BB32: 276.73289 | BC32: 1696 | BD32: 0.16316798 | BE32: =BA32 -> 0.084243677 | BF32: 0.044788817 | BG32: 329.93083 | BH32: 1730 | BI32: 0.19071146 | BJ32: =BF32 -> 0.044788817 | BK32: 0.073533708 | BL32: 177.875 | BM32: 1696 | BN32: 0.10487913 | BO32: =BK32 -> 0.073533708 | BP32: 0.035706835 | BQ32: 286.1663 | BR32: 1964 | BS32: 0.14570585 | BT32: =BP32 -> 0.035706835 | BU32: 0.094457562 | BV32: 339.55042 | BW32: 1964 | BX32: 0.17288718 | BY32: =BU32 -> 0.094457562 | BZ32: 0.097509188 | CA32: 166.12751 | CB32: 1644 | CC32: 0.1010508 | CD32: =BZ32 -> 0.097509188 | CE32: 0.12800661 | CF32: 331.08389 | CG32: 1871 | CH32: 0.17695558 | CI32: =CE32 -> 0.12800661 | CJ32: 0.016665368 | CK32: 273.38631 | CL32: 1696 | CM32: 0.16119476 | CN32: =CJ32 -> 0.016665368 | CO32: 0.024345113 | CP32: 342.00221 | CQ32: 1871 | CR32: 0.18279113 | CS32: =CO32 -> 0.024345113 | CT32: 0.016179653 | CU32: 254.60075 | CV32: 1730 | CW32: 0.14716806 | CX32: =CT32 -> 0.016179653 | CY32: 0.19287909 | CZ32: 198.71376 | DA32: 1730 | DB32: 0.11486345 | DC32: =CY32 -> 0.19287909
A35: 42.553717 | B35: 0.11119069 | C35: 0.030405379
A36: 42.553717 | B36: 0.069550632 | C36: 0.03219863
A37: 42.553717 | B37: 0.046826638 | C37: 0.036207748
A38: 42.553717 | B38: 0.042291308 | C38: 0.033928877
A39: 42.553717 | B39: 0.067823675 | C39: 0.030462352
A40: 42.553717 | B40: 0.18282382 | C40: 0.034615771
A41: 42.553717 | B41: 0.46546403 | C41: 0.036270349
A42: 42.553717 | B42: 0.76096698 | C42: 0.031756296
A43: 42.553717 | B43: 0.84140965 | C43: 0.040608171
A44: 42.553717 | B44: 0.69061139 | C44: 0.035564446
A45: 42.553717 | B45: 0.6519759 | C45: 0.034368295
A46: 42.553717 | B46: 0.70845511 | C46: 0.032641605
... A52: 42.553717 | B52: 0.8711181 | C52: 1.1613671
A53: 42.553717 | B53: 0.79681369 | C53: 0.72091497 | E53: 48.515376 | F53: 0.025838046 | G53: 0.023848377 | H53: 59.077888 | I53: 0.026163472 | J53: 0.019541677
A54: 42.553717 | B54: 0.59785639 | C54: 0.058321612 | E54: 48.515376 | F54: 0.029511089 | G54: 0.022363039 | H54: 59.29067 | I54: 0.03382844 | J54: 0.05863239
A55: 42.553717 | B55: 0.50236637 | C55: 0.039806092 | E55: 51.632551 | F55: 0.030188942 | G55: 0.036251315 | H55: 59.29067 | I55: 0.036956325 | J55: 0.064393838
A56: 42.553717 | B56: 0.4902946 | C56: 0.03640723 | E56: 51.632551 | F56: 0.033450816 | G56: 0.032382954 | H56: 56.942593 | I56: 0.0372205 | J56: 0.016873005
A57: 42.553717 | B57: 0.35025161 | C57: 0.035213281 | E57: 51.921288 | F57: 0.035499258 | G57: 0.024777357 | H57: 58.933844 | I57: 0.038468998 | J57: 0.018337116
...
